Workbook

Sheet 1 Balance sheet
A1: BILAN PREVISIONNEL
A3: ALL AMOUNTS IN KEUR | B3: Actual 08/2020 | C3: Estimé 2020 | D3: 2021 | E3: 2022 | F3: 2023
A4: Immobilisations corporelles/ incorporelles | B4: =SUM(B5:B6) -> 1870.4446 | C4: =SUM(C5:C6) -> 1881.4578 | D4: =SUM(D5:D6) -> 2111.6055 | E4: =SUM(E5:E6) -> 2634.0101 | F4: =SUM(F5:F6) -> 2950.6057
A5: Immobilisations | B5: 2987.6658 | C5: 3129.3648 | D5: =C5+400/3+'2 P&L'!D45+'2 P&L'!E45+'2 P&L'!F45+'2 P&L'!G45 -> 3863.4731 | E5: =D5+400/3+'2 P&L'!H45+'2 P&L'!I45+'2 P&L'!J45+'2 P&L'!K45 -> 5025.5815 | F5: =E5+400/3+'2 P&L'!L45+'2 P&L'!M45+'2 P&L'!N45+'2 P&L'!O45 -> 6077.6898 | G5: =F5-C5 -> 2948.325
A6: Amortissement | B6: -1117.2212 | C6: -1247.907 | D6: =C6+'[1]Recap Amortissement'!$E$10 -> -1751.8676 | E6: =D6+'[1]Recap Amortissement'!$I$10 -> -2391.5713 | F6: =E6+'[1]Recap Amortissement'!$M$10 -> -3127.0841 | G6: =F6-C6 -> -1879.1771
A7: Immobilisations financières | B7: 7.05 | C7: =B7 -> 7.05 | D7: =C7 -> 7.05 | E7: =D7 -> 7.05 | F7: =E7 -> 7.05 | G7: =D6-C6 -> -503.96067
A8: Actifs immobilisés | B8: =B4+B7 -> 1877.4946 | C8: =C4+C7 -> 1888.5078 | D8: =D4+D7 -> 2118.6555 | E8: =E4+E7 -> 2641.0601 | F8: =F4+F7 -> 2957.6557 | G8: =D5-C5 -> 734.10833
A9: Stocks | B9: 7.37821 | C9: 7.37821 | D9: =C9 -> 7.37821 | E9: =D9 -> 7.37821 | F9: =E9 -> 7.37821
A10: Créances commerciales | B10: 5.83226 | C10: 5.83226 | D10: =C10-'3 Cash Flow'!G4 -> 582.6619 | E10: =C10-'3 Cash Flow'!L4 -> 353.986 | F10: =C10-'3 Cash Flow'!Q4 -> 542.90593
A11: Autres créances | B11: 36.4293 | C11: 36.4293 | D11: =C11 -> 36.4293 | E11: =D11 -> 36.4293 | F11: =E11 -> 36.4293
A12: Cash & équivalents | B12: =SUM(B13:B22) -> 523.59175 | C12: =SUM(C13:C22) -> 129.3068 | D12: =SUM(D13:D22) -> 1515.034 | E12: =SUM(E13:E22) -> 2876.1213 | F12: =SUM(F13:F22) -> 4998.983
A13: Opening cash | B13: 523.59175 | C13: =B13 -> 523.59175 | D13: =C12 -> 129.3068 | E13: =D12 -> 1515.034 | F13: =E12 -> 2876.1213
A14: Apport capital | B14: 0 | C14: 0 | D14: 4000 | E14: 2000 | F14: 0
A15: Revenus | B15: 0 | C15: 67.824 | D15: =SUM('2 P&L'!D12:G12) -> 1298.3469 | E15: =SUM('2 P&L'!H12:K12)-D16 -> 5051.8169 | F15: =SUM('2 P&L'!L12:O12)-E16 -> 9120.496
A16: Revenus non perçus | B16: 0 | C16: 0 | D16: ='3 Cash Flow'!G4 -> -576.82964 | E16: ='3 Cash Flow'!L4 -> -348.15374 | F16: ='3 Cash Flow'!Q4 -> -537.07367
A17: Acquisitions immobilisations | B17: 0 | C17: 0 | D17: =-400/3 -> -133.33333 | E17: =-400/3 -> -133.33333 | F17: =-400/3 -> -133.33333
A18: Subsides reçus | B18: 0 | C18: 0 | D18: 0 | E18: 0 | F18: 0
A19: Payroll & OPEX & coûts financiers | B19: 0 | C19: -462.10895 | D19: =SUM('2 P&L'!D47:G48)+SUM('2 P&L'!D54:G54) -> -3044.5721 | E19: =SUM('2 P&L'!H47:K48)+SUM('2 P&L'!H54:K54)-D20 -> -4441.7749 | F19: =SUM('2 P&L'!L47:O48)+SUM('2 P&L'!L54:O54)-E20 -> -4976.5772
A20: Report des paiements OPEX | B20: 0 | C20: 0 | D20: ='3 Cash Flow'!G3 -> 86.776689 | E20: ='3 Cash Flow'!L3 -> -8.6664991 | F20: ='3 Cash Flow'!Q3 -> 4.8749216
A21: Achat stock | B21: 0 | C21: 0 | D21: =SUM('2 P&L'!D13:G13) -> -244.66123 | E21: =SUM('2 P&L'!H13:K13) -> -758.80113 | F21: =SUM('2 P&L'!L13:O13) -> -1355.525
A22: Impôts sur le résultat | B22: ='[2]P&L'!B38 -> 0 | C22: 0 | D22: 0 | E22: 0 | F22: 0
A23: Comptes de régularisation | B23: 0 | C23: 0 | D23: 0 | E23: 0 | F23: 0
A24: Actifs circulants | B24: =+B12+B11+B23+B10+B9 -> 573.23152 | C24: =+C12+C11+C23+C10+C9 -> 178.94657 | D24: =+D12+D11+D23+D10+D9 -> 2141.5034 | E24: =+E12+E11+E23+E10+E9 -> 3273.9148 | F24: =+F12+F11+F23+F10+F9 -> 5585.6965
A25: TOTAL ACTIF | B25: =B8+B24 -> 2450.7261 | C25: =C8+C24 -> 2067.4544 | D25: =D8+D24 -> 4260.1589 | E25: =E8+E24 -> 5914.9749 | F25: =F8+F24 -> 8543.3522
A27: Capital | B27: 4650.315 | C27: =B27 -> 4650.315 | D27: =C27+4000 -> 8650.315 | E27: =D27+2000 -> 10650.315 | F27: =E27 -> 10650.315
A28: Réserves & résultat reporté | B28: -2386.6292 | C28: =B28+C15+C19+C4-B4 -> -2769.9009 | D28: =C28+SUM('2 P&L'!D62:G62) -> -4663.973 | E28: =D28+SUM('2 P&L'!H62:K62) -> -4913.7139 | F28: =E28+SUM('2 P&L'!L62:O62) -> -2298.878 | G28: =F28-C28 -> 471.02285
A29: Subsides | B29: 0 | C29: =B29 -> 0 | D29: =C29 -> 0 | E29: =D29 -> 0 | F29: =E29 -> 0
A30: Fonds propres | B30: =SUM(B27:B29) -> 2263.6859 | C30: =SUM(C27:C29) -> 1880.4142 | D30: =SUM(D27:D29) -> 3986.342 | E30: =SUM(E27:E29) -> 5736.6012 | F30: =SUM(F27:F29) -> 8351.437
A31: Provisions pour risques et charges | B31: 0 | C31: =B31 -> 0 | D31: =C31 -> 0 | E31: =D31 -> 0 | F31: =E31 -> 0
A32: Dettes financières long terme | B32: 94.28986 | C32: =B32 -> 94.28986 | D32: =C32 -> 94.28986 | E32: =D32 -> 94.28986 | F32: =E32 -> 94.28986
A33: Dettes financières court terme | B33: 0 | C33: =B33 -> 0 | D33: =C33 -> 0 | E33: =D33 -> 0 | F33: =E33 -> 0
A34: Dettes commerciales | B34: 107.13429 | C34: =B34 -> 107.13429 | D34: =C34+'3 Cash Flow'!G3 -> 193.91098 | E34: =C34+'3 Cash Flow'!L3 -> 98.467791 | F34: =C34+'3 Cash Flow'!Q3 -> 112.00921
A35: Dettes fiscales, salariales et sociales | B35: 32.62096 | C35: =B35 -> 32.62096 | D35: =C35 -> 32.62096 | E35: =D35 -> 32.62096 | F35: =E35 -> 32.62096
A36: Autres dettes | B36: -47.00488 | C36: =B36 -> -47.00488 | D36: =C36 -> -47.00488 | E36: =D36 -> -47.00488 | F36: =E36 -> -47.00488
A37: Comptes de régularisation | B37: 0 | C37: =B37 -> 0 | D37: =C37 -> 0 | E37: =D37 -> 0 | F37: =E37 -> 0
A38: Autres passifs | B38: =SUM(B31:B36,B37) -> 187.04023 | C38: =SUM(C31:C36,C37) -> 187.04023 | D38: =SUM(D31:D36,D37) -> 273.81692 | E38: =SUM(E31:E36,E37) -> 178.37373 | F38: =SUM(F31:F36,F37) -> 191.91515
A39: TOTAL PASSIF | B39: =+B38+B30 -> 2450.7261 | C39: =+C38+C30 -> 2067.4544 | D39: =+D38+D30 -> 4260.1589 | E39: =+E38+E30 -> 5914.9749 | F39: =+F38+F30 -> 8543.3522
B40: =+B39-B25 -> 0 | C40: =+C39-C25 -> 0 | D40: =+D39-D25 -> 0 | E40: =+E39-E25 -> 0 | F40: =+F39-F25 -> 0

Sheet 2 P&L
B2: DATA FROM sales V8.4 / somme corrections in 8.6 not included
C4: PROFIT AND LOSS | D4: YEAR 1 | H4: Year2 | L4: Year3
C5: ALL AMOUNTS IN KEUR | D5: Q1 | E5: Q2 | F5: Q3 | G5: Q4 | H5: Q1 | I5: Q2 | J5: Q3 | K5: Q4 | L5: Q1 | M5: Q2 | N5: Q3 | O5: Q4 | P5: TOTAL | Q5: Comments
C6: T1 -Hospital market | D6: ='Tableau recap'!E4 -> 23.585794 | E6: ='Tableau recap'!F4 -> 47.171589 | F6: ='Tableau recap'!G4 -> 99.51492 | G6: ='Tableau recap'!H4 -> 373.10071 | H6: ='Tableau recap'!I4 -> 280.07969 | I6: ='Tableau recap'!J4 -> 402.23186 | J6: ='Tableau recap'!K4 -> 524.38404 | K6: ='Tableau recap'!L4 -> 646.53622 | ... O6: ='Tableau recap'!P4 -> 1210.0564 | P6: =SUM(D6:O6) -> 7236.8303
C7: T2 - Homecare market | D7: ='Tableau recap'!E14 -> 12.018168 | E7: ='Tableau recap'!F14 -> 35.574767 | F7: ='Tableau recap'!G14 -> 53.362151 | G7: ='Tableau recap'!H14 -> 76.918751 | H7: ='Tableau recap'!I14 -> 238.18886 | I7: ='Tableau recap'!J14 -> 238.18886 | J7: ='Tableau recap'!K14 -> 238.18886 | K7: ='Tableau recap'!L14 -> 238.18886 | ... O7: ='Tableau recap'!P14 -> 485.3042 | P7: =SUM(D7:O7) -> 3071.8461
C8: T3 - Nutrow & Feedim evolution | D8: ='Tableau recap'!E24 -> 0 | E8: ='Tableau recap'!F24 -> 0 | F8: ='Tableau recap'!G24 -> 0 | G8: ='Tableau recap'!H24 -> 0 | H8: ='Tableau recap'!I24 -> 0 | I8: ='Tableau recap'!J24 -> 0 | J8: ='Tableau recap'!K24 -> 0 | K8: ='Tableau recap'!L24 -> 0 | ... O8: ='Tableau recap'!P24 -> 0 | P8: =SUM(D8:O8) -> 0
C9: T4 - Oncology development | D9: ='Tableau recap'!E34 -> 0 | E9: ='Tableau recap'!F34 -> 0 | F9: ='Tableau recap'!G34 -> 0 | G9: ='Tableau recap'!H34 -> 0 | H9: ='Tableau recap'!I34 -> 0 | I9: ='Tableau recap'!J34 -> 0 | J9: ='Tableau recap'!K34 -> 0 | K9: ='Tableau recap'!L34 -> 0 | ... O9: ='Tableau recap'!P34 -> 0 | P9: =SUM(D9:O9) -> 0
C10: T5 - Operations | D10: ='Tableau recap'!E44 -> 48.125 | E10: ='Tableau recap'!F44 -> 20.625 | F10: ='Tableau recap'!G44 -> 48.125 | G10: ='Tableau recap'!H44 -> 20.625 | H10: ='Tableau recap'!I44 -> 90.75 | I10: ='Tableau recap'!J44 -> 140.25 | J10: ='Tableau recap'!K44 -> 189.75 | K10: ='Tableau recap'!L44 -> 239.25 | ... O10: ='Tableau recap'!P44 -> 103.125 | P10: =SUM(D10:O10) -> 1210
C11: T6 - OEM Feedim | D11: ='Tableau recap'!E54 -> 0 | E11: ='Tableau recap'!F54 -> 45 | F11: ='Tableau recap'!G54 -> 0 | G11: ='Tableau recap'!H54 -> 394.6 | H11: ='Tableau recap'!I54 -> 218.5 | I11: ='Tableau recap'!J54 -> 263.5 | J11: ='Tableau recap'!K54 -> 263.5 | K11: ='Tableau recap'!L54 -> 263.5 | ... O11: ='Tableau recap'!P54 -> 394.6 | P11: =SUM(D11:O11) -> 3027
C12: TOTAL REVENUE | D12: =SUM(D6:D11) -> 83.728962 | E12: =SUM(E6:E11) -> 148.37136 | F12: =SUM(F6:F11) -> 201.00207 | G12: =SUM(G6:G11) -> 865.24447 | H12: =SUM(H6:H11) -> 827.51854 | I12: =SUM(I6:I11) -> 1044.1707 | J12: =SUM(J6:J11) -> 1215.8229 | K12: =SUM(K6:K11) -> 1387.4751 | ... P12: =SUM(P6:P11) -> 14545.676
A13: 22 | C13: COGS | D13: =-'Tableau recap'!E93 -> -2.3482652 | E13: =-'Tableau recap'!F93 -> -8.6851811 | F13: =-'Tableau recap'!G93 -> -14.029459 | G13: =-'Tableau recap'!H93 -> -219.59833 | H13: =-'Tableau recap'!I93 -> -184.37366 | I13: =-'Tableau recap'!J93 -> -187.92474 | J13: =-'Tableau recap'!K93 -> -191.47582 | K13: =-'Tableau recap'!L93 -> -195.02691 | ... O13: =-'Tableau recap'!P93 -> -338.88125 | P13: =SUM(D13:O13) -> -2358.9874
C14: Variation de stock | D14: =COGS!C21/1000 -> 0 | E14: =COGS!D21/1000 -> 0 | F14: =COGS!E21/1000 -> 0 | G14: =COGS!F21/1000 -> 0 | H14: =COGS!G21/1000 -> 0 | I14: =COGS!H21/1000 -> 0 | J14: =COGS!I21/1000 -> 0 | K14: =COGS!J21/1000 -> 0 | ... O14: =COGS!N21/1000 -> 0 | P14: =SUM(D14:O14) -> 0
C15: TOTAL COGS | D15: =SUM(D13:D14) -> -2.3482652 | E15: =SUM(E13:E14) -> -8.6851811 | F15: =SUM(F13:F14) -> -14.029459 | G15: =SUM(G13:G14) -> -219.59833 | H15: =SUM(H13:H14) -> -184.37366 | I15: =SUM(I13:I14) -> -187.92474 | J15: =SUM(J13:J14) -> -191.47582 | K15: =SUM(K13:K14) -> -195.02691 | ... P15: =SUM(P13:P14) -> -2358.9874
C16: GROSS MARGIN | D16: =D12+D15 -> 81.380697 | E16: =E12+E15 -> 139.68617 | F16: =F12+F15 -> 186.97261 | G16: =G12+G15 -> 645.64614 | H16: =H12+H15 -> 643.14489 | I16: =I12+I15 -> 856.24598 | J16: =J12+J15 -> 1024.3471 | K16: =K12+K15 -> 1192.4482 | ... P16: =P12+P15 -> 12186.689
C17: GROSS MARGIN Rate | D17: =D16/D12 -> 0.97195397 | E17: =E16/E12 -> 0.94146322 | F17: =F16/F12 -> 0.93020242 | G17: =G16/G12 -> 0.74620083 | H17: =H16/H12 -> 0.77719695 | I17: =I16/I12 -> 0.82002489 | J17: =J16/J12 -> 0.84251339 | K17: =K16/K12 -> 0.85943754 | ... P17: =P16/P12 -> 0.83782209
A18: 10 | B18: HR/Admin | C18: Directors | D18: =-'Recap costs'!H33/1000 -> -9 | E18: =-'Recap costs'!I33/1000 -> -9 | F18: =-'Recap costs'!J33/1000 -> -9 | G18: =-'Recap costs'!K33/1000 -> -9 | H18: =-'Recap costs'!L33/1000 -> -9 | I18: =-'Recap costs'!M33/1000 -> -9 | J18: =-'Recap costs'!N33/1000 -> -9 | K18: =-'Recap costs'!O33/1000 -> -9 | ... O18: =-'Recap costs'!S33/1000 -> -9 | P18: =SUM(D18:O18) -> -108
A19: 11 | C19: Employees & Freelances | D19: =SUM(D20:D26) -> -327.61809 | E19: =SUM(E20:E26) -> -514.49309 | F19: =SUM(F20:F26) -> -551.59309 | G19: =SUM(G20:G26) -> -706.44309 | H19: =SUM(H20:H26) -> -867.84309 | I19: =SUM(I20:I26) -> -837.59309 | J19: =SUM(J20:J26) -> -864.34309 | K19: =SUM(K20:K26) -> -922.09309 | ... O19: =SUM(O20:O26) -> -1041.6931 | P19: =SUM(D19:O19) -> -9573.442
C20: T1 -Hospital market: Baxter & DIM 3 Pilot | D20: =-('PT Recap costs'!B48+'PT Recap costs'!B49)/1000 -> -13.47309 | E20: =-('PT Recap costs'!C48+'PT Recap costs'!C49)/1000 -> -82.91059 | F20: =-('PT Recap costs'!D48+'PT Recap costs'!D49)/1000 -> -82.91059 | G20: =-('PT Recap costs'!E48+'PT Recap costs'!E49)/1000 -> -105.46059 | H20: =-('PT Recap costs'!F48+'PT Recap costs'!F49)/1000 -> -109.03559 | I20: =-('PT Recap costs'!G48+'PT Recap costs'!G49)/1000 -> -109.03559 | J20: =-('PT Recap costs'!H48+'PT Recap costs'!H49)/1000 -> -109.03559 | K20: =-('PT Recap costs'!I48+'PT Recap costs'!I49)/1000 -> -109.03559 | ... O20: =-('PT Recap costs'!M48+'PT Recap costs'!M49)/1000 -> -120.31059 | P20: =SUM(D20:O20) -> -1190.8646
C21: T2 - Homecare market: Vivisol | D21: =-('PT Recap costs'!B52+'PT Recap costs'!B53)/1000 -> -13.47309 | E21: =-('PT Recap costs'!C52+'PT Recap costs'!C53)/1000 -> -82.91059 | F21: =-('PT Recap costs'!D52+'PT Recap costs'!D53)/1000 -> -82.91059 | G21: =-('PT Recap costs'!E52+'PT Recap costs'!E53)/1000 -> -105.46059 | H21: =-('PT Recap costs'!F52+'PT Recap costs'!F53)/1000 -> -109.03559 | I21: =-('PT Recap costs'!G52+'PT Recap costs'!G53)/1000 -> -109.03559 | J21: =-('PT Recap costs'!H52+'PT Recap costs'!H53)/1000 -> -109.03559 | K21: =-('PT Recap costs'!I52+'PT Recap costs'!I53)/1000 -> -109.03559 | ... O21: =-('PT Recap costs'!M52+'PT Recap costs'!M53)/1000 -> -120.31059 | P21: =SUM(D21:O21) -> -1190.8646
C22: T3 - Nutrow & Feedim evolution | D22: =-('PT Recap costs'!B56+'PT Recap costs'!B57)/1000 -> -100.67891 | E22: =-('PT Recap costs'!C56+'PT Recap costs'!C57)/1000 -> -103.42891 | F22: =-('PT Recap costs'!D56+'PT Recap costs'!D57)/1000 -> -98.715611 | G22: =-('PT Recap costs'!E56+'PT Recap costs'!E57)/1000 -> -178.46561 | H22: =-('PT Recap costs'!F56+'PT Recap costs'!F57)/1000 -> -213.42891 | I22: =-('PT Recap costs'!G56+'PT Recap costs'!G57)/1000 -> -183.17891 | J22: =-('PT Recap costs'!H56+'PT Recap costs'!H57)/1000 -> -106.17891 | K22: =-('PT Recap costs'!I56+'PT Recap costs'!I57)/1000 -> -144.67891 | ... O22: =-('PT Recap costs'!M56+'PT Recap costs'!M57)/1000 -> -235.42891 | P22: =SUM(D22:O22) -> -1930.2203
C23: T4 - Oncology: development | D23: =-('PT Recap costs'!B60+'PT Recap costs'!B61)/1000 -> -11.25 | E23: =-('PT Recap costs'!C60+'PT Recap costs'!C61)/1000 -> -41.5 | F23: =-('PT Recap costs'!D60+'PT Recap costs'!D61)/1000 -> -46.213295 | G23: =-('PT Recap costs'!E60+'PT Recap costs'!E61)/1000 -> -76.213295 | H23: =-('PT Recap costs'!F60+'PT Recap costs'!F61)/1000 -> -60.25 | I23: =-('PT Recap costs'!G60+'PT Recap costs'!G61)/1000 -> -60.25 | J23: =-('PT Recap costs'!H60+'PT Recap costs'!H61)/1000 -> -90.5 | K23: =-('PT Recap costs'!I60+'PT Recap costs'!I61)/1000 -> -109.75 | ... O23: =-('PT Recap costs'!M60+'PT Recap costs'!M61)/1000 -> -93.5 | P23: =SUM(D23:O23) -> -869.92659
C24: T5 - Operations organisation (Services): Installation & Interfaçage | D24: =-('PT Recap costs'!B64+'PT Recap costs'!B65)/1000 -> -27 | E24: =-('PT Recap costs'!C64+'PT Recap costs'!C65)/1000 -> -27 | F24: =-('PT Recap costs'!D64+'PT Recap costs'!D65)/1000 -> -27 | G24: =-('PT Recap costs'!E64+'PT Recap costs'!E65)/1000 -> -27 | H24: =-('PT Recap costs'!F64+'PT Recap costs'!F65)/1000 -> -134.25 | I24: =-('PT Recap costs'!G64+'PT Recap costs'!G65)/1000 -> -134.25 | J24: =-('PT Recap costs'!H64+'PT Recap costs'!H65)/1000 -> -117.75 | K24: =-('PT Recap costs'!I64+'PT Recap costs'!I65)/1000 -> -117.75 | ... O24: =-('PT Recap costs'!M64+'PT Recap costs'!M65)/1000 -> -129.025 | P24: =SUM(D24:O24) -> -1116.825
C25: T6 - OEM Feedim | D25: =-('PT Recap costs'!B68+'PT Recap costs'!B69)/1000 -> 0 | E25: =-('PT Recap costs'!C68+'PT Recap costs'!C69)/1000 -> -15 | F25: =-('PT Recap costs'!D68+'PT Recap costs'!D69)/1000 -> -30 | G25: =-('PT Recap costs'!E68+'PT Recap costs'!E69)/1000 -> -30 | H25: =-('PT Recap costs'!F68+'PT Recap costs'!F69)/1000 -> -30 | I25: =-('PT Recap costs'!G68+'PT Recap costs'!G69)/1000 -> -30 | J25: =-('PT Recap costs'!H68+'PT Recap costs'!H69)/1000 -> -120 | K25: =-('PT Recap costs'!I68+'PT Recap costs'!I69)/1000 -> -120 | ... O25: =-('PT Recap costs'!M68+'PT Recap costs'!M69)/1000 -> -131.275 | P25: =SUM(D25:O25) -> -888.825
C26: Other | D26: =-('PT Recap costs'!B72+'PT Recap costs'!B73)/1000-'Recap costs'!H31/1000-'Recap costs'!H60/1000-'Recap costs'!H61/1000 -> -161.743 | E26: =-('PT Recap costs'!C72+'PT Recap costs'!C73)/1000-'Recap costs'!I31/1000-'Recap costs'!I60/1000-'Recap costs'!I61/1000 -> -161.743 | F26: =-('PT Recap costs'!D72+'PT Recap costs'!D73)/1000-'Recap costs'!J31/1000-'Recap costs'!J60/1000-'Recap costs'!J61/1000 -> -183.843 | G26: =-('PT Recap costs'!E72+'PT Recap costs'!E73)/1000-'Recap costs'!K31/1000-'Recap costs'!K60/1000-'Recap costs'!K61/1000 -> -183.843 | H26: =-('PT Recap costs'!F72+'PT Recap costs'!F73)/1000-'Recap costs'!L31/1000-'Recap costs'!L60/1000-'Recap costs'!L61/1000 -> -211.843 | I26: =-('PT Recap costs'!G72+'PT Recap costs'!G73)/1000-'Recap costs'!M31/1000-'Recap costs'!M60/1000-'Recap costs'!M61/1000 -> -211.843 | J26: =-('PT Recap costs'!H72+'PT Recap costs'!H73)/1000-'Recap costs'!N31/1000-'Recap costs'!N60/1000-'Recap costs'!N61/1000 -> -211.843 | K26: =-('PT Recap costs'!I72+'PT Recap costs'!I73)/1000-'Recap costs'!O31/1000-'Recap costs'!O60/1000-'Recap costs'!O61/1000 -> -211.843 | ... O26: =-('PT Recap costs'!M72+'PT Recap costs'!M73)/1000-'Recap costs'!S31/1000-'Recap costs'!S60/1000-'Recap costs'!S61/1000 -> -211.843 | P26: =SUM(D26:O26) -> -2385.916
A27: 13 | B27: HR/Admin | C27: Recruitment | D27: =-'Recap costs'!H34/1000 -> -30 | E27: =-'Recap costs'!I34/1000 -> -60 | F27: =-'Recap costs'!J34/1000 -> 0 | G27: =-'Recap costs'!K34/1000 -> -40 | H27: =-'Recap costs'!L34/1000 -> -40 | I27: =-'Recap costs'!M34/1000 -> 0 | J27: =-'Recap costs'!N34/1000 -> -10 | K27: =-'Recap costs'!O34/1000 -> -30 | ... O27: =-'Recap costs'!S34/1000 -> -10 | P27: =SUM(D27:O27) -> -250
A28: 14 | B28: HR/Admin | C28: Training | D28: =-'Recap costs'!H35/1000 -> -10.5 | E28: =-'Recap costs'!I35/1000 -> -12.5 | F28: =-'Recap costs'!J35/1000 -> -13.5 | G28: =-'Recap costs'!K35/1000 -> -13.5 | H28: =-'Recap costs'!L35/1000 -> -12.5 | I28: =-'Recap costs'!M35/1000 -> -12.5 | J28: =-'Recap costs'!N35/1000 -> -12.5 | K28: =-'Recap costs'!O35/1000 -> -12.5 | ... O28: =-'Recap costs'!S35/1000 -> -13 | P28: =SUM(D28:O28) -> -152
A29: 15 | B29: Travel | C29: Travel | D29: =-('Recap costs'!H75+'Recap costs'!H76+'Recap costs'!H77+'Recap costs'!H78+'Recap costs'!H79+'Recap costs'!H80)/1000 -> -22.5 | E29: =-('Recap costs'!I75+'Recap costs'!I76+'Recap costs'!I77+'Recap costs'!I78+'Recap costs'!I79+'Recap costs'!I80)/1000 -> -22.5 | F29: =-('Recap costs'!J75+'Recap costs'!J76+'Recap costs'!J77+'Recap costs'!J78+'Recap costs'!J79+'Recap costs'!J80)/1000 -> -22.5 | G29: =-('Recap costs'!K75+'Recap costs'!K76+'Recap costs'!K77+'Recap costs'!K78+'Recap costs'!K79+'Recap costs'!K80)/1000 -> -22.5 | H29: =-('Recap costs'!L75+'Recap costs'!L76+'Recap costs'!L77+'Recap costs'!L78+'Recap costs'!L79+'Recap costs'!L80)/1000 -> -30 | I29: =-('Recap costs'!M75+'Recap costs'!M76+'Recap costs'!M77+'Recap costs'!M78+'Recap costs'!M79+'Recap costs'!M80)/1000 -> -30 | J29: =-('Recap costs'!N75+'Recap costs'!N76+'Recap costs'!N77+'Recap costs'!N78+'Recap costs'!N79+'Recap costs'!N80)/1000 -> -30 | K29: =-('Recap costs'!O75+'Recap costs'!O76+'Recap costs'!O77+'Recap costs'!O78+'Recap costs'!O79+'Recap costs'!O80)/1000 -> -30 | ... O29: =-('Recap costs'!S75+'Recap costs'!S76+'Recap costs'!S77+'Recap costs'!S78+'Recap costs'!S79+'Recap costs'!S80)/1000 -> -30 | P29: =SUM(D29:O29) -> -330
A30: 16 | C30: Consultancies | D30: =SUM(D31:D37) -> -137.86433 | E30: =SUM(E31:E37) -> -137.86433 | F30: =SUM(F31:F37) -> -130.86433 | G30: =SUM(G31:G37) -> -130.86433 | H30: =SUM(H31:H37) -> -85.864333 | I30: =SUM(I31:I37) -> -85.864333 | J30: =SUM(J31:J37) -> -85.864333 | K30: =SUM(K31:K37) -> -85.864333 | ... O30: =SUM(O31:O37) -> -85.864333 | P30: =SUM(D30:O30) -> -1224.372
C31: T1 -Hospital market: Baxter & DIM 3 Pilot | D31: =-'PT Recap costs'!B47/1000-'PT Recap costs'!B34/1000 -> -8.0615556 | E31: =-'PT Recap costs'!C47/1000-'PT Recap costs'!C34/1000 -> -8.0615556 | F31: =-'PT Recap costs'!D47/1000-'PT Recap costs'!D34/1000 -> -8.0615556 | G31: =-'PT Recap costs'!E47/1000-'PT Recap costs'!E34/1000 -> -8.0615556 | H31: =-'PT Recap costs'!F47/1000-'PT Recap costs'!F34/1000 -> -8.0615556 | I31: =-'PT Recap costs'!G47/1000-'PT Recap costs'!G34/1000 -> -8.0615556 | J31: =-'PT Recap costs'!H47/1000-'PT Recap costs'!H34/1000 -> -8.0615556 | K31: =-'PT Recap costs'!I47/1000-'PT Recap costs'!I34/1000 -> -8.0615556 | ... O31: =-'PT Recap costs'!M47/1000-'PT Recap costs'!M34/1000 -> -8.0615556 | P31: =SUM(D31:O31) -> -96.738667
C32: T2 - Homecare market: Vivisol | D32: =-'PT Recap costs'!B51/1000-'PT Recap costs'!B37/1000 -> -5.0555556 | E32: =-'PT Recap costs'!C51/1000-'PT Recap costs'!C37/1000 -> -5.0555556 | F32: =-'PT Recap costs'!D51/1000-'PT Recap costs'!D37/1000 -> -5.0555556 | G32: =-'PT Recap costs'!E51/1000-'PT Recap costs'!E37/1000 -> -5.0555556 | H32: =-'PT Recap costs'!F51/1000-'PT Recap costs'!F37/1000 -> -5.0555556 | I32: =-'PT Recap costs'!G51/1000-'PT Recap costs'!G37/1000 -> -5.0555556 | J32: =-'PT Recap costs'!H51/1000-'PT Recap costs'!H37/1000 -> -5.0555556 | K32: =-'PT Recap costs'!I51/1000-'PT Recap costs'!I37/1000 -> -5.0555556 | ... O32: =-'PT Recap costs'!M51/1000-'PT Recap costs'!M37/1000 -> -5.0555556 | P32: =SUM(D32:O32) -> -60.666667
C33: T3 - Nutrow & Feedim evolution | D33: =-'PT Recap costs'!B55/1000-'PT Recap costs'!B29/1000 -> -75.555556 | E33: =-'PT Recap costs'!C55/1000-'PT Recap costs'!C29/1000 -> -75.555556 | F33: =-'PT Recap costs'!D55/1000-'PT Recap costs'!D29/1000 -> -75.555556 | G33: =-'PT Recap costs'!E55/1000-'PT Recap costs'!E29/1000 -> -75.555556 | H33: =-'PT Recap costs'!F55/1000-'PT Recap costs'!F29/1000 -> -30.555556 | I33: =-'PT Recap costs'!G55/1000-'PT Recap costs'!G29/1000 -> -30.555556 | J33: =-'PT Recap costs'!H55/1000-'PT Recap costs'!H29/1000 -> -30.555556 | K33: =-'PT Recap costs'!I55/1000-'PT Recap costs'!I29/1000 -> -30.555556 | ... O33: =-'PT Recap costs'!M55/1000-'PT Recap costs'!M29/1000 -> -30.555556 | P33: =SUM(D33:O33) -> -546.66667
C34: T4 - Oncology: development | D34: =-'PT Recap costs'!B59/1000-'PT Recap costs'!B40/1000 -> -0.55555556 | E34: =-'PT Recap costs'!C59/1000-'PT Recap costs'!C40/1000 -> -0.55555556 | F34: =-'PT Recap costs'!D59/1000-'PT Recap costs'!D40/1000 -> -0.55555556 | G34: =-'PT Recap costs'!E59/1000-'PT Recap costs'!E40/1000 -> -0.55555556 | H34: =-'PT Recap costs'!F59/1000-'PT Recap costs'!F40/1000 -> -0.55555556 | I34: =-'PT Recap costs'!G59/1000-'PT Recap costs'!G40/1000 -> -0.55555556 | J34: =-'PT Recap costs'!H59/1000-'PT Recap costs'!H40/1000 -> -0.55555556 | K34: =-'PT Recap costs'!I59/1000-'PT Recap costs'!I40/1000 -> -0.55555556 | ... O34: =-'PT Recap costs'!M59/1000-'PT Recap costs'!M40/1000 -> -0.55555556 | P34: =SUM(D34:O34) -> -6.6666667
C35: T5 - Operations organisation (Services): Installation & Interfaçage | D35: =-'PT Recap costs'!B63/1000-'PT Recap costs'!B13/1000 -> -1.5555556 | E35: =-'PT Recap costs'!C63/1000-'PT Recap costs'!C13/1000 -> -1.5555556 | F35: =-'PT Recap costs'!D63/1000-'PT Recap costs'!D13/1000 -> -1.5555556 | G35: =-'PT Recap costs'!E63/1000-'PT Recap costs'!E13/1000 -> -1.5555556 | H35: =-'PT Recap costs'!F63/1000-'PT Recap costs'!F13/1000 -> -1.5555556 | I35: =-'PT Recap costs'!G63/1000-'PT Recap costs'!G13/1000 -> -1.5555556 | J35: =-'PT Recap costs'!H63/1000-'PT Recap costs'!H13/1000 -> -1.5555556 | K35: =-'PT Recap costs'!I63/1000-'PT Recap costs'!I13/1000 -> -1.5555556 | ... O35: =-'PT Recap costs'!M63/1000-'PT Recap costs'!M13/1000 -> -1.5555556 | P35: =SUM(D35:O35) -> -18.666667
C36: T6 - OEM Feedim | D36: =-'PT Recap costs'!B67/1000-'PT Recap costs'!B25/1000 -> -0.55555556 | E36: =-'PT Recap costs'!C67/1000-'PT Recap costs'!C25/1000 -> -0.55555556 | F36: =-'PT Recap costs'!D67/1000-'PT Recap costs'!D25/1000 -> -0.55555556 | G36: =-'PT Recap costs'!E67/1000-'PT Recap costs'!E25/1000 -> -0.55555556 | H36: =-'PT Recap costs'!F67/1000-'PT Recap costs'!F25/1000 -> -0.55555556 | I36: =-'PT Recap costs'!G67/1000-'PT Recap costs'!G25/1000 -> -0.55555556 | J36: =-'PT Recap costs'!H67/1000-'PT Recap costs'!H25/1000 -> -0.55555556 | K36: =-'PT Recap costs'!I67/1000-'PT Recap costs'!I25/1000 -> -0.55555556 | ... O36: =-'PT Recap costs'!M67/1000-'PT Recap costs'!M25/1000 -> -0.55555556 | P36: =SUM(D36:O36) -> -6.6666667
C37: Other | D37: =-'PT Recap costs'!B71/1000-('Recap costs'!H24+'Recap costs'!H26+'Recap costs'!H27+'Recap costs'!H32+'Recap costs'!H2)/1000 -> -46.525 | E37: =-'PT Recap costs'!C71/1000-('Recap costs'!I24+'Recap costs'!I26+'Recap costs'!I27+'Recap costs'!I32+'Recap costs'!I2)/1000 -> -46.525 | F37: =-'PT Recap costs'!D71/1000-('Recap costs'!J24+'Recap costs'!J26+'Recap costs'!J27+'Recap costs'!J32+'Recap costs'!J2)/1000 -> -39.525 | G37: =-'PT Recap costs'!E71/1000-('Recap costs'!K24+'Recap costs'!K26+'Recap costs'!K27+'Recap costs'!K32+'Recap costs'!K2)/1000 -> -39.525 | H37: =-'PT Recap costs'!F71/1000-('Recap costs'!L24+'Recap costs'!L26+'Recap costs'!L27+'Recap costs'!L32+'Recap costs'!L2)/1000 -> -39.525 | I37: =-'PT Recap costs'!G71/1000-('Recap costs'!M24+'Recap costs'!M26+'Recap costs'!M27+'Recap costs'!M32+'Recap costs'!M2)/1000 -> -39.525 | J37: =-'PT Recap costs'!H71/1000-('Recap costs'!N24+'Recap costs'!N26+'Recap costs'!N27+'Recap costs'!N32+'Recap costs'!N2)/1000 -> -39.525 | K37: =-'PT Recap costs'!I71/1000-('Recap costs'!O24+'Recap costs'!O26+'Recap costs'!O27+'Recap costs'!O32+'Recap costs'!O2)/1000 -> -39.525 | ... O37: =-'PT Recap costs'!M71/1000-('Recap costs'!S24+'Recap costs'!S26+'Recap costs'!S27+'Recap costs'!S32+'Recap costs'!S2)/1000 -> -39.525 | P37: =SUM(D37:O37) -> -488.3
A38: 17 | B38: Other costs | C38: IP & patents costs | D38: =-'Recap costs'!H54/1000 -> -0.3453767 | E38: =-'Recap costs'!I54/1000 -> -0.61202251 | F38: =-'Recap costs'!J54/1000 -> -0.8291209 | G38: =-'Recap costs'!K54/1000 -> -3.569079 | H38: =-'Recap costs'!L54/1000 -> -3.4134619 | I38: =-'Recap costs'!M54/1000 -> -4.3071385 | J38: =-'Recap costs'!N54/1000 -> -5.015193 | K38: =-'Recap costs'!O54/1000 -> -5.7232474 | ... O38: =-'Recap costs'!S54/1000 -> -9.04634 | P38: =SUM(D38:O38) -> -60
A39: 18 | B39: Marketing | C39: Marketing & communication | D39: =-'Recap costs'!H62/1000 -> -1.7268835 | E39: =-'Recap costs'!I62/1000 -> -3.0601125 | F39: =-'Recap costs'!J62/1000 -> -4.1456045 | G39: =-'Recap costs'!K62/1000 -> -17.845395 | H39: =-'Recap costs'!L62/1000 -> -17.06731 | I39: =-'Recap costs'!M62/1000 -> -21.535693 | J39: =-'Recap costs'!N62/1000 -> -25.075965 | K39: =-'Recap costs'!O62/1000 -> -28.616237 | ... O39: =-'Recap costs'!S62/1000 -> -45.2317 | P39: =SUM(D39:O39) -> -300
A40: 19 | B40: Other costs | C40: Shipment in & out | D40: =-'Recap costs'!H55/1000 -> -0.06907534 | E40: =-'Recap costs'!I55/1000 -> -0.1224045 | F40: =-'Recap costs'!J55/1000 -> -0.16582418 | G40: =-'Recap costs'!K55/1000 -> -0.7138158 | H40: =-'Recap costs'!L55/1000 -> -0.68269239 | I40: =-'Recap costs'!M55/1000 -> -0.86142771 | J40: =-'Recap costs'!N55/1000 -> -1.0030386 | K40: =-'Recap costs'!O55/1000 -> -1.1446495 | ... O40: =-'Recap costs'!S55/1000 -> -1.809268 | P40: =SUM(D40:O40) -> -12
A41: 20 | B41: Other costs | C41: Small equipment | D41: =-'Recap costs'!H56/1000 -> -0.12951626 | E41: =-'Recap costs'!I56/1000 -> -0.22950844 | F41: =-'Recap costs'!J56/1000 -> -0.31092034 | G41: =-'Recap costs'!K56/1000 -> -1.3384046 | H41: =-'Recap costs'!L56/1000 -> -1.2800482 | I41: =-'Recap costs'!M56/1000 -> -1.6151769 | J41: =-'Recap costs'!N56/1000 -> -1.8806974 | K41: =-'Recap costs'!O56/1000 -> -2.1462178 | ... O41: =-'Recap costs'!S56/1000 -> -3.3923775 | P41: =SUM(D41:O41) -> -22.5
A42: 21 | B42: Other costs | C42: Software & licences | D42: =-'Recap costs'!H57/1000 -> -0.86344175 | E42: =-'Recap costs'!I57/1000 -> -1.5300563 | F42: =-'Recap costs'!J57/1000 -> -2.0728022 | G42: =-'Recap costs'!K57/1000 -> -8.9226975 | H42: =-'Recap costs'!L57/1000 -> -8.5336548 | I42: =-'Recap costs'!M57/1000 -> -10.767846 | J42: =-'Recap costs'!N57/1000 -> -12.537982 | K42: =-'Recap costs'!O57/1000 -> -14.308118 | ... O42: =-'Recap costs'!S57/1000 -> -22.61585 | P42: =SUM(D42:O42) -> -150
...

Sheet 3 Cash Flow
A1: ALL AMOUNTS IN KEUR | B1: BP 21-23 | C1: Q1 21 | D1: Q2 21 | E1: Q3 21 | F1: Q4 21 | G1: BP 2021 | H1: Q1 22 | I1: Q2 22 | J1: Q3 22 | K1: Q4 22 | L1: BP 2022 | M1: Q1 23 | N1: Q2 23 | O1: Q3 23 | P1: Q4 23 | Q1: BP 2023 | R1: TOTAL
A2: Gross cash flow (EBITDA) | B2: ='2 P&L'!P50 -> 2374.2 | C2: ='2 P&L'!D50 -> -331.38231 | D2: ='2 P&L'!E50 -> -494.48941 | E2: ='2 P&L'!F50 -> -420.36903 | F2: ='2 P&L'!G50 -> -135.87077 | G2: =SUM(C2:F2) -> -1382.1115 | H2: ='2 P&L'!H50 -> -135.54106 | I2: ='2 P&L'!I50 -> 109.05521 | J2: ='2 P&L'!J50 -> 170.41798 | K2: ='2 P&L'!K50 -> 254.03076 | L2: =SUM(H2:K2) -> 397.96288 | M2: ='2 P&L'!L50 -> 863.41215 | N2: ='2 P&L'!M50 -> 828.31215 | O2: ='2 P&L'!N50 -> 838.31215 | P2: ='2 P&L'!O50 -> 828.31215 | Q2: =SUM(M2:P2) -> 3358.3486 | R2: =G2+L2+Q2 -> 2374.2
A3: Suppliers - WK changes (30 days) | B3: =-'2 P&L'!O48/3 -> 82.985112 | C3: =-'2 P&L'!D48/3 -> 74.550389 | D3: ='2 P&L'!D48/3-'2 P&L'!E48/3 -> 11.512526 | E3: ='2 P&L'!E48/3-'2 P&L'!F48/3 -> -21.311316 | F3: ='2 P&L'!F48/3-'2 P&L'!G48/3 -> 22.025089 | G3: =SUM(C3:F3) -> 86.776689 | H3: ='2 P&L'!G48/3-'2 P&L'!H48/3 -> -12.660319 | I3: ='2 P&L'!H48/3-'2 P&L'!I48/3 -> -10.498393 | J3: ='2 P&L'!I48/3-'2 P&L'!J48/3 -> 5.5794393 | K3: ='2 P&L'!J48/3-'2 P&L'!K48/3 -> 8.9127727 | L3: =SUM(H3:K3) -> -8.6664991 | M3: ='2 P&L'!K48/3-'2 P&L'!L48/3 -> 8.208255 | N3: ='2 P&L'!L48/3-'2 P&L'!M48/3 -> -3.3333333 | O3: ='2 P&L'!M48/3-'2 P&L'!N48/3 -> -3.3333333 | P3: ='2 P&L'!N48/3-'2 P&L'!O48/3 -> 3.3333333 | Q3: =SUM(M3:P3) -> 4.8749216 | R3: =G3+L3+Q3 -> 82.985112
A4: Clients - WK changes (60 days) | B4: =-'2 P&L'!O12*2/3 -> -1462.057 | C4: =-'2 P&L'!D12*2/3 -> -55.819308 | D4: =-C4-'2 P&L'!E12/3*2 -> -43.094929 | E4: ='2 P&L'!E12/3*2-'2 P&L'!F12/3*2 -> -35.087144 | F4: ='2 P&L'!F12/3*2-'2 P&L'!G12/3*2 -> -442.82826 | G4: =SUM(C4:F4) -> -576.82964 | H4: ='2 P&L'!G12/3*2-'2 P&L'!H12/3*2 -> 25.150614 | I4: ='2 P&L'!H12/3*2-'2 P&L'!I12/3*2 -> -144.43478 | J4: ='2 P&L'!I12/3*2-'2 P&L'!J12/3*2 -> -114.43478 | K4: ='2 P&L'!J12/3*2-'2 P&L'!K12/3*2 -> -114.43478 | L4: =SUM(H4:K4) -> -348.15374 | M4: ='2 P&L'!K12/3*2-'2 P&L'!L12/3*2 -> -537.07367 | N4: ='2 P&L'!L12/3*2-'2 P&L'!M12/3*2 -> 0 | O4: ='2 P&L'!M12/3*2-'2 P&L'!N12/3*2 -> 0 | P4: ='2 P&L'!N12/3*2-'2 P&L'!O12/3*2 -> 0 | Q4: =SUM(M4:P4) -> -537.07367 | R4: =G4+L4+Q4 -> -1462.057
A5: Inventory | B5: =-'2 P&L'!P14 -> 0 | C5: =-'2 P&L'!D14 -> 0 | D5: =-'2 P&L'!E14 -> 0 | E5: =-'2 P&L'!F14 -> 0 | F5: =-'2 P&L'!G14 -> 0 | G5: =SUM(C5:F5) -> 0 | H5: =-'2 P&L'!H14 -> 0 | I5: =-'2 P&L'!I14 -> 0 | J5: =-'2 P&L'!J14 -> 0 | K5: =-'2 P&L'!K14 -> 0 | L5: =SUM(H5:K5) -> 0 | M5: =-'2 P&L'!L14 -> 0 | N5: =-'2 P&L'!M14 -> 0 | O5: =-'2 P&L'!N14 -> 0 | P5: =-'2 P&L'!O14 -> 0 | Q5: =SUM(M5:P5) -> 0 | R5: =G5+L5+Q5 -> 0
A6: CASH FROM OPERATING ACTIVITIES | B6: =SUM(B2:B5) -> 995.12802 | C6: =SUM(C2:C5) -> -312.65123 | D6: =SUM(D2:D5) -> -526.07181 | E6: =SUM(E2:E5) -> -476.76748 | F6: =SUM(F2:F5) -> -556.67394 | G6: =SUM(G2:G5) -> -1872.1645 | H6: =SUM(H2:H5) -> -123.05077 | I6: =SUM(I2:I5) -> -45.87797 | ... Q6: =SUM(Q2:Q5) -> 2826.1498 | R6: =G6+L6+Q6 -> 995.12802
A7: CAPEX | B7: ='2 P&L'!P66 -> -400 | C7: ='2 P&L'!D66 -> -33.333333 | D7: ='2 P&L'!E66 -> -33.333333 | E7: ='2 P&L'!F66 -> -33.333333 | F7: ='2 P&L'!G66 -> -33.333333 | G7: =SUM(C7:F7) -> -133.33333 | H7: ='2 P&L'!H66 -> -33.333333 | I7: ='2 P&L'!I66 -> -33.333333 | J7: ='2 P&L'!J66 -> -33.333333 | K7: ='2 P&L'!K66 -> -33.333333 | L7: =SUM(H7:K7) -> -133.33333 | M7: ='2 P&L'!L66 -> -33.333333 | N7: ='2 P&L'!M66 -> -33.333333 | O7: ='2 P&L'!N66 -> -33.333333 | P7: ='2 P&L'!O66 -> -33.333333 | Q7: =SUM(M7:P7) -> -133.33333 | R7: =G7+L7+Q7 -> -400
A8: R&D and other capitalised costs | B8: ='2 P&L'!P67 -> -2548.325 | C8: ='2 P&L'!D67 -> -138.50625 | D8: ='2 P&L'!E67 -> -138.50625 | E8: ='2 P&L'!F67 -> -138.50625 | F8: ='2 P&L'!G67 -> -185.25625 | G8: =SUM(C8:F8) -> -600.775 | H8: ='2 P&L'!H67 -> -311.50625 | I8: ='2 P&L'!I67 -> -281.25625 | J8: ='2 P&L'!J67 -> -218.00625 | K8: ='2 P&L'!K67 -> -218.00625 | L8: =SUM(H8:K8) -> -1028.775 | M8: ='2 P&L'!L67 -> -218.00625 | N8: ='2 P&L'!M67 -> -218.00625 | O8: ='2 P&L'!N67 -> -218.00625 | P8: ='2 P&L'!O67 -> -264.75625 | Q8: =SUM(M8:P8) -> -918.775 | R8: =G8+L8+Q8 -> -2548.325
A9: CASH FROM INVESTING ACTIVITIES | B9: =SUM(B7:B8) -> -2948.325 | C9: =SUM(C7:C8) -> -171.83958 | D9: =SUM(D7:D8) -> -171.83958 | E9: =SUM(E7:E8) -> -171.83958 | F9: =SUM(F7:F8) -> -218.58958 | G9: =SUM(G7:G8) -> -734.10833 | H9: =SUM(H7:H8) -> -344.83958 | I9: =SUM(I7:I8) -> -314.58958 | ... Q9: =SUM(Q7:Q8) -> -1052.1083 | R9: =G9+L9+Q9 -> -2948.325
A10: Capital increase | B10: 6000 | C10: 3000 | D10: 0 | E10: 0 | F10: 1000 | G10: =SUM(C10:F10) -> 4000 | H10: 0 | I10: 2000 | J10: 0 | K10: 0 | L10: =SUM(H10:K10) -> 2000 | M10: 0 | N10: 0 | O10: 0 | P10: 0 | Q10: =SUM(M10:P10) -> 0 | R10: =G10+L10+Q10 -> 6000
A11: New funding | B11: ='2 P&L'!P71 -> 0 | C11: ='2 P&L'!D71 -> 0 | D11: ='2 P&L'!E71 -> 0 | E11: ='2 P&L'!F71 -> 0 | F11: ='2 P&L'!G71 -> 0 | G11: =SUM(C11:F11) -> 0 | H11: ='2 P&L'!H71 -> 0 | I11: ='2 P&L'!I71 -> 0 | J11: ='2 P&L'!J71 -> 0 | K11: ='2 P&L'!K71 -> 0 | L11: =SUM(H11:K11) -> 0 | M11: ='2 P&L'!L71 -> 0 | N11: ='2 P&L'!M71 -> 0 | O11: ='2 P&L'!N71 -> 0 | P11: ='2 P&L'!O71 -> 0 | Q11: =SUM(M11:P11) -> 0 | R11: =G11+L11+Q11 -> 0
A12: Loan reimbursement | B12: ='2 P&L'!P72 -> 0 | C12: ='2 P&L'!D72 -> 0 | D12: ='2 P&L'!E72 -> 0 | E12: ='2 P&L'!F72 -> 0 | F12: ='2 P&L'!G72 -> 0 | G12: =SUM(C12:F12) -> 0 | H12: ='2 P&L'!H72 -> 0 | I12: ='2 P&L'!I72 -> 0 | J12: ='2 P&L'!J72 -> 0 | K12: ='2 P&L'!K72 -> 0 | L12: =SUM(H12:K12) -> 0 | M12: ='2 P&L'!L72 -> 0 | N12: ='2 P&L'!M72 -> 0 | O12: ='2 P&L'!N72 -> 0 | P12: ='2 P&L'!O72 -> 0 | Q12: =SUM(M12:P12) -> 0 | R12: =G12+L12+Q12 -> 0
A13: Financial costs/ income | B13: ='2 P&L'!P73 -> -24 | C13: ='2 P&L'!D73 -> -2 | D13: ='2 P&L'!E73 -> -2 | E13: ='2 P&L'!F73 -> -2 | F13: ='2 P&L'!G73 -> -2 | G13: =SUM(C13:F13) -> -8 | H13: ='2 P&L'!H73 -> -2 | I13: ='2 P&L'!I73 -> -2 | J13: ='2 P&L'!J73 -> -2 | K13: ='2 P&L'!K73 -> -2 | L13: =SUM(H13:K13) -> -8 | M13: ='2 P&L'!L73 -> -2 | N13: ='2 P&L'!M73 -> -2 | O13: ='2 P&L'!N73 -> -2 | P13: ='2 P&L'!O73 -> -2 | Q13: =SUM(M13:P13) -> -8 | R13: =G13+L13+Q13 -> -24
A14: Subsidies | B14: ='2 P&L'!P74 -> 0 | C14: ='2 P&L'!D74 -> 0 | D14: ='2 P&L'!E74 -> 0 | E14: ='2 P&L'!F74 -> 0 | F14: ='2 P&L'!G74 -> 0 | G14: =SUM(C14:F14) -> 0 | H14: ='2 P&L'!H74 -> 0 | I14: ='2 P&L'!I74 -> 0 | J14: ='2 P&L'!J74 -> 0 | K14: ='2 P&L'!K74 -> 0 | L14: =SUM(H14:K14) -> 0 | M14: ='2 P&L'!L74 -> 0 | N14: ='2 P&L'!M74 -> 0 | O14: ='2 P&L'!N74 -> 0 | P14: ='2 P&L'!O74 -> 0 | Q14: =SUM(M14:P14) -> 0 | R14: =G14+L14+Q14 -> 0
A15: CASH FROM FINANCING ACTIVITIES | B15: =SUM(B10:B14) -> 5976 | C15: =SUM(C10:C14) -> 2998 | D15: =SUM(D10:D14) -> -2 | E15: =SUM(E10:E14) -> -2 | F15: =SUM(F10:F14) -> 998 | G15: =SUM(G10:G14) -> 3992 | H15: =SUM(H10:H14) -> -2 | I15: =SUM(I10:I14) -> 1998 | ... Q15: =SUM(Q10:Q14) -> -8 | R15: =G15+L15+Q15 -> 5976
A17: NET CASH VARIATION | B17: =B6+B9+B15 -> 4022.803 | C17: =C6+C9+C15 -> 2513.5092 | D17: =D6+D9+D15 -> -699.9114 | E17: =E6+E9+E15 -> -650.60707 | F17: =F6+F9+F15 -> 222.73647 | G17: =G6+G9+G15 -> 1385.7272 | H17: =H6+H9+H15 -> -469.89035 | I17: =I6+I9+I15 -> 1637.5324 | ... Q17: =Q6+Q9+Q15 -> 1766.0415 | R17: =G17+L17+Q17 -> 4022.803
A19: OPENING CASH 01/01/2021 | B19: 0 | C19: =B19 -> 0 | D19: =C20 -> 2513.5092 | E19: =D20 -> 1813.5978 | F19: =E20 -> 1162.9907 | G19: =B19 -> 0 | H19: =F20 -> 1385.7272 | I19: =H20 -> 915.83685 | J19: =I20 -> 2553.3693 | K19: =J20 -> 2361.5923 | L19: =G20 -> 1385.7272 | M19: =K20 -> 2256.7615 | N19: =M20 -> 2337.9687 | O19: =N20 -> 2909.6079 | P19: =O20 -> 3491.2471 | Q19: =L20 -> 2256.7615 | R19: 0
A20: CLOSING CASH 31/12/2023 | B20: =B17+B19 -> 4022.803 | C20: =C17+C19 -> 2513.5092 | D20: =D17+D19 -> 1813.5978 | E20: =E17+E19 -> 1162.9907 | F20: =F17+F19 -> 1385.7272 | G20: =G17+G19 -> 1385.7272 | H20: =H17+H19 -> 915.83685 | I20: =I17+I19 -> 2553.3693 | ... R20: =R17+R19 -> 4022.803
B21: =B20-B3-B4-B5-B10-'2 P&L'!P77 -> 0

Sheet Tableau recap
E3: Q1 21 | F3: Q2 21 | G3: Q3 21 | H3: Q4 21 | I3: Q1 22 | J3: Q2 22 | K3: Q3 22 | L3: Q4 22 | M3: Q1 23 | N3: Q2 23 | O3: Q3 23 | P3: Q4 23 | Q3: Total
B4: T1 | C4: Hospital market: Baxter & DIM 3 Pilot | D4: Cash in from Revenue | E4: 23.585794 | F4: 47.171589 | G4: 99.51492 | H4: 373.10071 | I4: 280.07969 | J4: 402.23186 | K4: 524.38404 | L4: 646.53622 | M4: 1210.0564 | N4: 1210.0564 | O4: 1210.0564 | P4: 1210.0564 | Q4: =SUM(E4:P4) -> 7236.8303
D5: COSTS | E5: =-SUM(E6:E11) -> -25.42976 | F5: =-SUM(F6:F11) -> -95.429041 | G5: =-SUM(G6:G11) -> -96.992509 | H5: =-SUM(H6:H11) -> -120.10429 | I5: =-SUM(I6:I11) -> -129.17574 | J5: =-SUM(J6:J11) -> -132.72682 | K5: =-SUM(K6:K11) -> -136.27791 | L5: =-SUM(L6:L11) -> -139.82899 | ... Q5: =-SUM(Q6:Q11) -> -1505.898
D6: COGS | E6: =COGS!C8/1000 -> 0.56178083 | F6: =COGS!D8/1000 -> 1.1235617 | G6: =COGS!E8/1000 -> 2.68703 | H6: =COGS!F8/1000 -> 3.2488108 | I6: =COGS!G8/1000 -> 8.7452615 | J6: =COGS!H8/1000 -> 12.296344 | K6: =COGS!I8/1000 -> 15.847427 | L6: =COGS!J8/1000 -> 19.39851 | ... P6: =COGS!N8/1000 -> 28.596518 | Q6: =SUM(E6:P6) -> 178.2948
D7: Consultancies | E7: ='PT Recap costs'!B47/1000 -> 7.506 | F7: ='PT Recap costs'!C47/1000 -> 7.506 | G7: ='PT Recap costs'!D47/1000 -> 7.506 | H7: ='PT Recap costs'!E47/1000 -> 7.506 | I7: ='PT Recap costs'!F47/1000 -> 7.506 | J7: ='PT Recap costs'!G47/1000 -> 7.506 | K7: ='PT Recap costs'!H47/1000 -> 7.506 | L7: ='PT Recap costs'!I47/1000 -> 7.506 | ... P7: ='PT Recap costs'!M47/1000 -> 7.506 | Q7: =SUM(E7:P7) -> 90.072
D8: Development & op. | E8: ='PT Recap costs'!B48/1000 -> 0 | F8: ='PT Recap costs'!C48/1000 -> 0 | G8: ='PT Recap costs'!D48/1000 -> 0 | H8: ='PT Recap costs'!E48/1000 -> 0 | I8: ='PT Recap costs'!F48/1000 -> 0 | J8: ='PT Recap costs'!G48/1000 -> 0 | K8: ='PT Recap costs'!H48/1000 -> 0 | L8: ='PT Recap costs'!I48/1000 -> 0 | ... P8: ='PT Recap costs'!M48/1000 -> 0 | Q8: =SUM(E8:P8) -> 0
D9: E&F | E9: ='PT Recap costs'!B49/1000 -> 13.47309 | F9: ='PT Recap costs'!C49/1000 -> 82.91059 | G9: ='PT Recap costs'!D49/1000 -> 82.91059 | H9: ='PT Recap costs'!E49/1000 -> 105.46059 | I9: ='PT Recap costs'!F49/1000 -> 109.03559 | J9: ='PT Recap costs'!G49/1000 -> 109.03559 | K9: ='PT Recap costs'!H49/1000 -> 109.03559 | L9: ='PT Recap costs'!I49/1000 -> 109.03559 | ... P9: ='PT Recap costs'!M49/1000 -> 120.31059 | Q9: =SUM(E9:P9) -> 1190.8646
D10: Legal | E10: ='PT Recap costs'!B34/1000 -> 0.55555556 | F10: ='PT Recap costs'!C34/1000 -> 0.55555556 | G10: ='PT Recap costs'!D34/1000 -> 0.55555556 | H10: ='PT Recap costs'!E34/1000 -> 0.55555556 | I10: ='PT Recap costs'!F34/1000 -> 0.55555556 | J10: ='PT Recap costs'!G34/1000 -> 0.55555556 | K10: ='PT Recap costs'!H34/1000 -> 0.55555556 | L10: ='PT Recap costs'!I34/1000 -> 0.55555556 | ... P10: ='PT Recap costs'!M34/1000 -> 0.55555556 | Q10: =SUM(E10:P10) -> 6.6666667
D11: T&E | E11: ='PT Recap costs'!B35/1000 -> 3.3333333 | F11: ='PT Recap costs'!C35/1000 -> 3.3333333 | G11: ='PT Recap costs'!D35/1000 -> 3.3333333 | H11: ='PT Recap costs'!E35/1000 -> 3.3333333 | I11: ='PT Recap costs'!F35/1000 -> 3.3333333 | J11: ='PT Recap costs'!G35/1000 -> 3.3333333 | K11: ='PT Recap costs'!H35/1000 -> 3.3333333 | L11: ='PT Recap costs'!I35/1000 -> 3.3333333 | ... P11: ='PT Recap costs'!M35/1000 -> 3.3333333 | Q11: =SUM(E11:P11) -> 40
D12: NET | E12: =E4+E5 -> -1.8439657 | F12: =F4+F5 -> -48.257452 | G12: =G4+G5 -> 2.5224112 | H12: =H4+H5 -> 252.99642 | I12: =I4+I5 -> 150.90395 | J12: =J4+J5 -> 269.50504 | K12: =K4+K5 -> 388.10613 | L12: =L4+L5 -> 506.70723 | ... Q12: =Q4+Q5 -> 5730.9323
B14: T2 | C14: Homecare market: Vivisol | D14: Cash in from Revenue | E14: 12.018168 | F14: 35.574767 | G14: 53.362151 | H14: 76.918751 | I14: 238.18886 | J14: 238.18886 | K14: 238.18886 | L14: 238.18886 | M14: 485.3042 | N14: 485.3042 | O14: 485.3042 | P14: 485.3042 | Q14: =SUM(E14:P14) -> 3071.8461
D15: COSTS | E15: =-SUM(E16:E21) -> -23.648463 | F15: =-SUM(F16:F21) -> -98.861098 | G15: =-SUM(G16:G21) -> -102.64191 | H15: =-SUM(H16:H21) -> -130.199 | I15: =-SUM(I16:I21) -> -168.05288 | J15: =-SUM(J16:J21) -> -168.05288 | K15: =-SUM(K16:K21) -> -168.05288 | L15: =-SUM(L16:L21) -> -168.05288 | ... Q15: =-SUM(Q16:Q21) -> -1972.2238
D16: COGS | E16: =COGS!C10/1000 -> 1.7864844 | F16: =COGS!D10/1000 -> 7.5616194 | G16: =COGS!E10/1000 -> 11.342429 | H16: =COGS!F10/1000 -> 16.349519 | I16: =COGS!G10/1000 -> 50.628398 | J16: =COGS!H10/1000 -> 50.628398 | K16: =COGS!I10/1000 -> 50.628398 | L16: =COGS!J10/1000 -> 50.628398 | ... P16: =COGS!N10/1000 -> 110.28474 | Q16: =SUM(E16:P16) -> 680.69259
D17: Consultancies | E17: ='PT Recap costs'!B51/1000 -> 4.5 | F17: ='PT Recap costs'!C51/1000 -> 4.5 | G17: ='PT Recap costs'!D51/1000 -> 4.5 | H17: ='PT Recap costs'!E51/1000 -> 4.5 | I17: ='PT Recap costs'!F51/1000 -> 4.5 | J17: ='PT Recap costs'!G51/1000 -> 4.5 | K17: ='PT Recap costs'!H51/1000 -> 4.5 | L17: ='PT Recap costs'!I51/1000 -> 4.5 | ... P17: ='PT Recap costs'!M51/1000 -> 4.5 | Q17: =SUM(E17:P17) -> 54
D18: Development & op. | E18: ='PT Recap costs'!B52/1000 -> 0 | F18: ='PT Recap costs'!C52/1000 -> 0 | G18: ='PT Recap costs'!D52/1000 -> 0 | H18: ='PT Recap costs'!E52/1000 -> 0 | I18: ='PT Recap costs'!F52/1000 -> 0 | J18: ='PT Recap costs'!G52/1000 -> 0 | K18: ='PT Recap costs'!H52/1000 -> 0 | L18: ='PT Recap costs'!I52/1000 -> 0 | ... P18: ='PT Recap costs'!M52/1000 -> 0 | Q18: =SUM(E18:P18) -> 0
D19: E&F | E19: ='PT Recap costs'!B53/1000 -> 13.47309 | F19: ='PT Recap costs'!C53/1000 -> 82.91059 | G19: ='PT Recap costs'!D53/1000 -> 82.91059 | H19: ='PT Recap costs'!E53/1000 -> 105.46059 | I19: ='PT Recap costs'!F53/1000 -> 109.03559 | J19: ='PT Recap costs'!G53/1000 -> 109.03559 | K19: ='PT Recap costs'!H53/1000 -> 109.03559 | L19: ='PT Recap costs'!I53/1000 -> 109.03559 | ... P19: ='PT Recap costs'!M53/1000 -> 120.31059 | Q19: =SUM(E19:P19) -> 1190.8646
D20: Legal | E20: ='PT Recap costs'!B37/1000 -> 0.55555556 | F20: ='PT Recap costs'!C37/1000 -> 0.55555556 | G20: ='PT Recap costs'!D37/1000 -> 0.55555556 | H20: ='PT Recap costs'!E37/1000 -> 0.55555556 | I20: ='PT Recap costs'!F37/1000 -> 0.55555556 | J20: ='PT Recap costs'!G37/1000 -> 0.55555556 | K20: ='PT Recap costs'!H37/1000 -> 0.55555556 | L20: ='PT Recap costs'!I37/1000 -> 0.55555556 | ... P20: ='PT Recap costs'!M37/1000 -> 0.55555556 | Q20: =SUM(E20:P20) -> 6.6666667
D21: T&E | E21: ='PT Recap costs'!B38/1000 -> 3.3333333 | F21: ='PT Recap costs'!C38/1000 -> 3.3333333 | G21: ='PT Recap costs'!D38/1000 -> 3.3333333 | H21: ='PT Recap costs'!E38/1000 -> 3.3333333 | I21: ='PT Recap costs'!F38/1000 -> 3.3333333 | J21: ='PT Recap costs'!G38/1000 -> 3.3333333 | K21: ='PT Recap costs'!H38/1000 -> 3.3333333 | L21: ='PT Recap costs'!I38/1000 -> 3.3333333 | ... P21: ='PT Recap costs'!M38/1000 -> 3.3333333 | Q21: =SUM(E21:P21) -> 40
D22: NET | E22: =E14+E15 -> -11.630296 | F22: =F14+F15 -> -63.286331 | G22: =G14+G15 -> -49.279757 | H22: =H14+H15 -> -53.280247 | I22: =I14+I15 -> 70.135979 | J22: =J14+J15 -> 70.135979 | K22: =K14+K15 -> 70.135979 | L22: =L14+L15 -> 70.135979 | ... Q22: =Q14+Q15 -> 1099.6222
B24: T3 | C24: Nutrow & Feedim evolution | D24: Cash in from Revenue | E24: 0 | F24: 0 | G24: 0 | H24: 0 | I24: 0 | J24: 0 | K24: 0 | L24: 0 | M24: 0 | N24: 0 | O24: 0 | P24: 0 | Q24: =SUM(E24:P24) -> 0
D25: COSTS | E25: =-SUM(E26:E31) -> -181.23446 | F25: =-SUM(F26:F31) -> -183.98446 | G25: =-SUM(G26:G31) -> -179.27117 | H25: =-SUM(H26:H31) -> -259.02117 | I25: =-SUM(I26:I31) -> -248.98446 | J25: =-SUM(J26:J31) -> -218.73446 | K25: =-SUM(K26:K31) -> -141.73446 | L25: =-SUM(L26:L31) -> -180.23446 | ... Q25: =-SUM(Q26:Q31) -> -2536.887
D26: COGS | E26: =COGS!C12/1000 -> 0 | F26: =COGS!D12/1000 -> 0 | G26: =COGS!E12/1000 -> 0 | H26: =COGS!F12/1000 -> 0 | I26: =COGS!G12/1000 -> 0 | J26: =COGS!H12/1000 -> 0 | K26: =COGS!I12/1000 -> 0 | L26: =COGS!J12/1000 -> 0 | ... P26: =COGS!N12/1000 -> 0 | Q26: =SUM(E26:P26) -> 0
D27: Consultancies | E27: ='PT Recap costs'!B55/1000 -> 75 | F27: ='PT Recap costs'!C55/1000 -> 75 | G27: ='PT Recap costs'!D55/1000 -> 75 | H27: ='PT Recap costs'!E55/1000 -> 75 | I27: ='PT Recap costs'!F55/1000 -> 30 | J27: ='PT Recap costs'!G55/1000 -> 30 | K27: ='PT Recap costs'!H55/1000 -> 30 | L27: ='PT Recap costs'!I55/1000 -> 30 | ... P27: ='PT Recap costs'!M55/1000 -> 30 | Q27: =SUM(E27:P27) -> 540
D28: Development & op. | E28: ='PT Recap costs'!B56/1000 -> 100.67891 | F28: ='PT Recap costs'!C56/1000 -> 100.67891 | G28: ='PT Recap costs'!D56/1000 -> 95.965611 | H28: ='PT Recap costs'!E56/1000 -> 172.96561 | I28: ='PT Recap costs'!F56/1000 -> 207.92891 | J28: ='PT Recap costs'!G56/1000 -> 177.67891 | K28: ='PT Recap costs'!H56/1000 -> 100.67891 | L28: ='PT Recap costs'!I56/1000 -> 139.17891 | ... P28: ='PT Recap costs'!M56/1000 -> 229.92891 | Q28: =SUM(E28:P28) -> 1875.2203
D29: E&F | E29: ='PT Recap costs'!B57/1000 -> 0 | F29: ='PT Recap costs'!C57/1000 -> 2.75 | G29: ='PT Recap costs'!D57/1000 -> 2.75 | H29: ='PT Recap costs'!E57/1000 -> 5.5 | I29: ='PT Recap costs'!F57/1000 -> 5.5 | J29: ='PT Recap costs'!G57/1000 -> 5.5 | K29: ='PT Recap costs'!H57/1000 -> 5.5 | L29: ='PT Recap costs'!I57/1000 -> 5.5 | ... P29: ='PT Recap costs'!M57/1000 -> 5.5 | Q29: =SUM(E29:P29) -> 55
D30: Legal | E30: ='PT Recap costs'!B29/1000 -> 0.55555556 | F30: ='PT Recap costs'!C29/1000 -> 0.55555556 | G30: ='PT Recap costs'!D29/1000 -> 0.55555556 | H30: ='PT Recap costs'!E29/1000 -> 0.55555556 | I30: ='PT Recap costs'!F29/1000 -> 0.55555556 | J30: ='PT Recap costs'!G29/1000 -> 0.55555556 | K30: ='PT Recap costs'!H29/1000 -> 0.55555556 | L30: ='PT Recap costs'!I29/1000 -> 0.55555556 | ... P30: ='PT Recap costs'!M29/1000 -> 0.55555556 | Q30: =SUM(E30:P30) -> 6.6666667
D31: T&E | E31: ='PT Recap costs'!B30/1000 -> 5 | F31: ='PT Recap costs'!C30/1000 -> 5 | G31: ='PT Recap costs'!D30/1000 -> 5 | H31: ='PT Recap costs'!E30/1000 -> 5 | I31: ='PT Recap costs'!F30/1000 -> 5 | J31: ='PT Recap costs'!G30/1000 -> 5 | K31: ='PT Recap costs'!H30/1000 -> 5 | L31: ='PT Recap costs'!I30/1000 -> 5 | ... P31: ='PT Recap costs'!M30/1000 -> 5 | Q31: =SUM(E31:P31) -> 60
D32: NET | E32: =E24+E25 -> -181.23446 | F32: =F24+F25 -> -183.98446 | G32: =G24+G25 -> -179.27117 | H32: =H24+H25 -> -259.02117 | I32: =I24+I25 -> -248.98446 | J32: =J24+J25 -> -218.73446 | K32: =K24+K25 -> -141.73446 | L32: =L24+L25 -> -180.23446 | ... Q32: =Q24+Q25 -> -2536.887
B34: T4 | C34: Oncology: development | D34: Cash in from Revenue | E34: 0 | F34: 0 | G34: 0 | H34: 0 | I34: 0 | J34: 0 | K34: 0 | L34: 0 | M34: 0 | N34: 0 | O34: 0 | P34: 0 | Q34: =SUM(E34:P34) -> 0
D35: COSTS | E35: =-SUM(E36:E41) -> -11.805556 | F35: =-SUM(F36:F41) -> -42.055556 | G35: =-SUM(G36:G41) -> -46.768851 | H35: =-SUM(H36:H41) -> -76.768851 | I35: =-SUM(I36:I41) -> -60.805556 | J35: =-SUM(J36:J41) -> -60.805556 | K35: =-SUM(K36:K41) -> -91.055556 | L35: =-SUM(L36:L41) -> -110.30556 | ... Q35: =-SUM(Q36:Q41) -> -876.59326
D36: COGS | E36: =COGS!C14/1000 -> 0 | F36: =COGS!D14/1000 -> 0 | G36: =COGS!E14/1000 -> 0 | H36: =COGS!F14/1000 -> 0 | I36: =COGS!G14/1000 -> 0 | J36: =COGS!H14/1000 -> 0 | K36: =COGS!I14/1000 -> 0 | L36: =COGS!J14/1000 -> 0 | ... P36: =COGS!N14/1000 -> 0 | Q36: =SUM(E36:P36) -> 0
D37: Consultancies | E37: ='PT Recap costs'!B59/1000 -> 0 | F37: ='PT Recap costs'!C59/1000 -> 0 | G37: ='PT Recap costs'!D59/1000 -> 0 | H37: ='PT Recap costs'!E59/1000 -> 0 | I37: ='PT Recap costs'!F59/1000 -> 0 | J37: ='PT Recap costs'!G59/1000 -> 0 | K37: ='PT Recap costs'!H59/1000 -> 0 | L37: ='PT Recap costs'!I59/1000 -> 0 | ... P37: ='PT Recap costs'!M59/1000 -> 0 | Q37: =SUM(E37:P37) -> 0
D38: Development & op. | E38: ='PT Recap costs'!B60/1000 -> 0 | F38: ='PT Recap costs'!C60/1000 -> 30.25 | G38: ='PT Recap costs'!D60/1000 -> 34.963295 | H38: ='PT Recap costs'!E60/1000 -> 64.963295 | I38: ='PT Recap costs'!F60/1000 -> 60.25 | J38: ='PT Recap costs'!G60/1000 -> 60.25 | K38: ='PT Recap costs'!H60/1000 -> 90.5 | L38: ='PT Recap costs'!I60/1000 -> 109.75 | ... P38: ='PT Recap costs'!M60/1000 -> 93.5 | Q38: =SUM(E38:P38) -> 824.92659
D39: E&F | E39: ='PT Recap costs'!B61/1000 -> 11.25 | F39: ='PT Recap costs'!C61/1000 -> 11.25 | G39: ='PT Recap costs'!D61/1000 -> 11.25 | H39: ='PT Recap costs'!E61/1000 -> 11.25 | I39: ='PT Recap costs'!F61/1000 -> 0 | J39: ='PT Recap costs'!G61/1000 -> 0 | K39: ='PT Recap costs'!H61/1000 -> 0 | L39: ='PT Recap costs'!I61/1000 -> 0 | ... P39: ='PT Recap costs'!M61/1000 -> 0 | Q39: =SUM(E39:P39) -> 45
D40: Legal | E40: ='PT Recap costs'!B40/1000 -> 0.55555556 | F40: ='PT Recap costs'!C40/1000 -> 0.55555556 | G40: ='PT Recap costs'!D40/1000 -> 0.55555556 | H40: ='PT Recap costs'!E40/1000 -> 0.55555556 | I40: ='PT Recap costs'!F40/1000 -> 0.55555556 | J40: ='PT Recap costs'!G40/1000 -> 0.55555556 | K40: ='PT Recap costs'!H40/1000 -> 0.55555556 | L40: ='PT Recap costs'!I40/1000 -> 0.55555556 | ... P40: ='PT Recap costs'!M40/1000 -> 0.55555556 | Q40: =SUM(E40:P40) -> 6.6666667
D41: T&E | E41: ='PT Recap costs'!B41/1000 -> 0 | F41: ='PT Recap costs'!C41/1000 -> 0 | G41: ='PT Recap costs'!D41/1000 -> 0 | H41: ='PT Recap costs'!E41/1000 -> 0 | I41: ='PT Recap costs'!F41/1000 -> 0 | J41: ='PT Recap costs'!G41/1000 -> 0 | K41: ='PT Recap costs'!H41/1000 -> 0 | L41: ='PT Recap costs'!I41/1000 -> 0 | ... P41: ='PT Recap costs'!M41/1000 -> 0 | Q41: =SUM(E41:P41) -> 0
D42: NET | E42: =E34+E35 -> -11.805556 | F42: =F34+F35 -> -42.055556 | G42: =G34+G35 -> -46.768851 | H42: =H34+H35 -> -76.768851 | I42: =I34+I35 -> -60.805556 | J42: =J34+J35 -> -60.805556 | K42: =K34+K35 -> -91.055556 | L42: =L34+L35 -> -110.30556 | ... Q42: =Q34+Q35 -> -876.59326
B44: T5 | C44: Operations organisation (Services): Installation & Interfaçage | D44: Cash in from Revenue | E44: 48.125 | F44: 20.625 | G44: 48.125 | H44: 20.625 | I44: 90.75 | J44: 140.25 | K44: 189.75 | L44: 239.25 | M44: 103.125 | N44: 103.125 | O44: 103.125 | P44: 103.125 | Q44: =SUM(E44:P44) -> 1210
D45: COSTS | E45: =-SUM(E46:E51) -> -36.055556 | F45: =-SUM(F46:F51) -> -36.055556 | G45: =-SUM(G46:G51) -> -36.055556 | H45: =-SUM(H46:H51) -> -36.055556 | I45: =-SUM(I46:I51) -> -150.80556 | J45: =-SUM(J46:J51) -> -150.80556 | K45: =-SUM(K46:K51) -> -134.30556 | L45: =-SUM(L46:L51) -> -134.30556 | ... Q45: =-SUM(Q46:Q51) -> -1285.4917
D46: COGS | E46: =COGS!C16/1000 -> 0 | F46: =COGS!D16/1000 -> 0 | G46: =COGS!E16/1000 -> 0 | H46: =COGS!F16/1000 -> 0 | I46: =COGS!G16/1000 -> 0 | J46: =COGS!H16/1000 -> 0 | K46: =COGS!I16/1000 -> 0 | L46: =COGS!J16/1000 -> 0 | ... P46: =COGS!N16/1000 -> 0 | Q46: =SUM(E46:P46) -> 0
...

Sheet PT Recap costs
A3: Étiquettes de lignes | B3: Somme de Q1 21 | C3: Somme de Q2 21 | D3: Somme de Q3 21 | E3: Somme de Q4 21 | F3: Somme de Q1 22 | G3: Somme de Q2 22 | H3: Somme de Q3 22 | I3: Somme de Q4 22 | J3: Somme de Q1 23 | K3: Somme de Q2 23 | L3: Somme de Q3 23 | M3: Somme de Q4 23 | N3: TOTAL
A4: Costs not allocated to target | B4: 12726.883 | C4: 14060.113 | D4: 26145.604 | E4: 39845.395 | F4: 61067.31 | G4: 65535.693 | H4: 69075.965 | I4: 72616.237 | J4: 89231.7 | K4: 89231.7 | L4: 89231.7 | M4: 89231.7 | N4: =SUM(B4:M4) -> 718000
A5: Sales and bus dev | B5: 12726.883 | C5: 14060.113 | D5: 26145.604 | E5: 39845.395 | F5: 61067.31 | G5: 65535.693 | H5: 69075.965 | I5: 72616.237 | J5: 89231.7 | K5: 89231.7 | L5: 89231.7 | M5: 89231.7 | N5: =SUM(B5:M5) -> 718000
A6: G&A | B6: 103209.2 | C6: 136413.55 | D6: 71394.113 | E6: 123769.59 | F6: 124066.72 | G6: 88103.159 | H6: 101301.2 | I6: 124499.25 | J6: 132508.55 | K6: 122508.55 | L6: 112508.55 | M6: 122508.55 | N6: =SUM(B6:M6) -> 1362791
A7: Facilities | B7: 11850 | C7: 11850 | D7: 11850 | E7: 11850 | F7: 13850 | G7: 13850 | H7: 13850 | I7: 13850 | J7: 16350 | K7: 16350 | L7: 16350 | M7: 16350 | N7: =SUM(B7:M7) -> 168200
A8: Finance | B8: 16000 | C8: 16000 | D8: 16000 | E8: 16000 | F8: 16000 | G8: 16000 | H8: 16000 | I8: 16000 | J8: 16000 | K8: 16000 | L8: 16000 | M8: 16000 | N8: =SUM(B8:M8) -> 192000
A9: HR/Admin | B9: 66951.791 | C9: 99069.56 | D9: 40165.445 | E9: 81375.593 | F9: 80306.862 | G9: 40701.57 | H9: 51014.294 | I9: 71327.018 | J9: 63294.717 | K9: 53294.717 | L9: 43294.717 | M9: 53294.717 | N9: =SUM(B9:M9) -> 744091
A10: Other costs | B10: 1407.4101 | C10: 2493.9917 | D10: 3378.6677 | E10: 14543.997 | F10: 13909.857 | G10: 17551.59 | H10: 20436.911 | I10: 23322.233 | J10: 36863.836 | K10: 36863.836 | L10: 36863.836 | M10: 36863.836 | N10: =SUM(B10:M10) -> 244500
A11: Capital increase | B11: 7000 | C11: 7000 | D11: 0 | E11: 0 | F11: 0 | G11: 0 | H11: 0 | I11: 0 | J11: 0 | K11: 0 | L11: 0 | M11: 0 | N11: =SUM(B11:M11) -> 14000
A12: T5 | B12: 8055.5556 | C12: 8055.5556 | D12: 8055.5556 | E12: 8055.5556 | F12: 15555.556 | G12: 15555.556 | H12: 15555.556 | I12: 15555.556 | J12: 15555.556 | K12: 15555.556 | L12: 15555.556 | M12: 15555.556 | N12: =SUM(B12:M12) -> 156666.67
A13: Legal | B13: 555.55556 | C13: 555.55556 | D13: 555.55556 | E13: 555.55556 | F13: 555.55556 | G13: 555.55556 | H13: 555.55556 | I13: 555.55556 | J13: 555.55556 | K13: 555.55556 | L13: 555.55556 | M13: 555.55556 | N13: =SUM(B13:M13) -> 6666.6667
A14: T&E | B14: 7500 | C14: 7500 | D14: 7500 | E14: 7500 | F14: 15000 | G14: 15000 | H14: 15000 | I14: 15000 | J14: 15000 | K14: 15000 | L14: 15000 | M14: 15000 | N14: =SUM(B14:M14) -> 150000
A15: See Target allocation | B15: 411499.84 | C15: 598374.84 | D15: 624474.84 | E15: 779324.84 | F15: 873724.84 | G15: 843474.84 | H15: 870224.84 | I15: 927974.84 | J15: 955724.84 | K15: 1000824.8 | L15: 1000824.8 | M15: 1047574.8 | N15: =SUM(B15:M15) -> 9934023
... A30: T&E | B30: 5000 | C30: 5000 | D30: 5000 | E30: 5000 | F30: 5000 | G30: 5000 | H30: 5000 | I30: 5000 | J30: 5000 | K30: 5000 | L30: 5000 | M30: 5000 | N30: =SUM(B30:M30) -> 60000
A31: (vide) | N31: =SUM(B31:M31) -> 0
A32: (vide) | N32: =SUM(B32:M32) -> 0
A33: T1 | B33: 3888.8889 | C33: 3888.8889 | D33: 3888.8889 | E33: 3888.8889 | F33: 3888.8889 | G33: 3888.8889 | H33: 3888.8889 | I33: 3888.8889 | J33: 3888.8889 | K33: 3888.8889 | L33: 3888.8889 | M33: 3888.8889 | N33: =SUM(B33:M33) -> 46666.667
A34: Legal | B34: 555.55556 | C34: 555.55556 | D34: 555.55556 | E34: 555.55556 | F34: 555.55556 | G34: 555.55556 | H34: 555.55556 | I34: 555.55556 | J34: 555.55556 | K34: 555.55556 | L34: 555.55556 | M34: 555.55556 | N34: =SUM(B34:M34) -> 6666.6667
A35: T&E | B35: 3333.3333 | C35: 3333.3333 | D35: 3333.3333 | E35: 3333.3333 | F35: 3333.3333 | G35: 3333.3333 | H35: 3333.3333 | I35: 3333.3333 | J35: 3333.3333 | K35: 3333.3333 | L35: 3333.3333 | M35: 3333.3333 | N35: =SUM(B35:M35) -> 40000
A36: T2 | B36: 3888.8889 | C36: 3888.8889 | D36: 3888.8889 | E36: 3888.8889 | F36: 3888.8889 | G36: 3888.8889 | H36: 3888.8889 | I36: 3888.8889 | J36: 3888.8889 | K36: 3888.8889 | L36: 3888.8889 | M36: 3888.8889 | N36: =SUM(B36:M36) -> 46666.667
A37: Legal | B37: 555.55556 | C37: 555.55556 | D37: 555.55556 | E37: 555.55556 | F37: 555.55556 | G37: 555.55556 | H37: 555.55556 | I37: 555.55556 | J37: 555.55556 | K37: 555.55556 | L37: 555.55556 | M37: 555.55556 | N37: =SUM(B37:M37) -> 6666.6667
A38: T&E | B38: 3333.3333 | C38: 3333.3333 | D38: 3333.3333 | E38: 3333.3333 | F38: 3333.3333 | G38: 3333.3333 | H38: 3333.3333 | I38: 3333.3333 | J38: 3333.3333 | K38: 3333.3333 | L38: 3333.3333 | M38: 3333.3333 | N38: =SUM(B38:M38) -> 40000
A39: T4 | B39: 555.55556 | C39: 555.55556 | D39: 555.55556 | E39: 555.55556 | F39: 555.55556 | G39: 555.55556 | H39: 555.55556 | I39: 555.55556 | J39: 555.55556 | K39: 555.55556 | L39: 555.55556 | M39: 555.55556 | N39: =SUM(B39:M39) -> 6666.6667
A40: Legal | B40: 555.55556 | C40: 555.55556 | D40: 555.55556 | E40: 555.55556 | F40: 555.55556 | G40: 555.55556 | H40: 555.55556 | I40: 555.55556 | J40: 555.55556 | K40: 555.55556 | L40: 555.55556 | M40: 555.55556 | N40: =SUM(B40:M40) -> 6666.6667
A41: T&E | B41: 0 | C41: 0 | D41: 0 | E41: 0 | F41: 0 | G41: 0 | H41: 0 | I41: 0 | J41: 0 | K41: 0 | L41: 0 | M41: 0 | N41: =SUM(B41:M41) -> 0
A42: Total général | B42: 555617.52 | C42: 783367.02 | D42: 761877.35 | E42: 1188371.5 | F42: 1276565.9 | G42: 1218371.8 | H42: 1265411.2 | I42: 1353450.6 | J42: 1549679.7 | K42: 1584779.7 | L42: 1574779.7 | M42: 1631529.7 | N42: =SUM(B42:M42) -> 14743801
A45: Étiquettes de lignes | B45: Somme de Q1 212 | C45: Somme de Q2 212 | D45: Somme de Q3 212 | E45: Somme de Q4 212 | F45: Somme de Q1 222 | G45: Somme de Q2 222 | H45: Somme de Q3 222 | I45: Somme de Q4 22 | J45: Somme de Q1 232 | K45: Somme de Q2 232 | L45: Somme de Q3 232 | M45: Somme de Q4 232 | N45: TOTAL
A46: T1 | B46: 20979.09 | C46: 90416.59 | D46: 90416.59 | E46: 112966.59 | F46: 116541.59 | G46: 116541.59 | H46: 116541.59 | I46: 116541.59 | J46: 116541.59 | K46: 127816.59 | L46: 127816.59 | M46: 127816.59 | N46: =SUM(B46:M46) -> 1280936.6
A47: Consultancies | B47: 7506 | C47: 7506 | D47: 7506 | E47: 7506 | F47: 7506 | G47: 7506 | H47: 7506 | I47: 7506 | J47: 7506 | K47: 7506 | L47: 7506 | M47: 7506 | N47: =SUM(B47:M47) -> 90072
A48: Dev & Op | B48: 0 | C48: 0 | D48: 0 | E48: 0 | F48: 0 | G48: 0 | H48: 0 | I48: 0 | J48: 0 | K48: 0 | L48: 0 | M48: 0 | N48: =SUM(B48:M48) -> 0
A49: E&F | B49: 13473.09 | C49: 82910.59 | D49: 82910.59 | E49: 105460.59 | F49: 109035.59 | G49: 109035.59 | H49: 109035.59 | I49: 109035.59 | J49: 109035.59 | K49: 120310.59 | L49: 120310.59 | M49: 120310.59 | N49: =SUM(B49:M49) -> 1190864.6
A50: T2 | B50: 17973.09 | C50: 87410.59 | D50: 87410.59 | E50: 109960.59 | F50: 113535.59 | G50: 113535.59 | H50: 113535.59 | I50: 113535.59 | J50: 113535.59 | K50: 124810.59 | L50: 124810.59 | M50: 124810.59 | N50: =SUM(B50:M50) -> 1244864.6
A51: Consultancies | B51: 4500 | C51: 4500 | D51: 4500 | E51: 4500 | F51: 4500 | G51: 4500 | H51: 4500 | I51: 4500 | J51: 4500 | K51: 4500 | L51: 4500 | M51: 4500 | N51: =SUM(B51:M51) -> 54000
A52: Dev & Op | B52: 0 | C52: 0 | D52: 0 | E52: 0 | F52: 0 | G52: 0 | H52: 0 | I52: 0 | J52: 0 | K52: 0 | L52: 0 | M52: 0 | N52: =SUM(B52:M52) -> 0
A53: E&F | B53: 13473.09 | C53: 82910.59 | D53: 82910.59 | E53: 105460.59 | F53: 109035.59 | G53: 109035.59 | H53: 109035.59 | I53: 109035.59 | J53: 109035.59 | K53: 120310.59 | L53: 120310.59 | M53: 120310.59 | N53: =SUM(B53:M53) -> 1190864.6
A54: T3 | B54: 175678.91 | C54: 178428.91 | D54: 173715.61 | E54: 253465.61 | F54: 243428.91 | G54: 213178.91 | H54: 136178.91 | I54: 174678.91 | J54: 218678.91 | K54: 218678.91 | L54: 218678.91 | M54: 265428.91 | N54: =SUM(B54:M54) -> 2470220.3
A55: Consultancies | B55: 75000 | C55: 75000 | D55: 75000 | E55: 75000 | F55: 30000 | G55: 30000 | H55: 30000 | I55: 30000 | J55: 30000 | K55: 30000 | L55: 30000 | M55: 30000 | N55: =SUM(B55:M55) -> 540000
A56: Dev & Op | B56: 100678.91 | C56: 100678.91 | D56: 95965.611 | E56: 172965.61 | F56: 207928.91 | G56: 177678.91 | H56: 100678.91 | I56: 139178.91 | J56: 183178.91 | K56: 183178.91 | L56: 183178.91 | M56: 229928.91 | N56: =SUM(B56:M56) -> 1875220.3
A57: E&F | B57: 0 | C57: 2750 | D57: 2750 | E57: 5500 | F57: 5500 | G57: 5500 | H57: 5500 | I57: 5500 | J57: 5500 | K57: 5500 | L57: 5500 | M57: 5500 | N57: =SUM(B57:M57) -> 55000
... A74: Total général | B74: 411499.84 | C74: 598374.84 | D74: 624474.84 | E74: 779324.84 | F74: 873724.84 | G74: 843474.84 | H74: 870224.84 | I74: 927974.84 | J74: 955724.84 | K74: 1000824.8 | L74: 1000824.8 | M74: 1047574.8 | N74: =SUM(B74:M74) -> 9934023
...

Sheet Recap costs
A1: Allocation | B1: Target | C1: Fonction | D1: Détails | E1: E&F + Consultancies | F1: Moyenne EFT | G1: Total | H1: Q1 21 | I1: Q2 21 | J1: Q3 21 | K1: Q4 21 | L1: Q1 22 | M1: Q2 22 | N1: Q3 22 | O1: Q4 22 | P1: Q1 23 | Q1: Q2 23 | R1: Q3 23 | S1: Q4 23 | T1: Total
A2: Capital increase | B2: G&A | E2: Consultancies | G2: =SUM(H2:S2) -> 14000 | H2: =14000/2 -> 7000 | I2: =14000/2 -> 7000 | J2: 0 | K2: 0 | L2: 0 | M2: 0 | N2: 0 | O2: 0 | P2: 0 | Q2: 0 | R2: 0 | S2: 0 | T2: =SUM(H2:S2) -> 14000
