Workbook

Sheet DATA Raw
A1: DATA RAW FOR MARKET POTENTIAL CALCULATION
B2: Min | C2: Max
A3: Market Growth % | B3: 8 | C3: 12
A5: Epidemiology – Allergies
A6: Dogs: 12–18% prevalence | B6: 12 | C6: 18
A7: Cats: 10–14% prevalence | B7: 10 | C7: 14
A8: Symptomatic cases tested | C8: 25 | G8: Distribution Strategy EU5
G9: • FR: Centravet, Alcyon, Coveto
A10: Pet Allergy Diagnostics Market | G10: • IT: Agrisan, Virbac Italy
A11: Global: $370M (2025) → $714M (2035) | G11: • ES: Distrivet, Covetrus
A12: KIT SALES PRICES € | B12: Min € | C12: Max € | G12: • DE: Alvetra & Werfft
A13: Lab IgE panels ELISA | B13: 85 | C13: 150 | G13: • BE: Ecuphar, Cenvet
A14: Rapid tests: | B14: 28 | C14: 45
A15: Dot arrays: | B15: 120 | C15: 180
A16: DIATECH Rapid Test | B16: 35 | C16: 39
A17: DIATECH Array | B17: 120 | C17: 150
A18: READER SALES PRICES €
A19: Unknown | B19: 1000
A21: CLINICS & MARKET POTENTIAL TESTS | B21: Clinics | C21: Tests Max
A22: France | B22: 7200 | C22: 270000
A23: Germany | B23: 10000 | C23: =+C22/B22*B23 -> 375000
A24: Italy | B24: 8500 | C24: =+C23/B23*B24 -> 318750
A25: Spain | B25: 7100 | C25: =+C24/B24*B25 -> 266250
A26: Belgium | B26: 750 | C26: =+C25/B25*B26 -> 28125
C27: =SUM(C22:C26) -> 1258125 | D27: TEST/Y
A32: Metric France | B32: Value | C32: Notes
A33: Number of veterinary clinics | B33: 7500 | C33: Ordre National des Vétérinaires (France)
A34: Dogs population (million) | B34: 7.6 | C34: FACCO / Kantar
A35: Cats population (million) | B35: 15.1 | C35: FACCO / Kantar
A36: Dermatology-related consultations (%) | B36: 15–20% | C36: Veterinary dermatology benchmarks
A37: Average test price (€) | B37: 35 | C37: JCHYTECH internal pricing
A38: Target gross margin (%) | B38: 60 | C38: Manufacturing & distribution model

Sheet SALES
A1: DIATECH
A2: Controls Sheet
A3: Amounts in €
B4: Year 1 | C4: Year 2 | D4: Year 3 | E4: Year 4 | F4: Year 5
A5: Assumptions for the Annual Period | B5: 2026 | C5: =+B5+1 -> 2027 | D5: =+C5+1 -> 2028 | E5: =+D5+1 -> 2029 | F5: =+E5+1 -> 2030
A6: Start Date of the Model | B6: 46174
A7: REVENUE ASSUMPTIONS
A9: Quarterly Sales Targets
A11: Thermic Units
A12: La 12T Belgium | B12: =SUM(#REF!) -> #REF! | C12: =SUM(#REF!) -> #REF! | D12: =SUM(#REF!) -> #REF! | E12: =SUM(#REF!) -> #REF! | F12: =SUM(#REF!) -> #REF!
A13: La 12T France | B13: =SUM(#REF!) -> #REF! | C13: =SUM(#REF!) -> #REF! | D13: =SUM(#REF!) -> #REF! | E13: =SUM(#REF!) -> #REF! | F13: =SUM(#REF!) -> #REF!
A14: La 12T Europe | B14: =SUM(#REF!) -> #REF! | C14: =SUM(#REF!) -> #REF! | D14: =SUM(#REF!) -> #REF! | E14: =SUM(#REF!) -> #REF! | F14: =SUM(#REF!) -> #REF!
A15: La 12T USA | B15: =SUM(#REF!) -> #REF! | C15: =SUM(#REF!) -> #REF! | D15: =SUM(#REF!) -> #REF! | E15: =SUM(#REF!) -> #REF! | F15: =SUM(#REF!) -> #REF!
A16: La 12T SE ASIA | B16: =SUM(#REF!) -> #REF! | C16: =SUM(#REF!) -> #REF! | D16: =SUM(#REF!) -> #REF! | E16: =SUM(#REF!) -> #REF! | F16: =SUM(#REF!) -> #REF!
B17: =SUM(B12:B16) -> #REF! | C17: =SUM(C12:C16) -> #REF! | D17: =SUM(D12:D16) -> #REF! | E17: =SUM(E12:E16) -> #REF! | F17: =SUM(F12:F16) -> #REF!
A18: Electric Units
A19: La 12E Belgium | B19: =SUM(#REF!) -> #REF! | C19: =SUM(#REF!) -> #REF! | D19: =SUM(#REF!) -> #REF! | E19: =SUM(#REF!) -> #REF! | F19: =SUM(#REF!) -> #REF!
A20: La 12E France | B20: =SUM(#REF!) -> #REF! | C20: =SUM(#REF!) -> #REF! | D20: =SUM(#REF!) -> #REF! | E20: =SUM(#REF!) -> #REF! | F20: =SUM(#REF!) -> #REF!
A21: La 12E Europe | B21: =SUM(#REF!) -> #REF! | C21: =SUM(#REF!) -> #REF! | D21: =SUM(#REF!) -> #REF! | E21: =SUM(#REF!) -> #REF! | F21: =SUM(#REF!) -> #REF!
A22: La 12E USA | B22: =SUM(#REF!) -> #REF! | C22: =SUM(#REF!) -> #REF! | D22: =SUM(#REF!) -> #REF! | E22: =SUM(#REF!) -> #REF! | F22: =SUM(#REF!) -> #REF!
A23: La 12E SE ASIA | B23: =SUM(#REF!) -> #REF! | C23: =SUM(#REF!) -> #REF! | D23: =SUM(#REF!) -> #REF! | E23: =SUM(#REF!) -> #REF! | F23: =SUM(#REF!) -> #REF!
B24: =SUM(B19:B23) -> #REF! | C24: =SUM(C19:C23) -> #REF! | D24: =SUM(D19:D23) -> #REF! | E24: =SUM(E19:E23) -> #REF! | F24: =SUM(F19:F23) -> #REF!
A25: KITS RAPID TEST
A26: Total Units Sold | B26: =SUM(B27:B29) -> 8100 | C26: =SUM(C27:C29) -> 23137.5 | D26: =SUM(D27:D29) -> 46275 | E26: =SUM(E27:E29) -> 76350 | F26: =SUM(F27:F29) -> 104805
A27: FRANCE | B27: =+'DATA Raw'!C22*0.03 -> 8100 | C27: =+B27*2 -> 16200 | D27: =+C27*2 -> 32400 | E27: =+D27*1.5 -> 48600 | F27: =+E27*1.3 -> 63180
A28: COUNTRIES 2 | C28: =+'DATA Raw'!C24*0.01 -> 3187.5 | D28: =+C28*2 -> 6375 | E28: =+D28*2 -> 12750 | F28: =+E28*1.5 -> 19125
A29: COUNTRIES 3 | B29: 0 | C29: =+'DATA Raw'!C23*0.01 -> 3750 | D29: =+C29*2 -> 7500 | E29: =+D29*2 -> 15000 | F29: =+E29*1.5 -> 22500
A30: Revenue generated | B30: =+B26*'DATA Raw'!$B$16 -> 283500 | C30: =+C26*'DATA Raw'!$B$16 -> 809812.5 | D30: =+D26*'DATA Raw'!$B$16 -> 1619625 | E30: =+E26*'DATA Raw'!$B$16 -> 2672250 | F30: =+F26*'DATA Raw'!$B$16 -> 3668175
A31: KITS ARRAY | B31: =SUM(B33:B35) -> 0 | C31: =SUM(C33:C35) -> 0 | D31: =SUM(D33:D35) -> 4860 | E31: =SUM(E32:E35) -> 27765 | F31: =SUM(F32:F35) -> 55530
A32: Total Units Sold | B32: =SUM(B33:B35) -> 0 | C32: =SUM(C33:C35) -> 0 | D32: =SUM(D33:D35) -> 4860 | E32: =SUM(E33:E35) -> 13882.5 | F32: =SUM(F33:F35) -> 27765
A33: FRANCE | D33: =+B27*0.6 -> 4860 | E33: =+C27*0.6 -> 9720 | F33: =+D27*0.6 -> 19440
A34: COUNTRIES 2 | D34: =+B28*0.6 -> 0 | E34: =+C28*0.6 -> 1912.5 | F34: =+D28*0.6 -> 3825
A35: COUNTRIES 3 | D35: =+B29*0.6 -> 0 | E35: =+C29*0.6 -> 2250 | F35: =+D29*0.6 -> 4500
A36: Revenue generated | F36: =SUM(F33:F35) -> 27765
A37: READERS | B37: 0 | C37: =B37*(1+C38) -> 0 | D37: =C37*(1+D38) -> 0 | E37: =D37*(1+E38) -> 0 | F37: =E37*(1+F38) -> 0
A38: Total Units Sold | C38: 0.05 | D38: 0.05 | E38: 0.05 | F38: 0.05
A39: FRANCE | B39: 0 | C39: =B39*(1+C40) -> 0 | D39: =C39*(1+D40) -> 0 | E39: =D39*(1+E40) -> 0 | F39: =E39*(1+F40) -> 0
A40: COUNTRIES 2 | C40: 0.05 | D40: 0.05 | E40: 0.05 | F40: 0.05
A41: COUNTRIES 3 | B41: 0.25 | C41: 0.25 | D41: 0.25 | E41: 0.25 | F41: 0.25
A42: Revenue generated | C42: NA | D42: NA | E42: NA | F42: NA
...

Sheet Expense Assumptions
A1: DIATECH
A2: Expense Assumptions Sheet
A3: Amounts in €
A5: Assumptions for the Monthly Period
A7: Cost Of Goods Sold (COGS)
B8: Year 1 | C8: Year 2 | D8: Year 3 | E8: Year 4 | F8: Year 5
A9: Thermic Units Sold | B9: 2026 | C9: =+B9+1 -> 2027 | D9: =+C9+1 -> 2028 | E9: =+D9+1 -> 2029 | F9: =+E9+1 -> 2030
A10: Thermic Unit Average Cost
A11: Distrib Costs
A12: Cost of sales for Thermic Units
A14: Electric Units Sold
A15: Electric Unit Average Cost
A16: Distrib Costs
A17: Cost of sales for Electric Units
A19: Cost of Sales for Spare Parts and Aftermarket Services as a % of sales
A20: Distrib Costs or royalties
A21: Cost of Sales for Spare Parts and Aftermarket Services
A23: PRODUCTS
A24: Cost Of Rapid TEST | B24: =+SALES!B30*0.5 -> 141750 | C24: =+SALES!C30*0.5 -> 404906.25 | D24: =+SALES!D30*0.5 -> 809812.5 | E24: =+SALES!E30*0.5 -> 1336125 | F24: =+SALES!F30*0.5 -> 1834087.5
A25: cost of Array TEST | B25: =+SALES!B43*0.55 -> 0 | C25: =+SALES!C43*0.55 -> 0 | D25: =+SALES!D43*0.55 -> 320760 | E25: =+SALES!E43*0.55 -> 916245 | F25: =+SALES!F43*0.55 -> 1832490
A26: Cost of Readers | B26: =+SALES!B46*0.5 -> 8100 | C26: =+SALES!C46*0.5 -> 23137.5 | D26: =+SALES!D46*0.5 -> 46275 | E26: =+SALES!E46*0.5 -> 76350 | F26: =+SALES!F46*0.5 -> 104805
A27: Cost of Sales | B27: =SUM(B24:B26) -> 149850 | C27: =SUM(C24:C26) -> 428043.75 | D27: =SUM(D24:D26) -> 1176847.5 | E27: =SUM(E24:E26) -> 2328720 | F27: =SUM(F24:F26) -> 3771382.5
A30: Operating Expenses (OPEX)
A32: Car rental | B32: =+SALES!B64 -> 0 | C32: =+SALES!C64 -> 3600 | D32: =+SALES!D64 -> 3960 | E32: =+SALES!E64 -> 4554 | F32: =+SALES!F64 -> 5009.4
A33: Commercial vehicle rentals | B33: =+SALES!B68 -> 0 | C33: =+SALES!C68 -> 0 | D33: =+SALES!D68 -> 3600 | E33: =+SALES!E68 -> 4140 | F33: =+SALES!F68 -> 4554
A34: Fuel | B34: =+SALES!B70 -> 0 | C34: =+SALES!C72 -> 3600 | D34: =+SALES!D72 -> 5400 | E34: =+SALES!E72 -> 6210 | F34: =+SALES!F72 -> 6831
A35: Travel costs (parking, etc.) | B35: =+SALES!B76 -> 4800 | C35: =+SALES!C76 -> 6000 | D35: =+SALES!D76 -> 7500 | E35: =+SALES!E76 -> 8250 | F35: =+SALES!F76 -> 9075
A36: Car insurance (omnium) | B36: =+SALES!B80 -> 0 | C36: =+SALES!C80 -> 1440 | D36: =+SALES!D80 -> 2160 | E36: =+SALES!E80 -> 2484 | F36: =+SALES!F80 -> 2732.4
A37: Events , Fairs , Missions | B37: =+SALES!B84 -> 1800 | C37: =+SALES!C84 -> 3600 | D37: =+SALES!D84 -> 3960 | E37: =+SALES!E84 -> 4554 | F37: =+SALES!F84 -> 3000
A38: Website | B38: =+SALES!B88 -> 2400 | C38: =+SALES!C88 -> 3000 | D38: =+SALES!D88 -> 3750 | E38: =+SALES!E88 -> 4312.5 | F38: =+SALES!F88 -> 4743.75
A39: Advertising / SPONSORSHIP | B39: =+SALES!B92 -> 1200 | C39: =+SALES!C92 -> 1320 | D39: =+SALES!D92 -> 1452 | E39: =+SALES!E92 -> 1669.8 | F39: =+SALES!F92 -> 1836.78
A40: Building rent | B40: =+SALES!B96 -> 2400 | C40: =+SALES!C96 -> 6000 | D40: =+SALES!D96 -> 12000 | E40: =+SALES!E96 -> 24000 | F40: =+SALES!F96 -> 26400
A41: Office General & Admin | B41: =+SALES!B100 -> 3000 | C41: =+SALES!C100 -> 4500 | D41: =+SALES!D100 -> 6750 | E41: =+SALES!E100 -> 10125 | F41: =+SALES!F100 -> 15187.5
A42: Consulting fees 1 (JCH) | B42: =+SALES!B104 -> 36000 | C42: =+SALES!C104 -> 43200 | D42: =+SALES!D104 -> 49680 | E42: =+SALES!E104 -> 57132 | F42: =+SALES!F104 -> 65701.8
A43: Consulting fees 2 (AB) | B43: =+SALES!B108 -> 36000 | C43: =+SALES!C108 -> 48600 | D43: =+SALES!D108 -> 65610 | E43: =+SALES!E108 -> 75451.5 | F43: =+SALES!F108 -> 86769.225
A44: Accounting fees | B44: =+SALES!B112 -> 1800 | C44: =+SALES!C112 -> 3600 | D44: =+SALES!D112 -> 3960 | E44: =+SALES!E112 -> 4356 | F44: =+SALES!F112 -> 4573.8
A45: Lawyer fees | B45: =+SALES!B116 -> 1200 | C45: =+SALES!C116 -> 2400 | D45: =+SALES!D116 -> 2520 | E45: =+SALES!E116 -> 2772 | F45: =+SALES!F116 -> 2910.6
A46: Coordination chinese partners | B46: =+SALES!B120 -> 9000 | C46: =+SALES!C120 -> 9450 | D46: =+SALES!D120 -> 9922.5 | E46: =+SALES!E120 -> 10914.75 | F46: =+SALES!F120 -> 11460.488
A47: Professional contribution | B47: =+SALES!B124 -> 360 | C47: =+SALES!C124 -> 378 | D47: =+SALES!D124 -> 396.9 | E47: =+SALES!E124 -> 436.59 | F47: =+SALES!F124 -> 458.4195
A48: Regulatory including 9001
...

Sheet Annual P&L
A1: DIATECH
A2: Compte de résultat annuel Montants en € | B2: Annual Profit & Loss Statement
B3: Amounts in €
A4: Hypothèses pour la période annuelle | B4: Assumptions for the Annual Period | C4: Y1 | D4: Y2 | E4: Y3 | F4: Y4 | G4: Y5
A5: SIM
A6: Services | B6: Thermic Unit Sales | C6: =SUMIF(#REF!,C$4,#REF!) -> #REF! | D6: =SUMIF(#REF!,D$4,#REF!) -> #REF! | E6: =SUMIF(#REF!,E$4,#REF!) -> #REF! | F6: =SUMIF(#REF!,F$4,#REF!) -> #REF! | G6: =SUMIF(#REF!,G$4,#REF!) -> #REF!
A7: Subventions à la R&D | B7: Electric Unit Sales | C7: =SUMIF(#REF!,C$4,#REF!) -> #REF! | D7: =SUMIF(#REF!,D$4,#REF!) -> #REF! | E7: =SUMIF(#REF!,E$4,#REF!) -> #REF! | F7: =SUMIF(#REF!,F$4,#REF!) -> #REF! | G7: =SUMIF(#REF!,G$4,#REF!) -> #REF!
A8: Chiffre d'affaires total | B8: Spare Parts and Aftermarket Services | C8: =SUMIF(#REF!,C$4,#REF!) -> #REF! | D8: =SUMIF(#REF!,D$4,#REF!) -> #REF! | E8: =SUMIF(#REF!,E$4,#REF!) -> #REF! | F8: =SUMIF(#REF!,F$4,#REF!) -> #REF! | G8: =SUMIF(#REF!,G$4,#REF!) -> #REF!
A10: Chiffre d'affaires total | B10: Total Revenue | C10: =+SALES!B51 -> 299700 | D10: =+SALES!C51 -> 856087.5 | E10: =+SALES!D51 -> 2295375 | F10: =+SALES!E51 -> 4490850 | G10: =+SALES!F51 -> 7209585
A12: SIM | B12: Thermic Units | C12: =SUMIF(#REF!,C$4,#REF!) -> #REF! | D12: =SUMIF(#REF!,D$4,#REF!) -> #REF! | E12: =SUMIF(#REF!,E$4,#REF!) -> #REF! | F12: =SUMIF(#REF!,F$4,#REF!) -> #REF! | G12: =SUMIF(#REF!,G$4,#REF!) -> #REF!
A13: Services | B13: Electric Units | C13: =SUMIF(#REF!,C$4,#REF!) -> #REF! | D13: =SUMIF(#REF!,D$4,#REF!) -> #REF! | E13: =SUMIF(#REF!,E$4,#REF!) -> #REF! | F13: =SUMIF(#REF!,F$4,#REF!) -> #REF! | G13: =SUMIF(#REF!,G$4,#REF!) -> #REF!
A14: Subventions à la R&D | B14: Spare Parts and Aftermarket Services | C14: =SUMIF(#REF!,C$4,#REF!) -> #REF! | D14: =SUMIF(#REF!,D$4,#REF!) -> #REF! | E14: =SUMIF(#REF!,E$4,#REF!) -> #REF! | F14: =SUMIF(#REF!,F$4,#REF!) -> #REF! | G14: =SUMIF(#REF!,G$4,#REF!) -> #REF!
A15: Coût total des marchandises vendues | B15: Total COGS | C15: =+'Expense Assumptions'!B27 -> 149850 | D15: =+'Expense Assumptions'!C27 -> 428043.75 | E15: =+'Expense Assumptions'!D27 -> 1176847.5 | F15: =+'Expense Assumptions'!E27 -> 2328720 | G15: =+'Expense Assumptions'!F27 -> 3771382.5
A17: Bénéfice brut | B17: Gross Profit | C17: =C10-C15 -> 149850 | D17: =D10-D15 -> 428043.75 | E17: =E10-E15 -> 1118527.5 | F17: =F10-F15 -> 2162130 | G17: =G10-G15 -> 3438202.5
A20: Total des dépenses d'exploitation | B20: Total Operating Expenses | C20: =+SALES!B127 -> 99960 | D20: =+SALES!C127 -> 140688 | E20: =+SALES!D127 -> 182621.4 | F20: =+SALES!E127 -> 221362.14 | G20: =+SALES!F127 -> 251244.16
A21: dépenses salariales | B21: Payroll Expenses | C21: =+'Expense Assumptions'!B71 -> 0 | D21: =+'Expense Assumptions'!C71 -> 91000 | E21: =+'Expense Assumptions'!D71 -> 237200 | F21: =+'Expense Assumptions'!E71 -> 420970 | G21: =+'Expense Assumptions'!F71 -> 700779.5
A23: Total des dépenses d'exploitation, y compris la masse salariale | B23: Total Operating Expenses including Payroll | C23: =+C21+C20 -> 99960 | D23: =+D21+D20 -> 231688 | E23: =+E21+E20 -> 419821.4 | F23: =+F21+F20 -> 642332.14 | G23: =+G21+G20 -> 952023.66
A25: EBITDA | B25: EBITDA | C25: =+C17-C23 -> 49890 | D25: =+D17-D23 -> 196355.75 | E25: =+E17-E23 -> 698706.1 | F25: =+F17-F23 -> 1519797.9 | G25: =+G17-G23 -> 2486178.8
A27: Amortissement et dépréciation | B27: Depreciation & Amortization
A28: Intérêt | B28: Interest
A30: Bénéfice avant impôt (BAI) | B30: Profit Before Tax (PBT) | C30: =+C25-C27-C28 -> 49890 | D30: =+D25-D27-D28 -> 196355.75 | E30: =+E25-E27-E28 -> 698706.1 | F30: =+F25-F27-F28 -> 1519797.9 | G30: =+G25-G27-G28 -> 2486178.8
