Workbook

Sheet Index
C5: DVS financial Data
C7: For | D7: FN | F7: Contact: | G7: Jean-Claude Havaux
C8: Version | D8: 2000K 1.0 | G8: CEO
C9: Author | D9: JCH | G9: Jc.havaux@brevomotors.com
C10: Date: | D10: 45159
A15: 1 | B15: Instructions
A16: 2 | B16: DATA Raw
A17: 3 | B17: Competitors
A18: 4 | B18: Dashboard | C18: NOT INCLUDED
A19: 5 | B19: Controls
A20: 6 | B20: Revenue Asumptions
A21: 7 | B21: Expense Assumptions
A22: 8 | B22: Payroll Assumptions
A23: 9 | B23: Debt Schedule
A24: 10 | B24: Fixed Asset Schedules
A25: 11 | B25: Working Capital Schedule
A26: 12 | B26: Monthly P&L
A27: 13 | B27: Annual P&L
A28: 14 | B28: Monthly CFS
A29: 15 | B29: Annual CFS
A30: 16 | B30: Balance Sheet
A31: 17 | B31: Valuation

Sheet DATA Raw
A1: DATA RAW FOR MARKET POTENTIAL CALCULATION
B2: Min | C2: Max
A3: Market Growth % | B3: 8 | C3: 12
A5: Epidemiology – Allergies
A6: Dogs: 12–18% prevalence | B6: 12 | C6: 18
A7: Cats: 10–14% prevalence | B7: 10 | C7: 14
A8: Symptomatic cases tested | C8: 25 | G8: Distribution Strategy EU5
G9: • FR: Centravet, Alcyon, Coveto
A10: Pet Allergy Diagnostics Market | G10: • IT: Agrisan, Virbac Italy
A11: Global: $370M (2025) → $714M (2035) | G11: • ES: Distrivet, Covetrus
A12: KIT SALES PRICES € | B12: Min € | C12: Max € | G12: • DE: Alvetra & Werfft
A13: Lab IgE panels ELISA | B13: 85 | C13: 150 | G13: • BE: Ecuphar, Cenvet
A14: Rapid tests: | B14: 28 | C14: 45
A15: Dot arrays: | B15: 120 | C15: 180
A16: DIATECH Rapid Test | B16: 35 | C16: 39
A17: DIATECH Array | B17: 120 | C17: 150
A18: READER SALES PRICES €
A19: Unknown | B19: 1000
A21: CLINICS & MARKET POTENTIAL TESTS | B21: Clinics | C21: Tests Max
A22: France | B22: 7200 | C22: 270000
A23: Germany | B23: 10000 | C23: =+C22/B22*B23 -> 375000
A24: Italy | B24: 8500 | C24: =+C23/B23*B24 -> 318750
A25: Spain | B25: 7100 | C25: =+C24/B24*B25 -> 266250
A26: Belgium | B26: 750 | C26: =+C25/B25*B26 -> 28125
C27: =SUM(C22:C26) -> 1258125 | D27: TEST/Y
A32: Metric France | B32: Value | C32: Notes
A33: Number of veterinary clinics | B33: 7500 | C33: Ordre National des Vétérinaires (France) | G33: =+#REF!*30000 -> #REF! | H33: € turnover
A34: Dogs population (million) | B34: 7.6 | C34: FACCO / Kantar
A35: Cats population (million) | B35: 15.1 | C35: FACCO / Kantar
A36: Dermatology-related consultations (%) | B36: 15–20% | C36: Veterinary dermatology benchmarks
A37: Average test price (€) | B37: 35 | C37: JCHYTECH internal pricing
A38: Target gross margin (%) | B38: 60 | C38: Manufacturing & distribution model
G42: =+#REF!*30000 -> #REF! | H42: € turnover
G49: /Year
G50: /Year
G51: /Year

Sheet Competitors
B1: € VAT excl | C1: Parts VATe | D1: Total W/o taxes | E1: PRIX TTC
A2: 1
A8: 2

Sheet Controls
A1: DIATECH
A2: Controls Sheet
A3: Amounts in €
B4: Year 1 | C4: Year 2 | D4: Year 3 | E4: Year 4 | F4: Year 5
A5: Assumptions for the Annual Period | B5: 2026 | C5: =+B5+1 -> 2027 | D5: =+C5+1 -> 2028 | E5: =+D5+1 -> 2029 | F5: =+E5+1 -> 2030
A6: Start Date of the Model | B6: 46174
A7: REVENUE ASSUMPTIONS
A9: Quarterly Sales Targets
A11: Thermic Units
A12: La 12T Belgium | B12: =SUM('Revenue Asumptions'!B10:M10) -> 0 | C12: =SUM('Revenue Asumptions'!N10:Y10) -> 0 | D12: =SUM('Revenue Asumptions'!Z10:AK10) -> 0 | E12: =SUM('Revenue Asumptions'!AL10:AW10) -> 0 | F12: =SUM('Revenue Asumptions'!AX10:BI10) -> 0
A13: La 12T France | B13: =SUM('Revenue Asumptions'!B11:M11) -> 0 | C13: =SUM('Revenue Asumptions'!N11:Y11) -> 0 | D13: =SUM('Revenue Asumptions'!Z11:AK11) -> 0 | E13: =SUM('Revenue Asumptions'!AL11:AW11) -> 0 | F13: =SUM('Revenue Asumptions'!AX11:BI11) -> 0
A14: La 12T Europe | B14: =SUM('Revenue Asumptions'!B12:M12) -> 0 | C14: =SUM('Revenue Asumptions'!N12:Y12) -> 0 | D14: =SUM('Revenue Asumptions'!Z12:AK12) -> 0 | E14: =SUM('Revenue Asumptions'!AL12:AW12) -> 0 | F14: =SUM('Revenue Asumptions'!AX12:BI12) -> 0
A15: La 12T USA | B15: =SUM('Revenue Asumptions'!B13:M13) -> 0 | C15: =SUM('Revenue Asumptions'!N13:Y13) -> 0 | D15: =SUM('Revenue Asumptions'!Z13:AK13) -> 0 | E15: =SUM('Revenue Asumptions'!AL13:AW13) -> 0 | F15: =SUM('Revenue Asumptions'!AX13:BI13) -> 0
A16: La 12T SE ASIA | B16: =SUM('Revenue Asumptions'!B14:M14) -> 0 | C16: =SUM('Revenue Asumptions'!N14:Y14) -> 0 | D16: =SUM('Revenue Asumptions'!Z14:AK14) -> 0 | E16: =SUM('Revenue Asumptions'!AL14:AW14) -> 0 | F16: =SUM('Revenue Asumptions'!AX14:BI14) -> 0
B17: =SUM(B12:B16) -> 0 | C17: =SUM(C12:C16) -> 0 | D17: =SUM(D12:D16) -> 0 | E17: =SUM(E12:E16) -> 0 | F17: =SUM(F12:F16) -> 0
A18: Electric Units
A19: La 12E Belgium | B19: =SUM('Revenue Asumptions'!B21:M21) -> 0 | C19: =SUM('Revenue Asumptions'!N21:AK21) -> 0 | D19: =SUM('Revenue Asumptions'!Z21:AK21) -> 0 | E19: =SUM('Revenue Asumptions'!AL21:AW21) -> 0 | F19: =SUM('Revenue Asumptions'!AX21:BI21) -> 0
A20: La 12E France | B20: =SUM('Revenue Asumptions'!B22:M22) -> 0 | C20: =SUM('Revenue Asumptions'!N22:AK22) -> 0 | D20: =SUM('Revenue Asumptions'!Z22:AK22) -> 0 | E20: =SUM('Revenue Asumptions'!AL22:AW22) -> 0 | F20: =SUM('Revenue Asumptions'!AX22:BI22) -> 0
A21: La 12E Europe | B21: =SUM('Revenue Asumptions'!B23:M23) -> 0 | C21: =SUM('Revenue Asumptions'!N23:AK23) -> 0 | D21: =SUM('Revenue Asumptions'!Z23:AK23) -> 0 | E21: =SUM('Revenue Asumptions'!AL23:AW23) -> 0 | F21: =SUM('Revenue Asumptions'!AX23:BI23) -> 0
A22: La 12E USA | B22: =SUM('Revenue Asumptions'!B24:M24) -> 0 | C22: =SUM('Revenue Asumptions'!N24:AK24) -> 0 | D22: =SUM('Revenue Asumptions'!Z24:AK24) -> 0 | E22: =SUM('Revenue Asumptions'!AL24:AW24) -> 0 | F22: =SUM('Revenue Asumptions'!AX24:BI24) -> 0
A23: La 12E SE ASIA | B23: =SUM('Revenue Asumptions'!B25:M25) -> 0 | C23: =SUM('Revenue Asumptions'!N25:AK25) -> 0 | D23: =SUM('Revenue Asumptions'!Z25:AK25) -> 0 | E23: =SUM('Revenue Asumptions'!AL25:AW25) -> 0 | F23: =SUM('Revenue Asumptions'!AX25:BI25) -> 0
B24: =SUM(B19:B23) -> 0 | C24: =SUM(C19:C23) -> 0 | D24: =SUM(D19:D23) -> 0 | E24: =SUM(E19:E23) -> 0 | F24: =SUM(F19:F23) -> 0
A25: KITS RAPID TEST
A26: Total Units Sold | B26: =SUM(B27:B29) -> 8100 | C26: =SUM(C27:C29) -> 23137.5 | D26: =SUM(D27:D29) -> 46275 | E26: =SUM(E27:E29) -> 76350 | F26: =SUM(F27:F29) -> 104805
A27: FRANCE | B27: =+'DATA Raw'!C22*0.03 -> 8100 | C27: =+B27*2 -> 16200 | D27: =+C27*2 -> 32400 | E27: =+D27*1.5 -> 48600 | F27: =+E27*1.3 -> 63180
A28: COUNTRIES 2 | C28: =+'DATA Raw'!C24*0.01 -> 3187.5 | D28: =+C28*2 -> 6375 | E28: =+D28*2 -> 12750 | F28: =+E28*1.5 -> 19125
A29: COUNTRIES 3 | B29: =+(B17+B24)*0.2 -> 0 | C29: =+'DATA Raw'!C23*0.01 -> 3750 | D29: =+C29*2 -> 7500 | E29: =+D29*2 -> 15000 | F29: =+E29*1.5 -> 22500
A30: Revenue generated | B30: =+B26*'DATA Raw'!$B$16 -> 283500 | C30: =+C26*'DATA Raw'!$B$16 -> 809812.5 | D30: =+D26*'DATA Raw'!$B$16 -> 1619625 | E30: =+E26*'DATA Raw'!$B$16 -> 2672250 | F30: =+F26*'DATA Raw'!$B$16 -> 3668175
A31: KITS ARRAY | B31: =+(B17+B24)*0.3 -> 0 | C31: =+(C17+C24)*0.3 -> 0 | D31: =+(D17+D24)*0.3 -> 0 | E31: =+(E17+E24)*0.3 -> 0 | F31: =+(F17+F24)*0.3 -> 0
A32: Total Units Sold | B32: =SUM(B33:B35) -> 0 | C32: =SUM(C33:C35) -> 0 | D32: =SUM(D33:D35) -> 4860 | E32: =SUM(E33:E35) -> 13882.5 | F32: =SUM(F33:F35) -> 27765
A33: FRANCE | D33: =+B27*0.6 -> 4860 | E33: =+C27*0.6 -> 9720 | F33: =+D27*0.6 -> 19440
A34: COUNTRIES 2 | D34: =+B28*0.6 -> 0 | E34: =+C28*0.6 -> 1912.5 | F34: =+D28*0.6 -> 3825
A35: COUNTRIES 3 | D35: =+B29*0.6 -> 0 | E35: =+C29*0.6 -> 2250 | F35: =+D29*0.6 -> 4500
A36: Revenue generated | F36: =SUM(F33:F35) -> 27765
A37: READERS | B37: 0 | C37: =B37*(1+C38) -> 0 | D37: =C37*(1+D38) -> 0 | E37: =D37*(1+E38) -> 0 | F37: =E37*(1+F38) -> 0
A38: Total Units Sold | C38: 0.05 | D38: 0.05 | E38: 0.05 | F38: 0.05
A39: FRANCE | B39: 0 | C39: =B39*(1+C40) -> 0 | D39: =C39*(1+D40) -> 0 | E39: =D39*(1+E40) -> 0 | F39: =E39*(1+F40) -> 0
A40: COUNTRIES 2 | C40: 0.05 | D40: 0.05 | E40: 0.05 | F40: 0.05
A41: COUNTRIES 3 | B41: 0.25 | C41: 0.25 | D41: 0.25 | E41: 0.25 | F41: 0.25
A42: Revenue generated | C42: NA | D42: NA | E42: NA | F42: NA
...

Sheet Revenue Asumptions
A1: DIATECH
A2: Revenue Assumptions Sheet
A3: Amounts in € | B3: =YEAR(B5) -> 2026 | C3: =YEAR(C5) -> 2026 | D3: =YEAR(D5) -> 2026 | E3: =YEAR(E5) -> 2026 | F3: =YEAR(F5) -> 2026 | G3: =YEAR(G5) -> 2026 | H3: =YEAR(H5) -> 2026 | I3: =YEAR(I5) -> 2027 | ... BI3: =YEAR(BI5) -> 2031
B4: 1 | C4: =B4+1 -> 2 | D4: =C4+1 -> 3 | E4: =D4+1 -> 4 | F4: =E4+1 -> 5 | G4: =F4+1 -> 6 | H4: =G4+1 -> 7 | I4: =H4+1 -> 8 | J4: =I4+1 -> 9 | ... BI4: =BH4+1 -> 60
A5: Assumptions for the Monthly Period | B5: =Controls!B6 -> 46174 | C5: =DATE(YEAR(B5),MONTH(B5)+1,DAY(B5)) -> 46204 | D5: =DATE(YEAR(C5),MONTH(C5)+1,DAY(C5)) -> 46235 | E5: =DATE(YEAR(D5),MONTH(D5)+1,DAY(D5)) -> 46266 | F5: =DATE(YEAR(E5),MONTH(E5)+1,DAY(E5)) -> 46296 | G5: =DATE(YEAR(F5),MONTH(F5)+1,DAY(F5)) -> 46327 | H5: =DATE(YEAR(G5),MONTH(G5)+1,DAY(G5)) -> 46357 | I5: =DATE(YEAR(H5),MONTH(H5)+1,DAY(H5)) -> 46388 | J5: =DATE(YEAR(I5),MONTH(I5)+1,DAY(I5)) -> 46419 | ... BI5: =DATE(YEAR(BH5),MONTH(BH5)+1,DAY(BH5)) -> 47969
A7: Unit Sales
A9: Thermic Units
A10: La 12T Belgium | B10: 0 | C10: 0 | D10: 0 | E10: 0 | F10: 0 | G10: 0 | H10: 0 | I10: 0 | J10: 0 | K10: 0 | L10: 0 | M10: 0 | N10: 0 | O10: 0 | P10: 0 | Q10: 0 | R10: 0 | S10: 0 | T10: 0 | U10: 0 | V10: 0 | W10: 0 | X10: 0 | Y10: 0 | Z10: 0 | AA10: 0 | AB10: 0 | AC10: 0 | AD10: 0 | AE10: 0 | AF10: 0 | AG10: 0 | AH10: 0 | AI10: 0 | AJ10: 0 | AK10: 0 | AL10: 0 | AM10: 0 | AN10: 0 | AO10: 0 | AP10: 0 | AQ10: 0 | AR10: 0 | AS10: 0 | AT10: 0 | AU10: 0 | AV10: 0 | AW10: 0 | AX10: 0 | AY10: 0 | AZ10: 0 | BA10: 0 | BB10: 0 | BC10: 0 | BD10: 0 | BE10: 0 | BF10: 0 | BG10: 0 | BH10: 0 | BI10: 0
A11: La 12T France | B11: 0 | C11: 0 | D11: 0 | E11: 0 | F11: 0 | G11: 0 | H11: 0 | I11: 0 | J11: 0 | K11: 0 | L11: 0 | M11: 0 | N11: 0 | O11: 0 | P11: 0 | Q11: 0 | R11: 0 | S11: 0 | T11: 0 | U11: 0 | V11: 0 | W11: 0 | X11: 0 | Y11: 0 | Z11: 0 | AA11: 0 | AB11: 0 | AC11: 0 | AD11: 0 | AE11: 0 | AF11: 0 | AG11: 0 | AH11: 0 | AI11: 0 | AJ11: 0 | AK11: 0 | AL11: 0 | AM11: 0 | AN11: 0 | AO11: 0 | AP11: 0 | AQ11: 0 | AR11: 0 | AS11: 0 | AT11: 0 | AU11: 0 | AV11: 0 | AW11: 0 | AX11: 0 | AY11: 0 | AZ11: 0 | BA11: 0 | BB11: 0 | BC11: 0 | BD11: 0 | BE11: 0 | BF11: 0 | BG11: 0 | BH11: 0 | BI11: 0
A12: La 12T Europe | B12: 0 | C12: 0 | D12: 0 | E12: 0 | F12: 0 | G12: 0 | H12: 0 | I12: 0 | J12: 0 | K12: 0 | L12: 0 | M12: 0 | N12: 0 | O12: 0 | P12: 0 | Q12: 0 | R12: 0 | S12: 0 | T12: 0 | U12: 0 | V12: 0 | W12: 0 | X12: 0 | Y12: 0 | Z12: 0 | AA12: 0 | AB12: 0 | AC12: 0 | AD12: 0 | AE12: 0 | AF12: 0 | AG12: 0 | AH12: 0 | AI12: 0 | AJ12: 0 | AK12: 0 | AL12: 0 | AM12: 0 | AN12: 0 | AO12: 0 | AP12: 0 | AQ12: 0 | AR12: 0 | AS12: 0 | AT12: 0 | AU12: 0 | AV12: 0 | AW12: 0 | AX12: 0 | AY12: 0 | AZ12: 0 | BA12: 0 | BB12: 0 | BC12: 0 | BD12: 0 | BE12: 0 | BF12: 0 | BG12: 0 | BH12: 0 | BI12: 0
A13: La 12T USA | B13: 0 | C13: 0 | D13: 0 | E13: 0 | F13: 0 | G13: 0 | H13: 0 | I13: 0 | J13: 0 | K13: 0 | L13: 0 | M13: 0 | N13: 0 | O13: 0 | P13: 0 | Q13: 0 | R13: 0 | S13: 0 | T13: 0 | U13: 0 | V13: 0 | W13: 0 | X13: 0 | Y13: 0 | Z13: 0 | AA13: 0 | AB13: 0 | AC13: 0 | AD13: 0 | AE13: 0 | AF13: 0 | AG13: 0 | AH13: 0 | AI13: 0 | AJ13: 0 | AK13: 0 | AL13: 0 | AM13: 0 | AN13: 0 | AO13: 0 | AP13: 0 | AQ13: 0 | AR13: 0 | AS13: 0 | AT13: 0 | AU13: 0 | AV13: 0 | AW13: 0 | AX13: 0 | AY13: 0 | AZ13: 0 | BA13: 0 | BB13: 0 | BC13: 0 | BD13: 0 | BE13: 0 | BF13: 0 | BG13: 0 | BH13: 0 | BI13: 0
A14: La 12T SE ASIA | B14: 0 | C14: 0 | D14: 0 | E14: 0 | F14: 0 | G14: 0 | H14: 0 | I14: 0 | J14: 0 | K14: 0 | L14: 0 | M14: 0 | N14: 0 | O14: 0 | P14: 0 | Q14: 0 | R14: 0 | S14: 0 | T14: 0 | U14: 0 | V14: 0 | W14: 0 | X14: 0 | Y14: 0 | Z14: 0 | AA14: 0 | AB14: 0 | AC14: 0 | AD14: 0 | AE14: 0 | AF14: 0 | AG14: 0 | AH14: 0 | AI14: 0 | AJ14: 0 | AK14: 0 | AL14: 0 | AM14: 0 | AN14: 0 | AO14: 0 | AP14: 0 | AQ14: 0 | AR14: 0 | AS14: 0 | AT14: 0 | AU14: 0 | AV14: 0 | AW14: 0 | AX14: 0 | AY14: 0 | AZ14: 0 | BA14: 0 | BB14: 0 | BC14: 0 | BD14: 0 | BE14: 0 | BF14: 0 | BG14: 0 | BH14: 0 | BI14: 0
A15: Total Units Sold | B15: =ROUND(SUM(B10:B14),0) -> 0 | C15: =ROUND(SUM(C10:C14),0) -> 0 | D15: =ROUND(SUM(D10:D14),0) -> 0 | E15: =ROUND(SUM(E10:E14),0) -> 0 | F15: =ROUND(SUM(F10:F14),0) -> 0 | G15: =ROUND(SUM(G10:G14),0) -> 0 | H15: =ROUND(SUM(H10:H14),0) -> 0 | I15: =ROUND(SUM(I10:I14),0) -> 0 | ... BI15: =ROUND(SUM(BI10:BI14),0) -> 0
A17: Thermic Unit Average Price | B17: =HLOOKUP(B$3,Controls!$A$5:$F$558,MATCH($A17,Controls!$A$5:$A$564,0),0) -> #N/A | C17: =HLOOKUP(C$3,Controls!$A$5:$F$558,MATCH($A17,Controls!$A$5:$A$564,0),0) -> #N/A | D17: =HLOOKUP(D$3,Controls!$A$5:$F$558,MATCH($A17,Controls!$A$5:$A$564,0),0) -> #N/A | E17: =HLOOKUP(E$3,Controls!$A$5:$F$558,MATCH($A17,Controls!$A$5:$A$564,0),0) -> #N/A | F17: =HLOOKUP(F$3,Controls!$A$5:$F$558,MATCH($A17,Controls!$A$5:$A$564,0),0) -> #N/A | G17: =HLOOKUP(G$3,Controls!$A$5:$F$558,MATCH($A17,Controls!$A$5:$A$564,0),0) -> #N/A | H17: =HLOOKUP(H$3,Controls!$A$5:$F$558,MATCH($A17,Controls!$A$5:$A$564,0),0) -> #N/A | I17: =HLOOKUP(I$3,Controls!$A$5:$F$558,MATCH($A17,Controls!$A$5:$A$564,0),0) -> #N/A | ... BI17: =HLOOKUP(BI$3,Controls!$A$5:$F$558,MATCH($A17,Controls!$A$5:$A$564,0),0) -> #N/A
A18: Revenue from Sale of Thermic Units | B18: =B15*B17 -> #N/A | C18: =C15*C17 -> #N/A | D18: =D15*D17 -> #N/A | E18: =E15*E17 -> #N/A | F18: =F15*F17 -> #N/A | G18: =G15*G17 -> #N/A | H18: =H15*H17 -> #N/A | I18: =I15*I17 -> #N/A | ... BI18: =BI15*BI17 -> #N/A
A20: Electric Units
A21: La 12E Belgium | B21: 0 | C21: 0 | D21: 0 | E21: 0 | F21: 0 | G21: 0 | H21: 0 | I21: 0 | J21: 0 | K21: 0 | L21: 0 | M21: 0 | N21: 0 | O21: 0 | P21: 0 | Q21: 0 | R21: 0 | S21: 0 | T21: 0 | U21: 0 | V21: 0 | W21: 0 | X21: 0 | Y21: 0 | Z21: 0 | AA21: 0 | AB21: 0 | AC21: 0 | AD21: 0 | AE21: 0 | AF21: 0 | AG21: 0 | AH21: 0 | AI21: 0 | AJ21: 0 | AK21: 0 | AL21: 0 | AM21: 0 | AN21: 0 | AO21: 0 | AP21: 0 | AQ21: 0 | AR21: 0 | AS21: 0 | AT21: 0 | AU21: 0 | AV21: 0 | AW21: 0 | AX21: 0 | AY21: 0 | AZ21: 0 | BA21: 0 | BB21: 0 | BC21: 0 | BD21: 0 | BE21: 0 | BF21: 0 | BG21: 0 | BH21: 0 | BI21: 0
A22: La 12E France | B22: 0 | C22: 0 | D22: 0 | E22: 0 | F22: 0 | G22: 0 | H22: 0 | I22: 0 | J22: 0 | K22: 0 | L22: 0 | M22: 0 | N22: 0 | O22: 0 | P22: 0 | Q22: 0 | R22: 0 | S22: 0 | T22: 0 | U22: 0 | V22: 0 | W22: 0 | X22: 0 | Y22: 0 | Z22: 0 | AA22: 0 | AB22: 0 | AC22: 0 | AD22: 0 | AE22: 0 | AF22: 0 | AG22: 0 | AH22: 0 | AI22: 0 | AJ22: 0 | AK22: 0 | AL22: 0 | AM22: 0 | AN22: 0 | AO22: 0 | AP22: 0 | AQ22: 0 | AR22: 0 | AS22: 0 | AT22: 0 | AU22: 0 | AV22: 0 | AW22: 0 | AX22: 0 | AY22: 0 | AZ22: 0 | BA22: 0 | BB22: 0 | BC22: 0 | BD22: 0 | BE22: 0 | BF22: 0 | BG22: 0 | BH22: 0 | BI22: 0
A23: La 12E Europe | B23: 0 | C23: 0 | D23: 0 | E23: 0 | F23: 0 | G23: 0 | H23: 0 | I23: 0 | J23: 0 | K23: 0 | L23: 0 | M23: 0 | N23: 0 | O23: 0 | P23: 0 | Q23: 0 | R23: 0 | S23: 0 | T23: 0 | U23: 0 | V23: 0 | W23: 0 | X23: 0 | Y23: 0 | Z23: 0 | AA23: 0 | AB23: 0 | AC23: 0 | AD23: 0 | AE23: 0 | AF23: 0 | AG23: 0 | AH23: 0 | AI23: 0 | AJ23: 0 | AK23: 0 | AL23: 0 | AM23: 0 | AN23: 0 | AO23: 0 | AP23: 0 | AQ23: 0 | AR23: 0 | AS23: 0 | AT23: 0 | AU23: 0 | AV23: 0 | AW23: 0 | AX23: 0 | AY23: 0 | AZ23: 0 | BA23: 0 | BB23: 0 | BC23: 0 | BD23: 0 | BE23: 0 | BF23: 0 | BG23: 0 | BH23: 0 | BI23: 0
A24: La 12E USA | B24: 0 | C24: 0 | D24: 0 | E24: 0 | F24: 0 | G24: 0 | H24: 0 | I24: 0 | J24: 0 | K24: 0 | L24: 0 | M24: 0 | N24: 0 | O24: 0 | P24: 0 | Q24: 0 | R24: 0 | S24: 0 | T24: 0 | U24: 0 | V24: 0 | W24: 0 | X24: 0 | Y24: 0 | Z24: 0 | AA24: 0 | AB24: 0 | AC24: 0 | AD24: 0 | AE24: 0 | AF24: 0 | AG24: 0 | AH24: 0 | AI24: 0 | AJ24: 0 | AK24: 0 | AL24: 0 | AM24: 0 | AN24: 0 | AO24: 0 | AP24: 0 | AQ24: 0 | AR24: 0 | AS24: 0 | AT24: 0 | AU24: 0 | AV24: 0 | AW24: 0 | AX24: 0 | AY24: 0 | AZ24: 0 | BA24: 0 | BB24: 0 | BC24: 0 | BD24: 0 | BE24: 0 | BF24: 0 | BG24: 0 | BH24: 0 | BI24: 0
A25: La 12E SE ASIA | B25: 0 | C25: 0 | D25: 0 | E25: 0 | F25: 0 | G25: 0 | H25: 0 | I25: 0 | J25: 0 | K25: 0 | L25: 0 | M25: 0 | N25: 0 | O25: 0 | P25: 0 | Q25: 0 | R25: 0 | S25: 0 | T25: 0 | U25: 0 | V25: 0 | W25: 0 | X25: 0 | Y25: 0 | Z25: 0 | AA25: 0 | AB25: 0 | AC25: 0 | AD25: 0 | AE25: 0 | AF25: 0 | AG25: 0 | AH25: 0 | AI25: 0 | AJ25: 0 | AK25: 0 | AL25: 0 | AM25: 0 | AN25: 0 | AO25: 0 | AP25: 0 | AQ25: 0 | AR25: 0 | AS25: 0 | AT25: 0 | AU25: 0 | AV25: 0 | AW25: 0 | AX25: 0 | AY25: 0 | AZ25: 0 | BA25: 0 | BB25: 0 | BC25: 0 | BD25: 0 | BE25: 0 | BF25: 0 | BG25: 0 | BH25: 0 | BI25: 0
A26: Total Units Sold | B26: =ROUND(SUM(B21:B25),0) -> 0 | C26: =ROUND(SUM(C21:C25),0) -> 0 | D26: =ROUND(SUM(D21:D25),0) -> 0 | E26: =ROUND(SUM(E21:E25),0) -> 0 | F26: =ROUND(SUM(F21:F25),0) -> 0 | G26: =ROUND(SUM(G21:G25),0) -> 0 | H26: =ROUND(SUM(H21:H25),0) -> 0 | I26: =ROUND(SUM(I21:I25),0) -> 0 | ... BI26: =ROUND(SUM(BI21:BI25),0) -> 0
A28: Electric Unit Average Price | B28: =HLOOKUP(B$3,Controls!$A$5:$F$558,MATCH($A28,Controls!$A$5:$A$564,0),0) -> #N/A | C28: =HLOOKUP(C$3,Controls!$A$5:$F$558,MATCH($A28,Controls!$A$5:$A$564,0),0) -> #N/A | D28: =HLOOKUP(D$3,Controls!$A$5:$F$558,MATCH($A28,Controls!$A$5:$A$564,0),0) -> #N/A | E28: =HLOOKUP(E$3,Controls!$A$5:$F$558,MATCH($A28,Controls!$A$5:$A$564,0),0) -> #N/A | F28: =HLOOKUP(F$3,Controls!$A$5:$F$558,MATCH($A28,Controls!$A$5:$A$564,0),0) -> #N/A | G28: =HLOOKUP(G$3,Controls!$A$5:$F$558,MATCH($A28,Controls!$A$5:$A$564,0),0) -> #N/A | H28: =HLOOKUP(H$3,Controls!$A$5:$F$558,MATCH($A28,Controls!$A$5:$A$564,0),0) -> #N/A | I28: =HLOOKUP(I$3,Controls!$A$5:$F$558,MATCH($A28,Controls!$A$5:$A$564,0),0) -> #N/A | ... BI28: =HLOOKUP(BI$3,Controls!$A$5:$F$558,MATCH($A28,Controls!$A$5:$A$564,0),0) -> #N/A
A29: Revenue from sale of Electric Units | B29: =B26*B28 -> #N/A | C29: =C26*C28 -> #N/A | D29: =D26*D28 -> #N/A | E29: =E26*E28 -> #N/A | F29: =F26*F28 -> #N/A | G29: =G26*G28 -> #N/A | H29: =H26*H28 -> #N/A | I29: =I26*I28 -> #N/A | ... BI29: =BI26*BI28 -> #N/A
A31: Spare Parts and Aftermarket Services
A32: Spare Parts and Aftermarket Services as a % of Sales | B32: =HLOOKUP(B$3,Controls!$A$5:$F$558,MATCH($A32,Controls!$A$5:$A$564,0),0) -> #N/A | C32: =HLOOKUP(C$3,Controls!$A$5:$F$558,MATCH($A32,Controls!$A$5:$A$564,0),0) -> #N/A | D32: =HLOOKUP(D$3,Controls!$A$5:$F$558,MATCH($A32,Controls!$A$5:$A$564,0),0) -> #N/A | E32: =HLOOKUP(E$3,Controls!$A$5:$F$558,MATCH($A32,Controls!$A$5:$A$564,0),0) -> #N/A | F32: =HLOOKUP(F$3,Controls!$A$5:$F$558,MATCH($A32,Controls!$A$5:$A$564,0),0) -> #N/A | G32: =HLOOKUP(G$3,Controls!$A$5:$F$558,MATCH($A32,Controls!$A$5:$A$564,0),0) -> #N/A | H32: =HLOOKUP(H$3,Controls!$A$5:$F$558,MATCH($A32,Controls!$A$5:$A$564,0),0) -> #N/A | I32: =HLOOKUP(I$3,Controls!$A$5:$F$558,MATCH($A32,Controls!$A$5:$A$564,0),0) -> #N/A | ... BI32: =HLOOKUP(BI$3,Controls!$A$5:$F$558,MATCH($A32,Controls!$A$5:$A$564,0),0) -> #N/A
A33: Revenue generated | B33: =(B18+B29)*B32 -> #N/A | C33: =(C18+C29)*C32 -> #N/A | D33: =(D18+D29)*D32 -> #N/A | E33: =(E18+E29)*E32 -> #N/A | F33: =(F18+F29)*F32 -> #N/A | G33: =(G18+G29)*G32 -> #N/A | H33: =(H18+H29)*H32 -> #N/A | I33: =(I18+I29)*I32 -> #N/A | ... BI33: =(BI18+BI29)*BI32 -> #N/A
A35: KITS RAPID TEST
A36: Total Units Sold | J36: =+('DATA Raw'!#REF!/10+'DATA Raw'!#REF!/10)/2 -> #REF! | V36: =+J36*1.5 -> #REF! | AH36: =+V36*2 -> #REF! | AT36: =+AH36*1.7 -> #REF! | BF36: =+AT36*1.75 -> #REF!
A37: FRANCE
A38: COUNTRIES 2
A39: COUNTRIES 3
A40: Revenue generated | B40: =+B36*Controls!$B$43 -> 0 | C40: =+C36*Controls!$B$43 -> 0 | D40: =+D36*Controls!$B$43 -> 0 | E40: =+E36*Controls!$B$43 -> 0 | F40: =+F36*Controls!$B$43 -> 0 | G40: =+G36*Controls!$B$43 -> 0 | H40: =+H36*Controls!$B$43 -> 0 | I40: =+I36*Controls!$B$43 -> 0 | ... M40: =+M36*Controls!$B$43 -> 0 | N40: =+N36*Controls!$C$43 -> 0 | O40: =+O36*Controls!$C$43 -> 0 | P40: =+P36*Controls!$C$43 -> 0 | Q40: =+Q36*Controls!$C$43 -> 0 | R40: =+R36*Controls!$C$43 -> 0 | S40: =+S36*Controls!$C$43 -> 0 | T40: =+T36*Controls!$C$43 -> 0 | U40: =+U36*Controls!$C$43 -> 0 | ... Y40: =+Y36*Controls!$C$43 -> 0 | Z40: =+Z36*Controls!$D$43 -> 0 | AA40: =+AA36*Controls!$D$43 -> 0 | AB40: =+AB36*Controls!$D$43 -> 0 | AC40: =+AC36*Controls!$D$43 -> 0 | AD40: =+AD36*Controls!$D$43 -> 0 | AE40: =+AE36*Controls!$D$43 -> 0 | AF40: =+AF36*Controls!$D$43 -> 0 | AG40: =+AG36*Controls!$D$43 -> 0 | ... AK40: =+AK36*Controls!$D$43 -> 0 | AL40: =+AL36*Controls!$E$43 -> 0 | AM40: =+AM36*Controls!$E$43 -> 0 | AN40: =+AN36*Controls!$E$43 -> 0 | AO40: =+AO36*Controls!$E$43 -> 0 | AP40: =+AP36*Controls!$E$43 -> 0 | AQ40: =+AQ36*Controls!$E$43 -> 0 | AR40: =+AR36*Controls!$E$43 -> 0 | AS40: =+AS36*Controls!$E$43 -> 0 | ... AW40: =+AW36*Controls!$E$43 -> 0 | AX40: =+AX36*Controls!$F$43 -> 0 | AY40: =+AY36*Controls!$F$43 -> 0 | AZ40: =+AZ36*Controls!$F$43 -> 0 | BA40: =+BA36*Controls!$F$43 -> 0 | BB40: =+BB36*Controls!$F$43 -> 0 | BC40: =+BC36*Controls!$F$43 -> 0 | BD40: =+BD36*Controls!$F$43 -> 0 | BE40: =+BE36*Controls!$F$43 -> 0 | ... BI40: =+BI36*Controls!$F$43 -> 0
A41: KITS ARRAY
A42: Total Units Sold | J42: =+('DATA Raw'!#REF!/10+'DATA Raw'!#REF!/10)/2 -> #REF! | V42: =+J42*1.5 -> #REF! | AH42: =+V42*2 -> #REF! | AT42: =+AH42*1.7 -> #REF! | BF42: =+AT42*1.75 -> #REF!
A43: FRANCE
A44: COUNTRIES 2
A45: COUNTRIES 3
A46: Revenue generated | B46: =+B42*Controls!$B$43 -> 0 | C46: =+C42*Controls!$B$43 -> 0 | D46: =+D42*Controls!$B$43 -> 0 | E46: =+E42*Controls!$B$43 -> 0 | F46: =+F42*Controls!$B$43 -> 0 | G46: =+G42*Controls!$B$43 -> 0 | H46: =+H42*Controls!$B$43 -> 0 | I46: =+I42*Controls!$B$43 -> 0 | ... M46: =+M42*Controls!$B$43 -> 0 | N46: =+N42*Controls!$C$43 -> 0 | O46: =+O42*Controls!$C$43 -> 0 | P46: =+P42*Controls!$C$43 -> 0 | Q46: =+Q42*Controls!$C$43 -> 0 | R46: =+R42*Controls!$C$43 -> 0 | S46: =+S42*Controls!$C$43 -> 0 | T46: =+T42*Controls!$C$43 -> 0 | U46: =+U42*Controls!$C$43 -> 0 | ... Y46: =+Y42*Controls!$C$43 -> 0 | Z46: =+Z42*Controls!$D$43 -> 0 | AA46: =+AA42*Controls!$D$43 -> 0 | AB46: =+AB42*Controls!$D$43 -> 0 | AC46: =+AC42*Controls!$D$43 -> 0 | AD46: =+AD42*Controls!$D$43 -> 0 | AE46: =+AE42*Controls!$D$43 -> 0 | AF46: =+AF42*Controls!$D$43 -> 0 | AG46: =+AG42*Controls!$D$43 -> 0 | ... AK46: =+AK42*Controls!$D$43 -> 0 | AL46: =+AL42*Controls!$E$43 -> 0 | AM46: =+AM42*Controls!$E$43 -> 0 | AN46: =+AN42*Controls!$E$43 -> 0 | AO46: =+AO42*Controls!$E$43 -> 0 | AP46: =+AP42*Controls!$E$43 -> 0 | AQ46: =+AQ42*Controls!$E$43 -> 0 | AR46: =+AR42*Controls!$E$43 -> 0 | AS46: =+AS42*Controls!$E$43 -> 0 | ... AW46: =+AW42*Controls!$E$43 -> 0 | AX46: =+AX42*Controls!$F$43 -> 0 | AY46: =+AY42*Controls!$F$43 -> 0 | AZ46: =+AZ42*Controls!$F$43 -> 0 | BA46: =+BA42*Controls!$F$43 -> 0 | BB46: =+BB42*Controls!$F$43 -> 0 | BC46: =+BC42*Controls!$F$43 -> 0 | BD46: =+BD42*Controls!$F$43 -> 0 | BE46: =+BE42*Controls!$F$43 -> 0 | BF46: =+BF42*Controls!$F$43 -> #REF!
A47: READERS
...

Sheet Expense Assumptions
A1: DVS
A2: Expense Assumptions Sheet
A3: Amounts in €
A5: Assumptions for the Monthly Period
A7: Cost Of Goods Sold (COGS)
B8: Year 1 | C8: Year 2 | D8: Year 3 | E8: Year 4 | F8: Year 5
A9: Thermic Units Sold | B9: 2026 | C9: =+B9+1 -> 2027 | D9: =+C9+1 -> 2028 | E9: =+D9+1 -> 2029 | F9: =+E9+1 -> 2030
A10: Thermic Unit Average Cost
A11: Distrib Costs
A12: Cost of sales for Thermic Units
A14: Electric Units Sold
A15: Electric Unit Average Cost
A16: Distrib Costs
A17: Cost of sales for Electric Units
A19: Cost of Sales for Spare Parts and Aftermarket Services as a % of sales
A20: Distrib Costs or royalties
A21: Cost of Sales for Spare Parts and Aftermarket Services
A23: PRODUCTS
A24: Cost Of Rapid TEST | B24: =+Controls!B30*0.5 -> 141750 | C24: =+Controls!C30*0.5 -> 404906.25 | D24: =+Controls!D30*0.5 -> 809812.5 | E24: =+Controls!E30*0.5 -> 1336125 | F24: =+Controls!F30*0.5 -> 1834087.5
A25: cost of Array TEST | B25: =+Controls!B46*0.55 -> 8910 | C25: =+Controls!C46*0.55 -> 25451.25 | D25: =+Controls!D46*0.55 -> 50902.5 | E25: =+Controls!E46*0.55 -> 83985 | F25: =+Controls!F46*0.55 -> 115285.5
A26: Cost of Readers | B26: =+Controls!B46*0.5 -> 8100 | C26: =+Controls!C46*0.5 -> 23137.5 | D26: =+Controls!D46*0.5 -> 46275 | E26: =+Controls!E46*0.5 -> 76350 | F26: =+Controls!F46*0.5 -> 104805
A27: Cost of Sales | B27: =SUM(B24:B26) -> 158760 | C27: =SUM(C24:C26) -> 453495 | D27: =SUM(D24:D26) -> 906990 | E27: =SUM(E24:E26) -> 1496460 | F27: =SUM(F24:F26) -> 2054178
A30: Operating Expenses (OPEX)
A32: Car rental | B32: =+Controls!B64 -> 0 | C32: =+Controls!C64 -> 3600 | D32: =+Controls!D64 -> 3960 | E32: =+Controls!E64 -> 4554 | F32: =+Controls!F64 -> 5009.4
A33: Commercial vehicle rentals | B33: =+Controls!B68 -> 0 | C33: =+Controls!C68 -> 0 | D33: =+Controls!D68 -> 3600 | E33: =+Controls!E68 -> 4140 | F33: =+Controls!F68 -> 4554
A34: Fuel | B34: =+Controls!B70 -> 0 | C34: =+Controls!C70 -> 300 | D34: =+Controls!D70 -> 450 | E34: =+Controls!E70 -> 517.5 | F34: =+Controls!F70 -> 569.25
A35: Travel costs (parking, etc.) | B35: =+Controls!B76 -> 4800 | C35: =+Controls!C76 -> 6000 | D35: =+Controls!D76 -> 7500 | E35: =+Controls!E76 -> 8250 | F35: =+Controls!F76 -> 9075
A36: Car insurance (omnium) | B36: =+Controls!B80 -> 0 | C36: =+Controls!C80 -> 1440 | D36: =+Controls!D80 -> 2160 | E36: =+Controls!E80 -> 2484 | F36: =+Controls!F80 -> 2732.4
A37: Events , Fairs , Missions | B37: =+Controls!B84 -> 1800 | C37: =+Controls!C84 -> 3600 | D37: =+Controls!D84 -> 3960 | E37: =+Controls!E84 -> 4554 | F37: =+Controls!F84 -> 3000
A38: Website | B38: =+Controls!B88 -> 2400 | C38: =+Controls!C88 -> 3000 | D38: =+Controls!D88 -> 3750 | E38: =+Controls!E88 -> 4312.5 | F38: =+Controls!F88 -> 4743.75
A39: Advertising / SPONSORSHIP | B39: =+Controls!B92 -> 1200 | C39: =+Controls!C92 -> 1320 | D39: =+Controls!D92 -> 1452 | E39: =+Controls!E92 -> 1669.8 | F39: =+Controls!F92 -> 1836.78
A40: Building rent | B40: =+Controls!B96 -> 2400 | C40: =+Controls!C96 -> 6000 | D40: =+Controls!D96 -> 12000 | E40: =+Controls!E96 -> 24000 | F40: =+Controls!F96 -> 26400
A41: Office General & Admin | B41: =+Controls!B100 -> 3000 | C41: =+Controls!C100 -> 4500 | D41: =+Controls!D100 -> 6750 | E41: =+Controls!E100 -> 10125 | F41: =+Controls!F100 -> 15187.5
A42: Consulting fees 1 (JCH) | B42: =+Controls!B104 -> 36000 | C42: =+Controls!C104 -> 43200 | D42: =+Controls!D104 -> 49680 | E42: =+Controls!E104 -> 57132 | F42: =+Controls!F104 -> 65701.8
A43: Consulting fees 2 (AB) | B43: =+Controls!B108 -> 36000 | C43: =+Controls!C108 -> 48600 | D43: =+Controls!D108 -> 65610 | E43: =+Controls!E108 -> 75451.5 | F43: =+Controls!F108 -> 86769.225
A44: Accounting fees | B44: =+Controls!B112 -> 1800 | C44: =+Controls!C112 -> 3600 | D44: =+Controls!D112 -> 3960 | E44: =+Controls!E112 -> 4356 | F44: =+Controls!F112 -> 4573.8
A45: Lawyer fees | B45: =+Controls!B116 -> 1200 | C45: =+Controls!C116 -> 2400 | D45: =+Controls!D116 -> 2520 | E45: =+Controls!E116 -> 2772 | F45: =+Controls!F116 -> 2910.6
A46: Coordination chinese partners | B46: =+Controls!B120 -> 9000 | C46: =+Controls!C120 -> 9450 | D46: =+Controls!D120 -> 9922.5 | E46: =+Controls!E120 -> 10914.75 | F46: =+Controls!F120 -> 11460.488
A47: Professional contribution | B47: =+Controls!B124 -> 360 | C47: =+Controls!C124 -> 378 | D47: =+Controls!D124 -> 396.9 | E47: =+Controls!E124 -> 436.59 | F47: =+Controls!F124 -> 458.4195
A48: Overheads | B48: 0 | C48: 0 | D48: 0 | E48: 0 | F48: 0
...

Sheet RH TIMELINE
D8: 1Q1 | E8: 1Q2 | F8: 1Q3 | G8: 1Q4 | H8: 2Q1 | I8: 2Q2 | J8: 2Q3 | K8: 2Q4 | L8: 3Q1 | M8: 3Q2 | N8: 3Q3 | O8: 3Q4 | P8: 4Q1 | Q8: 4Q2 | R8: 4Q3 | S8: 4Q4 | T8: 5Q1 | U8: 5Q2 | V8: 5Q3 | W8: 5Q4
B35: N = | C35: 24
B37: CIRCUIT MANAGER
B38: CIRCUIT OPERATOR
B40: Decision BOD

Sheet Payroll Assumptions
A1: DVS
A2: Payroll Sheet
A3: Amounts in €
A5: Assumptions for the Monthly Period
A7: Employment

Sheet Debt Schedule
A1: DIATECH
A2: Debt Schedule
A3: Amounts in €
A5: Assumptions for the Monthly Period
A7: Total Interest Payments
A8: Total Principal Payments
A9: Total Closing Balance
A12: Loan for Technical Stock
A13: Monthly Interest Rate
A14: Opening Balance at the start
A15: Future Value
A16: Tenure (in Months)
... A51: Closing Balance

Sheet Fixed Asset Schedules
A1: DIATECH
A2: Fixed Assets Schedules Sheet
A3: Amounts in €
A5: Assumptions for the Monthly Period
A7: Total Opening Balance
A8: Total Fixed Asset Additions
A9: Total Depreciation
A10: Total Closing Balance
A12: Intangible Assets
A14: Licence Technology (Prodution, R&D and Netwroks)
A15: Monthly Depreciation
A17: Opening Balance
... A94: Closing Balance

Sheet Working Capital Schedule
A1: DIATECH
A2: Working Capital Schedules
A3: Amounts in €
A5: Assumptions for the Monthly Period
A7: Inventory
A8: Inventory Cycle
A9: Inventory Growth after year 5
A11: COGS
A12: Inventory
A13: PAYMENT FURNISHER anticipation Cogs at 4 months
A14: OPEX Furnisher
A15: TOTAL PAYMENTS
... A22: Trade Receivables

Sheet Monthly P&L
A1: DVS
A2: Monthly Profit & Loss Statement
A3: Amounts in € | B3: =YEAR(B5) -> 2026 | C3: =YEAR(C5) -> 2026 | D3: =YEAR(D5) -> 2026 | E3: =YEAR(E5) -> 2026 | F3: =YEAR(F5) -> 2026 | G3: =YEAR(G5) -> 2026 | H3: =YEAR(H5) -> 2026 | I3: =YEAR(I5) -> 2027 | ... BI3: =YEAR(BI5) -> 2031
B4: 1 | C4: =B4+1 -> 2 | D4: =C4+1 -> 3 | E4: =D4+1 -> 4 | F4: =E4+1 -> 5 | G4: =F4+1 -> 6 | H4: =G4+1 -> 7 | I4: =H4+1 -> 8 | J4: =I4+1 -> 9 | ... BI4: =BH4+1 -> 60
A5: Assumptions for the Monthly Period | B5: ='Revenue Asumptions'!B5 -> 46174 | C5: ='Revenue Asumptions'!C5 -> 46204 | D5: ='Revenue Asumptions'!D5 -> 46235 | E5: ='Revenue Asumptions'!E5 -> 46266 | F5: ='Revenue Asumptions'!F5 -> 46296 | G5: ='Revenue Asumptions'!G5 -> 46327 | H5: ='Revenue Asumptions'!H5 -> 46357 | I5: ='Revenue Asumptions'!I5 -> 46388 | ... BI5: ='Revenue Asumptions'!BI5 -> 47969
A7: Thermic Unit Sales | B7: ='Revenue Asumptions'!B18 -> #N/A | C7: ='Revenue Asumptions'!C18 -> #N/A | D7: ='Revenue Asumptions'!D18 -> #N/A | E7: ='Revenue Asumptions'!E18 -> #N/A | F7: ='Revenue Asumptions'!F18 -> #N/A | G7: ='Revenue Asumptions'!G18 -> #N/A | H7: ='Revenue Asumptions'!H18 -> #N/A | I7: ='Revenue Asumptions'!I18 -> #N/A | ... BI7: ='Revenue Asumptions'!BI18 -> #N/A
A8: Electric Unit Sales | B8: ='Revenue Asumptions'!B29 -> #N/A | C8: ='Revenue Asumptions'!C29 -> #N/A | D8: ='Revenue Asumptions'!D29 -> #N/A | E8: ='Revenue Asumptions'!E29 -> #N/A | F8: ='Revenue Asumptions'!F29 -> #N/A | G8: ='Revenue Asumptions'!G29 -> #N/A | H8: ='Revenue Asumptions'!H29 -> #N/A | I8: ='Revenue Asumptions'!I29 -> #N/A | ... BI8: ='Revenue Asumptions'!BI29 -> #N/A
A9: Spare Parts and Aftermarket Services | B9: =+'Revenue Asumptions'!B33 -> #N/A | C9: =+'Revenue Asumptions'!C33 -> #N/A | D9: =+'Revenue Asumptions'!D33 -> #N/A | E9: =+'Revenue Asumptions'!E33 -> #N/A | F9: =+'Revenue Asumptions'!F33 -> #N/A | G9: =+'Revenue Asumptions'!G33 -> #N/A | H9: =+'Revenue Asumptions'!H33 -> #N/A | I9: =+'Revenue Asumptions'!I33 -> #N/A | ... BI9: =+'Revenue Asumptions'!BI33 -> #N/A
A10: SIM Sales | B10: =+'Revenue Asumptions'!B40 -> 0 | C10: =+'Revenue Asumptions'!C40 -> 0 | D10: =+'Revenue Asumptions'!D40 -> 0 | E10: =+'Revenue Asumptions'!E40 -> 0 | F10: =+'Revenue Asumptions'!F40 -> 0 | G10: =+'Revenue Asumptions'!G40 -> 0 | H10: =+'Revenue Asumptions'!H40 -> 0 | I10: =+'Revenue Asumptions'!I40 -> 0 | ... BI10: =+'Revenue Asumptions'!BI40 -> 0
A11: Services | B11: =+'Revenue Asumptions'!B57 -> #REF! | C11: =+'Revenue Asumptions'!C57 -> #REF! | D11: =+'Revenue Asumptions'!D57 -> #REF! | E11: =+'Revenue Asumptions'!E57 -> #REF! | F11: =+'Revenue Asumptions'!F57 -> #REF! | G11: =+'Revenue Asumptions'!G57 -> #REF! | H11: =+'Revenue Asumptions'!H57 -> #REF! | I11: =+'Revenue Asumptions'!I57 -> #REF! | ... BI11: =+'Revenue Asumptions'!BI57 -> 0
A12: R&D Subsidies | B12: 0 | C12: 0 | D12: 0 | E12: 0 | F12: 0 | G12: 0 | H12: 0 | I12: 0 | J12: 0 | K12: 0 | L12: 0 | M12: 0 | N12: 0 | O12: 0 | P12: 0 | Q12: 0 | R12: 0 | S12: 0 | T12: 0 | U12: 0 | V12: 0 | W12: 0 | X12: 0 | Y12: 0 | Z12: 0 | AA12: 0 | AB12: 0 | AC12: 0 | AD12: 0 | AE12: 0 | AF12: 0 | AG12: 0 | AH12: 0 | AI12: 0 | AJ12: 0 | AK12: 0 | AL12: 0 | AM12: 0 | AN12: 0 | AO12: 0 | AP12: 0 | AQ12: 0 | AR12: 0 | AS12: 0 | AT12: 0 | AU12: 0 | AV12: 0 | AW12: 0 | AX12: 0 | AY12: 0 | AZ12: 0 | BA12: 0 | BB12: 0 | BC12: 0 | BD12: 0 | BE12: 0 | BF12: 0 | BG12: 0 | BH12: 0 | BI12: 0 | BJ12: POTENTIAL OF GRANT/SUBSIDIES IS NOT CONSIDERED IN THIS PLAN
A14: Total Revenue | B14: =SUM(B7:B13) -> #N/A | C14: =SUM(C7:C13) -> #N/A | D14: =SUM(D7:D13) -> #N/A | E14: =SUM(E7:E13) -> #N/A | F14: =SUM(F7:F13) -> #N/A | G14: =SUM(G7:G13) -> #N/A | H14: =SUM(H7:H13) -> #N/A | I14: =SUM(I7:I13) -> #N/A | ... BI14: =SUM(BI7:BI13) -> #N/A
A17: Thermic Units | B17: ='Expense Assumptions'!#REF! -> #REF! | C17: ='Expense Assumptions'!#REF! -> #REF! | D17: ='Expense Assumptions'!#REF! -> #REF! | E17: ='Expense Assumptions'!#REF! -> #REF! | F17: ='Expense Assumptions'!#REF! -> #REF! | G17: ='Expense Assumptions'!#REF! -> #REF! | H17: ='Expense Assumptions'!#REF! -> #REF! | I17: ='Expense Assumptions'!#REF! -> #REF! | ... BI17: ='Expense Assumptions'!#REF! -> #REF!
A18: Electric Units | B18: ='Expense Assumptions'!#REF! -> #REF! | C18: ='Expense Assumptions'!#REF! -> #REF! | D18: ='Expense Assumptions'!#REF! -> #REF! | E18: ='Expense Assumptions'!#REF! -> #REF! | F18: ='Expense Assumptions'!#REF! -> #REF! | G18: ='Expense Assumptions'!#REF! -> #REF! | H18: ='Expense Assumptions'!#REF! -> #REF! | I18: ='Expense Assumptions'!#REF! -> #REF! | ... BI18: ='Expense Assumptions'!#REF! -> #REF!
A19: Spare Parts and Aftermarket Services | B19: ='Expense Assumptions'!#REF! -> #REF! | C19: ='Expense Assumptions'!#REF! -> #REF! | D19: ='Expense Assumptions'!#REF! -> #REF! | E19: ='Expense Assumptions'!#REF! -> #REF! | F19: ='Expense Assumptions'!#REF! -> #REF! | G19: ='Expense Assumptions'!#REF! -> #REF! | H19: ='Expense Assumptions'!#REF! -> #REF! | I19: ='Expense Assumptions'!#REF! -> #REF! | ... BI19: ='Expense Assumptions'!#REF! -> #REF!
A20: SIM Sales | B20: =+'Expense Assumptions'!#REF! -> #REF! | C20: =+'Expense Assumptions'!#REF! -> #REF! | D20: =+'Expense Assumptions'!#REF! -> #REF! | E20: =+'Expense Assumptions'!#REF! -> #REF! | F20: =+'Expense Assumptions'!#REF! -> #REF! | G20: =+'Expense Assumptions'!#REF! -> #REF! | H20: =+'Expense Assumptions'!#REF! -> #REF! | I20: =+'Expense Assumptions'!#REF! -> #REF! | ... BI20: =+'Expense Assumptions'!#REF! -> #REF!
A21: Services | B21: =+'Expense Assumptions'!#REF! -> #REF! | C21: =+'Expense Assumptions'!#REF! -> #REF! | D21: =+'Expense Assumptions'!#REF! -> #REF! | E21: =+'Expense Assumptions'!#REF! -> #REF! | F21: =+'Expense Assumptions'!#REF! -> #REF! | G21: =+'Expense Assumptions'!#REF! -> #REF! | H21: =+'Expense Assumptions'!#REF! -> #REF! | I21: =+'Expense Assumptions'!#REF! -> #REF! | ... BI21: =+'Expense Assumptions'!#REF! -> #REF!
A22: R&D Subsidies | B22: =+'Expense Assumptions'!#REF! -> #REF! | C22: =+'Expense Assumptions'!#REF! -> #REF! | D22: =+'Expense Assumptions'!#REF! -> #REF! | E22: =+'Expense Assumptions'!#REF! -> #REF! | F22: =+'Expense Assumptions'!#REF! -> #REF! | G22: =+'Expense Assumptions'!#REF! -> #REF! | H22: =+'Expense Assumptions'!#REF! -> #REF! | I22: =+'Expense Assumptions'!#REF! -> #REF! | ... BI22: =+'Expense Assumptions'!#REF! -> #REF! | BJ22: POTENTIAL OF GRANT/SUBSIDIES IS NOT CONSIDERED IN THIS PLAN
A24: Total COGS | B24: =SUM(B17:B23) -> #REF! | C24: =SUM(C17:C23) -> #REF! | D24: =SUM(D17:D23) -> #REF! | E24: =SUM(E17:E23) -> #REF! | F24: =SUM(F17:F23) -> #REF! | G24: =SUM(G17:G23) -> #REF! | H24: =SUM(H17:H23) -> #REF! | I24: =SUM(I17:I23) -> #REF! | ... BI24: =SUM(BI17:BI23) -> #REF!
A26: Gross Profit | B26: =B14-B24 -> #N/A | C26: =C14-C24 -> #N/A | D26: =D14-D24 -> #N/A | E26: =E14-E24 -> #N/A | F26: =F14-F24 -> #N/A | G26: =G14-G24 -> #N/A | H26: =H14-H24 -> #N/A | I26: =I14-I24 -> #N/A | ... BI26: =BI14-BI24 -> #N/A
A27: Gross Margin % | B27: =+IF(B26>0,B26/B14,"NA") -> #N/A | C27: =+IF(C26>0,C26/C14,"NA") -> #N/A | D27: =+IF(D26>0,D26/D14,"NA") -> #N/A | E27: =+IF(E26>0,E26/E14,"NA") -> #N/A | F27: =+IF(F26>0,F26/F14,"NA") -> #N/A | G27: =+IF(G26>0,G26/G14,"NA") -> #N/A | H27: =+IF(H26>0,H26/H14,"NA") -> #N/A | I27: =+IF(I26>0,I26/I14,"NA") -> #N/A | ... BI27: =+IF(BI26>0,BI26/BI14,"NA") -> #N/A
A29: Operating Expenses
A31: Car rental | B31: ='Expense Assumptions'!#REF! -> #REF! | C31: ='Expense Assumptions'!#REF! -> #REF! | D31: ='Expense Assumptions'!#REF! -> #REF! | E31: ='Expense Assumptions'!#REF! -> #REF! | F31: ='Expense Assumptions'!#REF! -> #REF! | G31: ='Expense Assumptions'!#REF! -> #REF! | H31: ='Expense Assumptions'!#REF! -> #REF! | I31: ='Expense Assumptions'!#REF! -> #REF! | ... BI31: ='Expense Assumptions'!#REF! -> #REF!
A32: Commercial vehicle rentals | B32: ='Expense Assumptions'!#REF! -> #REF! | C32: ='Expense Assumptions'!#REF! -> #REF! | D32: ='Expense Assumptions'!#REF! -> #REF! | E32: ='Expense Assumptions'!#REF! -> #REF! | F32: ='Expense Assumptions'!#REF! -> #REF! | G32: ='Expense Assumptions'!#REF! -> #REF! | H32: ='Expense Assumptions'!#REF! -> #REF! | I32: ='Expense Assumptions'!#REF! -> #REF! | ... BI32: ='Expense Assumptions'!#REF! -> #REF!
A33: Fuel | B33: ='Expense Assumptions'!#REF! -> #REF! | C33: ='Expense Assumptions'!#REF! -> #REF! | D33: ='Expense Assumptions'!#REF! -> #REF! | E33: ='Expense Assumptions'!#REF! -> #REF! | F33: ='Expense Assumptions'!#REF! -> #REF! | G33: ='Expense Assumptions'!#REF! -> #REF! | H33: ='Expense Assumptions'!#REF! -> #REF! | I33: ='Expense Assumptions'!#REF! -> #REF! | ... BI33: ='Expense Assumptions'!#REF! -> #REF!
A34: Travel costs (parking, etc.) | B34: ='Expense Assumptions'!#REF! -> #REF! | C34: ='Expense Assumptions'!#REF! -> #REF! | D34: ='Expense Assumptions'!#REF! -> #REF! | E34: ='Expense Assumptions'!#REF! -> #REF! | F34: ='Expense Assumptions'!#REF! -> #REF! | G34: ='Expense Assumptions'!#REF! -> #REF! | H34: ='Expense Assumptions'!#REF! -> #REF! | I34: ='Expense Assumptions'!#REF! -> #REF! | ... BI34: ='Expense Assumptions'!#REF! -> #REF!
A35: Car insurance (omnium) | B35: ='Expense Assumptions'!#REF! -> #REF! | C35: ='Expense Assumptions'!#REF! -> #REF! | D35: ='Expense Assumptions'!#REF! -> #REF! | E35: ='Expense Assumptions'!#REF! -> #REF! | F35: ='Expense Assumptions'!#REF! -> #REF! | G35: ='Expense Assumptions'!#REF! -> #REF! | H35: ='Expense Assumptions'!#REF! -> #REF! | I35: ='Expense Assumptions'!#REF! -> #REF! | ... BI35: ='Expense Assumptions'!#REF! -> #REF!
A36: Travels | B36: ='Expense Assumptions'!#REF! -> #REF! | C36: ='Expense Assumptions'!#REF! -> #REF! | D36: ='Expense Assumptions'!#REF! -> #REF! | E36: ='Expense Assumptions'!#REF! -> #REF! | F36: ='Expense Assumptions'!#REF! -> #REF! | G36: ='Expense Assumptions'!#REF! -> #REF! | H36: ='Expense Assumptions'!#REF! -> #REF! | I36: ='Expense Assumptions'!#REF! -> #REF! | ... BI36: ='Expense Assumptions'!#REF! -> #REF!
A37: Events and Restaurants | B37: ='Expense Assumptions'!#REF! -> #REF! | C37: ='Expense Assumptions'!#REF! -> #REF! | D37: ='Expense Assumptions'!#REF! -> #REF! | E37: ='Expense Assumptions'!#REF! -> #REF! | F37: ='Expense Assumptions'!#REF! -> #REF! | G37: ='Expense Assumptions'!#REF! -> #REF! | H37: ='Expense Assumptions'!#REF! -> #REF! | I37: ='Expense Assumptions'!#REF! -> #REF! | ... BI37: ='Expense Assumptions'!#REF! -> #REF!
A38: Fairs, missions | B38: ='Expense Assumptions'!#REF! -> #REF! | C38: ='Expense Assumptions'!#REF! -> #REF! | D38: ='Expense Assumptions'!#REF! -> #REF! | E38: ='Expense Assumptions'!#REF! -> #REF! | F38: ='Expense Assumptions'!#REF! -> #REF! | G38: ='Expense Assumptions'!#REF! -> #REF! | H38: ='Expense Assumptions'!#REF! -> #REF! | I38: ='Expense Assumptions'!#REF! -> #REF! | ... BI38: ='Expense Assumptions'!#REF! -> #REF!
A39: Subscriptions and dues Federations HORS DORNA | B39: ='Expense Assumptions'!#REF! -> #REF! | C39: ='Expense Assumptions'!#REF! -> #REF! | D39: ='Expense Assumptions'!#REF! -> #REF! | E39: ='Expense Assumptions'!#REF! -> #REF! | F39: ='Expense Assumptions'!#REF! -> #REF! | G39: ='Expense Assumptions'!#REF! -> #REF! | H39: ='Expense Assumptions'!#REF! -> #REF! | I39: ='Expense Assumptions'!#REF! -> #REF! | ... BI39: ='Expense Assumptions'!#REF! -> #REF!
A40: Website | B40: ='Expense Assumptions'!#REF! -> #REF! | C40: ='Expense Assumptions'!#REF! -> #REF! | D40: ='Expense Assumptions'!#REF! -> #REF! | E40: ='Expense Assumptions'!#REF! -> #REF! | F40: ='Expense Assumptions'!#REF! -> #REF! | G40: ='Expense Assumptions'!#REF! -> #REF! | H40: ='Expense Assumptions'!#REF! -> #REF! | I40: ='Expense Assumptions'!#REF! -> #REF! | ... BI40: ='Expense Assumptions'!#REF! -> #REF!
A41: Prints/Tshirts/Goodies | B41: ='Expense Assumptions'!#REF! -> #REF! | C41: ='Expense Assumptions'!#REF! -> #REF! | D41: ='Expense Assumptions'!#REF! -> #REF! | E41: ='Expense Assumptions'!#REF! -> #REF! | F41: ='Expense Assumptions'!#REF! -> #REF! | G41: ='Expense Assumptions'!#REF! -> #REF! | H41: ='Expense Assumptions'!#REF! -> #REF! | I41: ='Expense Assumptions'!#REF! -> #REF! | ... BI41: ='Expense Assumptions'!#REF! -> #REF!
A42: Advertising / SPONSORSHIP | B42: ='Expense Assumptions'!#REF! -> #REF! | C42: ='Expense Assumptions'!#REF! -> #REF! | D42: ='Expense Assumptions'!#REF! -> #REF! | E42: ='Expense Assumptions'!#REF! -> #REF! | F42: ='Expense Assumptions'!#REF! -> #REF! | G42: ='Expense Assumptions'!#REF! -> #REF! | H42: ='Expense Assumptions'!#REF! -> #REF! | I42: ='Expense Assumptions'!#REF! -> #REF! | ... BI42: ='Expense Assumptions'!#REF! -> #REF!
... A50: Overheads | B50: ='Expense Assumptions'!#REF! -> #REF! | C50: ='Expense Assumptions'!#REF! -> #REF! | D50: ='Expense Assumptions'!#REF! -> #REF! | E50: ='Expense Assumptions'!#REF! -> #REF! | F50: ='Expense Assumptions'!#REF! -> #REF! | G50: ='Expense Assumptions'!#REF! -> #REF! | H50: ='Expense Assumptions'!#REF! -> #REF! | I50: ='Expense Assumptions'!#REF! -> #REF! | ... BI50: ='Expense Assumptions'!#REF! -> #REF!
A52: Total Operating Expenses | B52: =SUM(B31:B51) -> #REF! | C52: =SUM(C31:C51) -> #REF! | D52: =SUM(D31:D51) -> #REF! | E52: =SUM(E31:E51) -> #REF! | F52: =SUM(F31:F51) -> #REF! | G52: =SUM(G31:G51) -> #REF! | H52: =SUM(H31:H51) -> #REF! | I52: =SUM(I31:I51) -> #REF! | ... BI52: =SUM(BI31:BI51) -> #REF!
A54: Payroll Expenses | B54: ='Payroll Assumptions'!#REF! -> #REF! | C54: ='Payroll Assumptions'!#REF! -> #REF! | D54: ='Payroll Assumptions'!#REF! -> #REF! | E54: ='Payroll Assumptions'!#REF! -> #REF! | F54: ='Payroll Assumptions'!#REF! -> #REF! | G54: ='Payroll Assumptions'!#REF! -> #REF! | H54: ='Payroll Assumptions'!#REF! -> #REF! | I54: ='Payroll Assumptions'!#REF! -> #REF! | ... BI54: ='Payroll Assumptions'!#REF! -> #REF!
A56: Total Operating Expenses including Payroll | B56: =B52+B54 -> #REF! | C56: =C52+C54 -> #REF! | D56: =D52+D54 -> #REF! | E56: =E52+E54 -> #REF! | F56: =F52+F54 -> #REF! | G56: =G52+G54 -> #REF! | H56: =H52+H54 -> #REF! | I56: =I52+I54 -> #REF! | ... BI56: =BI52+BI54 -> #REF!
A58: EBITDA | B58: =B26-B56 -> #N/A | C58: =C26-C56 -> #N/A | D58: =D26-D56 -> #N/A | E58: =E26-E56 -> #N/A | F58: =F26-F56 -> #N/A | G58: =G26-G56 -> #N/A | H58: =H26-H56 -> #N/A | I58: =I26-I56 -> #N/A | ... BI58: =BI26-BI56 -> #N/A
A59: EBITDA Margin (%) | B59: =+IF(B58>0,B58/B14,"NA") -> #N/A | C59: =+IF(C58>0,C58/C14,"NA") -> #N/A | D59: =+IF(D58>0,D58/D14,"NA") -> #N/A | E59: =+IF(E58>0,E58/E14,"NA") -> #N/A | F59: =+IF(F58>0,F58/F14,"NA") -> #N/A | G59: =+IF(G58>0,G58/G14,"NA") -> #N/A | H59: =+IF(H58>0,H58/H14,"NA") -> #N/A | I59: =+IF(I58>0,I58/I14,"NA") -> #N/A | ... BI59: =+IF(BI58>0,BI58/BI14,"NA") -> #N/A
...

Sheet Annual P&L
A1: DIATECH
A2: Compte de résultat annuel Montants en € | B2: Annual Profit & Loss Statement
B3: Amounts in €
A4: Hypothèses pour la période annuelle | B4: Assumptions for the Annual Period | C4: =+Controls!B5 -> 2026 | D4: =Controls!C5 -> 2027 | E4: =Controls!D5 -> 2028 | F4: =Controls!E5 -> 2029 | G4: =Controls!F5 -> 2030
A5: SIM
A6: Services | B6: Thermic Unit Sales | C6: =SUMIF('Monthly P&L'!$B$3:$BI$3,C$4,'Monthly P&L'!$B7:$BI7) -> #N/A | D6: =SUMIF('Monthly P&L'!$B$3:$BI$3,D$4,'Monthly P&L'!$B7:$BI7) -> #N/A | E6: =SUMIF('Monthly P&L'!$B$3:$BI$3,E$4,'Monthly P&L'!$B7:$BI7) -> #N/A | F6: =SUMIF('Monthly P&L'!$B$3:$BI$3,F$4,'Monthly P&L'!$B7:$BI7) -> #N/A | G6: =SUMIF('Monthly P&L'!$B$3:$BI$3,G$4,'Monthly P&L'!$B7:$BI7) -> #N/A
A7: Subventions à la R&D | B7: Electric Unit Sales | C7: =SUMIF('Monthly P&L'!$B$3:$BI$3,C$4,'Monthly P&L'!$B8:$BI8) -> #N/A | D7: =SUMIF('Monthly P&L'!$B$3:$BI$3,D$4,'Monthly P&L'!$B8:$BI8) -> #N/A | E7: =SUMIF('Monthly P&L'!$B$3:$BI$3,E$4,'Monthly P&L'!$B8:$BI8) -> #N/A | F7: =SUMIF('Monthly P&L'!$B$3:$BI$3,F$4,'Monthly P&L'!$B8:$BI8) -> #N/A | G7: =SUMIF('Monthly P&L'!$B$3:$BI$3,G$4,'Monthly P&L'!$B8:$BI8) -> #N/A
A8: Chiffre d'affaires total | B8: Spare Parts and Aftermarket Services | C8: =SUMIF('Monthly P&L'!$B$3:$BI$3,C$4,'Monthly P&L'!$B9:$BI9) -> #N/A | D8: =SUMIF('Monthly P&L'!$B$3:$BI$3,D$4,'Monthly P&L'!$B9:$BI9) -> #N/A | E8: =SUMIF('Monthly P&L'!$B$3:$BI$3,E$4,'Monthly P&L'!$B9:$BI9) -> #N/A | F8: =SUMIF('Monthly P&L'!$B$3:$BI$3,F$4,'Monthly P&L'!$B9:$BI9) -> #N/A | G8: =SUMIF('Monthly P&L'!$B$3:$BI$3,G$4,'Monthly P&L'!$B9:$BI9) -> #N/A
A10: Chiffre d'affaires total | B10: Total Revenue | C10: =+Controls!B51 -> 299700 | D10: =+Controls!C51 -> 856087.5 | E10: =+Controls!D51 -> 2295375 | F10: =+Controls!E51 -> 4490850 | G10: =+Controls!F51 -> 7209585
B11: TESTS SOLD | C11: =+C10/39 -> 7684.6154 | D11: =+D10/39 -> 21950.962 | E11: =+E10/39 -> 58855.769 | F11: =+F10/39 -> 115150 | G11: =+G10/39 -> 184861.15
A12: SIM | B12: Thermic Units | C12: =SUMIF('Monthly P&L'!$B$3:$BI$3,C$4,'Monthly P&L'!$B16:$BI18) -> 0 | D12: =SUMIF('Monthly P&L'!$B$3:$BI$3,D$4,'Monthly P&L'!$B17:$BI17) -> #REF! | E12: =SUMIF('Monthly P&L'!$B$3:$BI$3,E$4,'Monthly P&L'!$B17:$BI17) -> #REF! | F12: =SUMIF('Monthly P&L'!$B$3:$BI$3,F$4,'Monthly P&L'!$B17:$BI17) -> #REF! | G12: =SUMIF('Monthly P&L'!$B$3:$BI$3,G$4,'Monthly P&L'!$B17:$BI17) -> #REF!
A13: Services | B13: Electric Units | C13: =SUMIF('Monthly P&L'!$B$3:$BI$3,C$4,'Monthly P&L'!$B17:$BI19) -> #REF! | D13: =SUMIF('Monthly P&L'!$B$3:$BI$3,D$4,'Monthly P&L'!$B18:$BI18) -> #REF! | E13: =SUMIF('Monthly P&L'!$B$3:$BI$3,E$4,'Monthly P&L'!$B18:$BI18) -> #REF! | F13: =SUMIF('Monthly P&L'!$B$3:$BI$3,F$4,'Monthly P&L'!$B18:$BI18) -> #REF! | G13: =SUMIF('Monthly P&L'!$B$3:$BI$3,G$4,'Monthly P&L'!$B18:$BI18) -> #REF!
A14: Subventions à la R&D | B14: Spare Parts and Aftermarket Services | C14: =SUMIF('Monthly P&L'!$B$3:$BI$3,C$4,'Monthly P&L'!$B18:$BI20) -> #REF! | D14: =SUMIF('Monthly P&L'!$B$3:$BI$3,D$4,'Monthly P&L'!$B19:$BI19) -> #REF! | E14: =SUMIF('Monthly P&L'!$B$3:$BI$3,E$4,'Monthly P&L'!$B19:$BI19) -> #REF! | F14: =SUMIF('Monthly P&L'!$B$3:$BI$3,F$4,'Monthly P&L'!$B19:$BI19) -> #REF! | G14: =SUMIF('Monthly P&L'!$B$3:$BI$3,G$4,'Monthly P&L'!$B19:$BI19) -> #REF!
A15: Coût total des marchandises vendues | B15: Total COGS | C15: =+'Expense Assumptions'!B27 -> 158760 | D15: =+'Expense Assumptions'!C27 -> 453495 | E15: =+'Expense Assumptions'!D27 -> 906990 | F15: =+'Expense Assumptions'!E27 -> 1496460 | G15: =+'Expense Assumptions'!F27 -> 2054178
A17: Bénéfice brut | B17: Gross Profit | C17: =C10-C15 -> 140940 | D17: =D10-D15 -> 402592.5 | E17: =E10-E15 -> 1388385 | F17: =F10-F15 -> 2994390 | G17: =G10-G15 -> 5155407
A20: Total des dépenses d'exploitation | B20: Total Operating Expenses | C20: =+Controls!B127 -> 99960 | D20: =+Controls!C127 -> 140688 | E20: =+Controls!D127 -> 182621.4 | F20: =+Controls!E127 -> 221362.14 | G20: =+Controls!F127 -> 251244.16
A21: dépenses salariales | B21: Payroll Expenses | C21: =+'Expense Assumptions'!B70 -> 0 | D21: =+'Expense Assumptions'!C70 -> 91000 | E21: =+'Expense Assumptions'!D70 -> 237200 | F21: =+'Expense Assumptions'!E70 -> 420970 | G21: =+'Expense Assumptions'!F70 -> 700779.5
A23: Total des dépenses d'exploitation, y compris la masse salariale | B23: Total Operating Expenses including Payroll | C23: =+C21+C20 -> 99960 | D23: =+D21+D20 -> 231688 | E23: =+E21+E20 -> 419821.4 | F23: =+F21+F20 -> 642332.14 | G23: =+G21+G20 -> 952023.66
A25: EBITDA | B25: EBITDA | C25: =+C17-C23 -> 40980 | D25: =+D17-D23 -> 170904.5 | E25: =+E17-E23 -> 968563.6 | F25: =+F17-F23 -> 2352057.9 | G25: =+G17-G23 -> 4203383.3
A27: Amortissement et dépréciation | B27: Depreciation & Amortization
A28: Intérêt | B28: Interest
A30: Bénéfice avant impôt (BAI) | B30: Profit Before Tax (PBT) | C30: =+C25-C27-C28 -> 40980 | D30: =+D25-D27-D28 -> 170904.5 | E30: =+E25-E27-E28 -> 968563.6 | F30: =+F25-F27-F28 -> 2352057.9 | G30: =+G25-G27-G28 -> 4203383.3

Sheet Monthly CFS
A1: DVS
A2: Monthly Cash Flow Statement
A3: Amounts in € | B3: =YEAR(B5) -> 2026 | C3: =YEAR(C5) -> 2026 | D3: =YEAR(D5) -> 2026 | E3: =YEAR(E5) -> 2026 | F3: =YEAR(F5) -> 2026 | G3: =YEAR(G5) -> 2026 | H3: =YEAR(H5) -> 2026 | I3: =YEAR(I5) -> 2027 | ... BI3: =YEAR(BI5) -> 2031
B4: 1 | C4: =B4+1 -> 2 | D4: =C4+1 -> 3 | E4: =D4+1 -> 4 | F4: =E4+1 -> 5 | G4: =F4+1 -> 6 | H4: =G4+1 -> 7 | I4: =H4+1 -> 8 | J4: =I4+1 -> 9 | ... BI4: =BH4+1 -> 60
A5: Assumptions for the Monthly Period | B5: ='Revenue Asumptions'!B5 -> 46174 | C5: ='Revenue Asumptions'!C5 -> 46204 | D5: ='Revenue Asumptions'!D5 -> 46235 | E5: ='Revenue Asumptions'!E5 -> 46266 | F5: ='Revenue Asumptions'!F5 -> 46296 | G5: ='Revenue Asumptions'!G5 -> 46327 | H5: ='Revenue Asumptions'!H5 -> 46357 | I5: ='Revenue Asumptions'!I5 -> 46388 | ... BI5: ='Revenue Asumptions'!BI5 -> 47969
A7: Cash flow from Operating Activities
A8: Profit before Tax | B8: ='Monthly P&L'!B64 -> #N/A | C8: ='Monthly P&L'!C64 -> #N/A | D8: ='Monthly P&L'!D64 -> #N/A | E8: ='Monthly P&L'!E64 -> #N/A | F8: ='Monthly P&L'!F64 -> #N/A | G8: ='Monthly P&L'!G64 -> #N/A | H8: ='Monthly P&L'!H64 -> #N/A | I8: ='Monthly P&L'!I64 -> #N/A | ... BI8: ='Monthly P&L'!BI64 -> #N/A
A9: Adjustments for:
A10: Add: Depreciation & Amortization | B10: =+'Monthly P&L'!B61 -> 0 | C10: =+'Monthly P&L'!C61 -> 0 | D10: =+'Monthly P&L'!D61 -> 0 | E10: =+'Monthly P&L'!E61 -> 0 | F10: =+'Monthly P&L'!F61 -> 0 | G10: =+'Monthly P&L'!G61 -> 0 | H10: =+'Monthly P&L'!H61 -> 0 | I10: =+'Monthly P&L'!I61 -> 0 | ... BI10: =+'Monthly P&L'!BI61 -> 0
A11: Sub: Increase in Inventory | B11: =-(' Balance Sheet'!D9-' Balance Sheet'!C9) -> #REF! | C11: =-(' Balance Sheet'!E9-' Balance Sheet'!D9) -> #REF! | D11: =-(' Balance Sheet'!F9-' Balance Sheet'!E9) -> #REF! | E11: =-(' Balance Sheet'!G9-' Balance Sheet'!F9) -> #REF! | F11: =-(' Balance Sheet'!H9-' Balance Sheet'!G9) -> #REF! | G11: =-(' Balance Sheet'!I9-' Balance Sheet'!H9) -> #REF! | H11: =-(' Balance Sheet'!J9-' Balance Sheet'!I9) -> #REF! | I11: =-(' Balance Sheet'!K9-' Balance Sheet'!J9) -> #REF! | ... BI11: =-(' Balance Sheet'!BK9-' Balance Sheet'!BJ9) -> #REF!
A12: Sub: Increase in Trade Receivables | B12: =-(' Balance Sheet'!D10-' Balance Sheet'!C10) -> #REF! | C12: =-(' Balance Sheet'!E10-' Balance Sheet'!D10) -> #REF! | D12: =-(' Balance Sheet'!F10-' Balance Sheet'!E10) -> #REF! | E12: =-(' Balance Sheet'!G10-' Balance Sheet'!F10) -> #REF! | F12: =-(' Balance Sheet'!H10-' Balance Sheet'!G10) -> #REF! | G12: =-(' Balance Sheet'!I10-' Balance Sheet'!H10) -> #REF! | H12: =-(' Balance Sheet'!J10-' Balance Sheet'!I10) -> #REF! | I12: =-(' Balance Sheet'!K10-' Balance Sheet'!J10) -> #REF! | ... BI12: =-(' Balance Sheet'!BK10-' Balance Sheet'!BJ10) -> #REF!
A14: Sub: Taxes paid | B14: =-'Monthly P&L'!B65 -> 0 | C14: =-'Monthly P&L'!C65 -> 0 | D14: =-'Monthly P&L'!D65 -> 0 | E14: =-'Monthly P&L'!E65 -> 0 | F14: =-'Monthly P&L'!F65 -> 0 | G14: =-'Monthly P&L'!G65 -> 0 | H14: =-'Monthly P&L'!H65 -> #VALUE! | I14: =-'Monthly P&L'!I65 -> 0 | ... BI14: =-'Monthly P&L'!BI65 -> 0
A16: Net Cash generated from Operating Activities | B16: =SUM(B8:B15) -> #N/A | C16: =SUM(C8:C15) -> #N/A | D16: =SUM(D8:D15) -> #N/A | E16: =SUM(E8:E15) -> #N/A | F16: =SUM(F8:F15) -> #N/A | G16: =SUM(G8:G15) -> #N/A | H16: =SUM(H8:H15) -> #N/A | I16: =SUM(I8:I15) -> #N/A | ... BI16: =SUM(BI8:BI15) -> #N/A
A18: Cash flow from Investing Activities
A19: Purchase of Fixed Assets | B19: =-'Fixed Asset Schedules'!B8 -> 0 | C19: =-'Fixed Asset Schedules'!C8 -> 0 | D19: =-'Fixed Asset Schedules'!D8 -> 0 | E19: =-'Fixed Asset Schedules'!E8 -> 0 | F19: =-'Fixed Asset Schedules'!F8 -> 0 | G19: =-'Fixed Asset Schedules'!G8 -> 0 | H19: =-'Fixed Asset Schedules'!H8 -> 0 | I19: =-'Fixed Asset Schedules'!I8 -> 0 | ... BI19: =-'Fixed Asset Schedules'!BI8 -> 0
A21: Net Cash used in Investing Activities | B21: =+B19 -> 0 | C21: =+C19 -> 0 | D21: =+D19 -> 0 | E21: =+E19 -> 0 | F21: =+F19 -> 0 | G21: =+G19 -> 0 | H21: =+H19 -> 0 | I21: =+I19 -> 0 | ... BI21: =+BI19 -> 0
A23: Cash flow from Financing Activities
A24: Issuance of Equity Share Capital | B24: 2000000 | C24: 0 | D24: 0 | E24: 0 | F24: 0 | G24: 0 | H24: 0 | I24: 0 | J24: 0 | K24: 0 | L24: 0 | M24: 0 | N24: 0 | O24: 0 | P24: 0 | Q24: 0 | R24: 0 | S24: 0 | T24: 0 | U24: 0 | V24: 0 | W24: 0 | X24: 0 | Y24: 0 | Z24: 0 | AA24: 0 | AB24: 0 | AC24: 0 | AD24: 0 | AE24: 0 | AF24: 0 | AG24: 0 | AH24: 0 | AI24: 0 | AJ24: 0 | AK24: 0 | AL24: 0 | AM24: 0 | AN24: 0 | AO24: 0 | AP24: 0 | AQ24: 0 | AR24: 0 | AS24: 0 | AT24: 0 | AU24: 0 | AV24: 0 | AW24: 0 | AX24: 0 | AY24: 0 | AZ24: 0 | BA24: 0 | BB24: 0 | BC24: 0 | BD24: 0 | BE24: 0 | BF24: 0 | BG24: 0 | BH24: 0 | BI24: 0
A25: Issuance of Debt | B25: ='Debt Schedule'!#REF! -> #REF! | AL25: ='Debt Schedule'!#REF! -> #REF! | AX25: ='Debt Schedule'!#REF! -> #REF!
A26: Debt repayment | B26: =-'Debt Schedule'!#REF! -> #REF! | C26: =-'Debt Schedule'!#REF! -> #REF! | D26: =-'Debt Schedule'!#REF! -> #REF! | E26: =-'Debt Schedule'!#REF! -> #REF! | F26: =-'Debt Schedule'!#REF! -> #REF! | G26: =-'Debt Schedule'!#REF! -> #REF! | H26: =-'Debt Schedule'!#REF! -> #REF! | I26: =-'Debt Schedule'!#REF! -> #REF! | ... BI26: =-'Debt Schedule'!#REF! -> #REF!
A29: Net Cash generated from Financing Activities | B29: =SUM(B24:B28) -> #REF! | C29: =SUM(C24:C28) -> #REF! | D29: =SUM(D24:D28) -> #REF! | E29: =SUM(E24:E28) -> #REF! | F29: =SUM(F24:F28) -> #REF! | G29: =SUM(G24:G28) -> #REF! | H29: =SUM(H24:H28) -> #REF! | I29: =SUM(I24:I28) -> #REF! | ... BI29: =SUM(BI24:BI28) -> #REF!
A31: Net change in Cash & Cash Equivalents | B31: =+B16+B21+B29 -> #N/A | C31: =+C16+C21+C29 -> #N/A | D31: =+D16+D21+D29 -> #N/A | E31: =+E16+E21+E29 -> #N/A | F31: =+F16+F21+F29 -> #N/A | G31: =+G16+G21+G29 -> #N/A | H31: =+H16+H21+H29 -> #N/A | I31: =+I16+I21+I29 -> #N/A | ... BI31: =+BI16+BI21+BI29 -> #N/A
A33: Opening Cash & Cash Equivalents | B33: =' Balance Sheet'!C8 -> 0 | C33: =+B35 -> #N/A | D33: =+C35 -> #N/A | E33: =+D35 -> #N/A | F33: =+E35 -> #N/A | G33: =+F35 -> #N/A | H33: =+G35 -> #N/A | I33: =+H35 -> #N/A | J33: =+I35 -> #N/A | ... BI33: =+BH35 -> #N/A
A35: Closing Cash & Cash Equivalents | B35: =+B31+B33 -> #N/A | C35: =+C31+C33 -> #N/A | D35: =+D31+D33 -> #N/A | E35: =+E31+E33 -> #N/A | F35: =+F31+F33 -> #N/A | G35: =+G31+G33 -> #N/A | H35: =+H31+H33 -> #N/A | I35: =+I31+I33 -> #N/A | ... BI35: =+BI31+BI33 -> #N/A
AB36: TO BE COVERED BY R&D SUBSIDIES STRATEGY | AE36: TO BE COVERED BY R&D SUBSIDIES STRATEGY | AH36: TO BE COVERED BY R&D SUBSIDIES STRATEGY

Sheet Annual CFS
A1: DVS
A2: Annual Cash Flow Statement
A3: Amounts in €
A5: Assumptions for the Annual Period | B5: =Controls!B5 -> 2026 | C5: =Controls!C5 -> 2027 | D5: =Controls!D5 -> 2028 | E5: =Controls!E5 -> 2029 | F5: =Controls!F5 -> 2030
A7: Cash flow from Operating Activities
A8: Profit before Tax | B8: =SUMIF('Monthly CFS'!$B$3:$BI$3,B$5,'Monthly CFS'!$B8:$BI8) -> #N/A | C8: =SUMIF('Monthly CFS'!$B$3:$BI$3,C$5,'Monthly CFS'!$B8:$BI8) -> #N/A | D8: =SUMIF('Monthly CFS'!$B$3:$BI$3,D$5,'Monthly CFS'!$B8:$BI8) -> #N/A | E8: =SUMIF('Monthly CFS'!$B$3:$BI$3,E$5,'Monthly CFS'!$B8:$BI8) -> #N/A | F8: =SUMIF('Monthly CFS'!$B$3:$BI$3,F$5,'Monthly CFS'!$B8:$BI8) -> #N/A
A9: Adjustments for:
A10: Add: Depreciation & Amortization | B10: =SUMIF('Monthly CFS'!$B$3:$BI$3,B$5,'Monthly CFS'!$B10:$BI10) -> 0 | C10: =SUMIF('Monthly CFS'!$B$3:$BI$3,C$5,'Monthly CFS'!$B10:$BI10) -> 0 | D10: =SUMIF('Monthly CFS'!$B$3:$BI$3,D$5,'Monthly CFS'!$B10:$BI10) -> 0 | E10: =SUMIF('Monthly CFS'!$B$3:$BI$3,E$5,'Monthly CFS'!$B10:$BI10) -> 0 | F10: =SUMIF('Monthly CFS'!$B$3:$BI$3,F$5,'Monthly CFS'!$B10:$BI10) -> 0
A11: Sub: Increase in Inventory | B11: =SUMIF('Monthly CFS'!$B$3:$BI$3,B$5,'Monthly CFS'!$B11:$BI11) -> #REF! | C11: =SUMIF('Monthly CFS'!$B$3:$BI$3,C$5,'Monthly CFS'!$B11:$BI11) -> #REF! | D11: =SUMIF('Monthly CFS'!$B$3:$BI$3,D$5,'Monthly CFS'!$B11:$BI11) -> #REF! | E11: =SUMIF('Monthly CFS'!$B$3:$BI$3,E$5,'Monthly CFS'!$B11:$BI11) -> #REF! | F11: =SUMIF('Monthly CFS'!$B$3:$BI$3,F$5,'Monthly CFS'!$B11:$BI11) -> #REF!
A12: Sub: Increase in Trade Receivables | B12: =SUMIF('Monthly CFS'!$B$3:$BI$3,B$5,'Monthly CFS'!$B12:$BI12) -> #REF! | C12: =SUMIF('Monthly CFS'!$B$3:$BI$3,C$5,'Monthly CFS'!$B12:$BI12) -> #REF! | D12: =SUMIF('Monthly CFS'!$B$3:$BI$3,D$5,'Monthly CFS'!$B12:$BI12) -> #REF! | E12: =SUMIF('Monthly CFS'!$B$3:$BI$3,E$5,'Monthly CFS'!$B12:$BI12) -> #REF! | F12: =SUMIF('Monthly CFS'!$B$3:$BI$3,F$5,'Monthly CFS'!$B12:$BI12) -> #REF!
A14: Sub: Taxes paid | B14: =SUMIF('Monthly CFS'!$B$3:$BI$3,B$5,'Monthly CFS'!$B14:$BI14) -> #VALUE! | C14: =SUMIF('Monthly CFS'!$B$3:$BI$3,C$5,'Monthly CFS'!$B14:$BI14) -> #VALUE! | D14: =SUMIF('Monthly CFS'!$B$3:$BI$3,D$5,'Monthly CFS'!$B14:$BI14) -> #VALUE! | E14: =SUMIF('Monthly CFS'!$B$3:$BI$3,E$5,'Monthly CFS'!$B14:$BI14) -> #VALUE! | F14: =SUMIF('Monthly CFS'!$B$3:$BI$3,F$5,'Monthly CFS'!$B14:$BI14) -> #VALUE!
A16: Net Cash generated from Operating Activities | B16: =SUM(B8:B15) -> #N/A | C16: =SUM(C8:C15) -> #N/A | D16: =SUM(D8:D15) -> #N/A | E16: =SUM(E8:E15) -> #N/A | F16: =SUM(F8:F15) -> #N/A
A18: Cash flow from Investing Activities
A19: Purchase of Fixed Assets | B19: =SUMIF('Monthly CFS'!$B$3:$BI$3,B$5,'Monthly CFS'!$B19:$BI19) -> 0 | C19: =SUMIF('Monthly CFS'!$B$3:$BI$3,C$5,'Monthly CFS'!$B19:$BI19) -> 0 | D19: =SUMIF('Monthly CFS'!$B$3:$BI$3,D$5,'Monthly CFS'!$B19:$BI19) -> 0 | E19: =SUMIF('Monthly CFS'!$B$3:$BI$3,E$5,'Monthly CFS'!$B19:$BI19) -> 0 | F19: =SUMIF('Monthly CFS'!$B$3:$BI$3,F$5,'Monthly CFS'!$B19:$BI19) -> 0
A21: Net Cash used in Investing Activities | B21: =+B19 -> 0 | C21: =+C19 -> 0 | D21: =+D19 -> 0 | E21: =+E19 -> 0 | F21: =+F19 -> 0
A23: Cash flow from Financing Activities
A24: Issuance of Equity Share Capital | B24: =SUMIF('Monthly CFS'!$B$3:$BI$3,B$5,'Monthly CFS'!$B24:$BI24) -> 2000000 | C24: =SUMIF('Monthly CFS'!$B$3:$BI$3,C$5,'Monthly CFS'!$B24:$BI24) -> 0 | D24: =SUMIF('Monthly CFS'!$B$3:$BI$3,D$5,'Monthly CFS'!$B24:$BI24) -> 0 | E24: =SUMIF('Monthly CFS'!$B$3:$BI$3,E$5,'Monthly CFS'!$B24:$BI24) -> 0 | F24: =SUMIF('Monthly CFS'!$B$3:$BI$3,F$5,'Monthly CFS'!$B24:$BI24) -> 0
A25: Issuance of Debt | B25: =SUMIF('Monthly CFS'!$B$3:$BI$3,B$5,'Monthly CFS'!$B25:$BI25) -> #REF! | C25: =SUMIF('Monthly CFS'!$B$3:$BI$3,C$5,'Monthly CFS'!$B25:$BI25) -> 0 | D25: =SUMIF('Monthly CFS'!$B$3:$BI$3,D$5,'Monthly CFS'!$B25:$BI25) -> 0 | E25: =SUMIF('Monthly CFS'!$B$3:$BI$3,E$5,'Monthly CFS'!$B25:$BI25) -> #REF! | F25: =SUMIF('Monthly CFS'!$B$3:$BI$3,F$5,'Monthly CFS'!$B25:$BI25) -> #REF!
A26: Debt Repayment | B26: =SUMIF('Monthly CFS'!$B$3:$BI$3,B$5,'Monthly CFS'!$B26:$BI26) -> #REF! | C26: =SUMIF('Monthly CFS'!$B$3:$BI$3,C$5,'Monthly CFS'!$B26:$BI26) -> #REF! | D26: =SUMIF('Monthly CFS'!$B$3:$BI$3,D$5,'Monthly CFS'!$B26:$BI26) -> #REF! | E26: =SUMIF('Monthly CFS'!$B$3:$BI$3,E$5,'Monthly CFS'!$B26:$BI26) -> #REF! | F26: =SUMIF('Monthly CFS'!$B$3:$BI$3,F$5,'Monthly CFS'!$B26:$BI26) -> #REF!
A29: Net Cash generated from Financing Activities | B29: =SUM(B24:B28) -> #REF! | C29: =SUM(C24:C28) -> #REF! | D29: =SUM(D24:D28) -> #REF! | E29: =SUM(E24:E28) -> #REF! | F29: =SUM(F24:F28) -> #REF!
A31: Net change in Cash & Cash Equivalents | B31: =+B16+B21+B29 -> #N/A | C31: =+C16+C21+C29 -> #N/A | D31: =+D16+D21+D29 -> #N/A | E31: =+E16+E21+E29 -> #N/A | F31: =+F16+F21+F29 -> #N/A
A33: Opening Cash & Cash Equivalents | B33: ='Monthly CFS'!B33 -> 0 | C33: =+B35 -> #N/A | D33: =+C35 -> #N/A | E33: =+D35 -> #N/A | F33: =+E35 -> #N/A
